Workbook

Sheet Dashboard
U1: CHART DATA (linked)
B2: FIELD SERVICE DASHBOARD
B3: July 2026 • Solar Module Complaints & Defect Analysis | U3: Site | V3: Modules | W3: Plant | X3: Modules
U4: Blupine | V4: 1845 | W4: P1 | X4: 1
B5: Total Complaints | E5: Closed Modules | H5: WIP / Open | K5: Closure Rate | N5: Avg Resolution | U5: First Energy | V5: 834 | W5: P2 | X5: 1604
B6: ='MSI Report'!B10 -> 881 | E6: ='MSI Report'!B11 -> 858 | H6: ='MSI Report'!B12 -> 23 | K6: ='MSI Report'!D10 -> 0.9738933 | N6: ='MSI Report'!G6 -> 64.1 | U6: Continuum | V6: 596 | W6: P4 | X6: 1351
U7: Ayana | V7: 367
B8: Daily Complaints Trend - July 2026 | U8: NTPC Limited | V8: 197
U9: Asian Fab Tec Ltd | V9: 59
U10: Madhav Infra Projects Ltd. | V10: 37
U11: WBSEDCL | V11: 32
U12: State | V12: Modules | W12: Defect Type | X12: G2B | Y12: G2TB | Z12: G2G
U13: Gujarat | V13: 1688 | W13: Cold Soldering | X13: 2182 | Y13: 250 | Z13: 82
U14: Karnataka | V14: 688 | W14: JB Issue | X14: 215 | Y14: 67 | Z14: 31
U15: MP | V15: 502 | W15: No Issue | X15: 110 | Y15: 11 | Z15: 12
U16: J&K | V16: 192 | W16: Tab lead Burn | X16: 18 | Y16: 17 | Z16: 0
U17: West Bengal | V17: 32 | W17: Low Generation | X17: 4 | Y17: 1 | Z17: 3
U18: Kerala | V18: 21 | W18: Glass Breakage | X18: 1 | Y18: 0 | Z18: 0
U19: Maharashtra | V19: 6
U20: Bihar | V20: 1
U22: Defect Type | V22: Count
B23: Complaints by Site | H23: Complaints by State | N23: Defect Type Mix | U23: Cold Soldering | V23: 2514
U24: JB Issue | V24: 313
U25: Tab lead Burn | V25: 35
U26: Glass Breakage | V26: 1
U27: Others | V27: 145
U29: TAT Range | V29: Modules
B40: Resolution Time (TAT) Distribution | H40: Weekly Complaint Volume
B58: MANUFACTURING PLANT-WISE | K58: MODULE TYPE DEFECT ANALYSIS - July 2026

Sheet MSI Report
A1: Monthly MIS Report - Solar PV Warranty Claims
B4: KEY PERFORMANCE INDICATORS
B5: Total Complaints | C5: Closed | D5: WIP / Open | E5: Repairable Defects | F5: Closure Rate | G5: Avg Resolution Day
B6: =B10 -> 881 | C6: =B11 -> 858 | D6: =B12 -> 23 | E6: =COUNTIFS('Monthly Report July-26'!W:W,"Repair",'Monthly Report July-26'!X:X,">="&DATE(2026,7,1),'Monthly Report July-26'!X:X,"<="&DATE(2026,7,31)) -> 719 | F6: =D10 -> 0.9738933 | G6: =ROUND(AVERAGEIF('Monthly Report July-26'!Y:Y,">=0"),1) -> 64.1
A8: 1. COMPLAINT STATUS SUMMARY
A9: Metric | B9: Value | C9: Metric | D9: Value
A10: Total Complaints (July) | B10: =SUM(B11,B12) -> 881 | C10: Closure Rate | D10: =B11/B10 -> 0.9738933
A11: Closed Modules | B11: =COUNTIFS('Monthly Report July-26'!F:F,"Closed",'Monthly Report July-26'!X:X,">="&DATE(2026,7,1),'Monthly Report July-26'!X:X,"<="&DATE(2026,7,31)) -> 858 | C11: WIP Rate | D11: =B12/B10 -> 0.026106697
A12: WIP Modules | B12: =COUNTIF('Monthly Report July-26'!F:F,"WIP") -> 23
A13: State covered | B13: =COUNTA(_xlfn.UNIQUE('Monthly Report July-26'!L2:L906)) -> 11
A16: By Customer | H16: By State
A17: COMPLAINTS BY SITE | H17: COMPLAINTS BY STATE
A18: Site | B18: Modules | C18: Closed | D18: WIP | H18: State | I18: Modules | J18: % Share | O18: =COUNTIFS(#REF!,#REF!,#REF!,"Closed",#REF!,">="&DATE(2026,4,1),#REF!,"<="&DATE(2026,4,30)) -> #REF!
A19: True Sun Trading Company | B19: =COUNTIF('Monthly Report July-26'!$C$2:$C$906,A19) -> 1 | C19: =COUNTIFS('Monthly Report July-26'!$C:$C,A19,'Monthly Report July-26'!$F:$F,"Closed",'Monthly Report July-26'!$X:$X,">="&DATE(2026,7,1),'Monthly Report July-26'!$X:$X,"<="&DATE(2026,7,31)) -> 1 | D19: =COUNTIFS('Monthly Report July-26'!$C:$C,A19,'Monthly Report July-26'!$F:$F,"WIP") -> 0 | H19: Kerala | I19: =COUNTIFS('Monthly Report July-26'!$L:$L,H19,'Monthly Report July-26'!$F:$F,"Closed",'Monthly Report July-26'!$X:$X,">="&DATE(2026,7,1),'Monthly Report July-26'!$X:$X,"<="&DATE(2026,7,31)) -> 3 | J19: =I19/$I$29 -> 0.0034965035
A20: Ayana | B20: =COUNTIF('Monthly Report July-26'!$C$2:$C$906,A20) -> 224 | C20: =COUNTIFS('Monthly Report July-26'!$C:$C,A20,'Monthly Report July-26'!$F:$F,"Closed",'Monthly Report July-26'!$X:$X,">="&DATE(2026,7,1),'Monthly Report July-26'!$X:$X,"<="&DATE(2026,7,31)) -> 224 | D20: =COUNTIFS('Monthly Report July-26'!$C:$C,A20,'Monthly Report July-26'!$F:$F,"WIP") -> 0 | H20: Gujarat | I20: =COUNTIFS('Monthly Report July-26'!$L:$L,H20,'Monthly Report July-26'!$F:$F,"Closed",'Monthly Report July-26'!$X:$X,">="&DATE(2026,7,1),'Monthly Report July-26'!$X:$X,"<="&DATE(2026,7,31)) -> 224 | J20: =I20/$I$29 -> 0.26107226
A21: First Energy | B21: =COUNTIF('Monthly Report July-26'!$C$2:$C$906,A21) -> 483 | C21: =COUNTIFS('Monthly Report July-26'!$C:$C,A21,'Monthly Report July-26'!$F:$F,"Closed",'Monthly Report July-26'!$X:$X,">="&DATE(2026,7,1),'Monthly Report July-26'!$X:$X,"<="&DATE(2026,7,31)) -> 483 | D21: =COUNTIFS('Monthly Report July-26'!$C:$C,A21,'Monthly Report July-26'!$F:$F,"WIP") -> 0 | H21: Tamil Nadu | I21: =COUNTIFS('Monthly Report July-26'!$L:$L,H21,'Monthly Report July-26'!$F:$F,"Closed",'Monthly Report July-26'!$X:$X,">="&DATE(2026,7,1),'Monthly Report July-26'!$X:$X,"<="&DATE(2026,7,31)) -> 483 | J21: =I21/$I$29 -> 0.56293706
A22: Yanara Power | B22: =COUNTIF('Monthly Report July-26'!$C$2:$C$906,A22) -> 12 | C22: =COUNTIFS('Monthly Report July-26'!$C:$C,A22,'Monthly Report July-26'!$F:$F,"Closed",'Monthly Report July-26'!$X:$X,">="&DATE(2026,7,1),'Monthly Report July-26'!$X:$X,"<="&DATE(2026,7,31)) -> 2 | D22: =COUNTIFS('Monthly Report July-26'!$C:$C,A22,'Monthly Report July-26'!$F:$F,"WIP") -> 10 | H22: Maharashtra | I22: =COUNTIFS('Monthly Report July-26'!$L:$L,H22,'Monthly Report July-26'!$F:$F,"Closed",'Monthly Report July-26'!$X:$X,">="&DATE(2026,7,1),'Monthly Report July-26'!$X:$X,"<="&DATE(2026,7,31)) -> 125 | J22: =I22/$I$29 -> 0.14568765
A23: Freyr Energy | B23: =COUNTIF('Monthly Report July-26'!$C$2:$C$906,A23) -> 3 | C23: =COUNTIFS('Monthly Report July-26'!$C:$C,A23,'Monthly Report July-26'!$F:$F,"Closed",'Monthly Report July-26'!$X:$X,">="&DATE(2026,7,1),'Monthly Report July-26'!$X:$X,"<="&DATE(2026,7,31)) -> 3 | D23: =COUNTIFS('Monthly Report July-26'!$C:$C,A23,'Monthly Report July-26'!$F:$F,"WIP") -> 0 | H23: Andhra Pradesh | I23: =COUNTIFS('Monthly Report July-26'!$L:$L,H23,'Monthly Report July-26'!$F:$F,"Closed",'Monthly Report July-26'!$X:$X,">="&DATE(2026,7,1),'Monthly Report July-26'!$X:$X,"<="&DATE(2026,7,31)) -> 3 | J23: =I23/$I$29 -> 0.0034965035
A24: Solar Square | B24: =COUNTIF('Monthly Report July-26'!$C$2:$C$906,A24) -> 38 | C24: =COUNTIFS('Monthly Report July-26'!$C:$C,A24,'Monthly Report July-26'!$F:$F,"Closed",'Monthly Report July-26'!$X:$X,">="&DATE(2026,7,1),'Monthly Report July-26'!$X:$X,"<="&DATE(2026,7,31)) -> 32 | D24: =COUNTIFS('Monthly Report July-26'!$C:$C,A24,'Monthly Report July-26'!$F:$F,"WIP") -> 6 | H24: Uttar Pradesh | I24: =COUNTIFS('Monthly Report July-26'!$L:$L,H24,'Monthly Report July-26'!$F:$F,"Closed",'Monthly Report July-26'!$X:$X,">="&DATE(2026,7,1),'Monthly Report July-26'!$X:$X,"<="&DATE(2026,7,31)) -> 12 | J24: =I24/$I$29 -> 0.013986014
A25: Panasonic | B25: =COUNTIF('Monthly Report July-26'!$C$2:$C$906,A25) -> 20 | C25: =COUNTIFS('Monthly Report July-26'!$C:$C,A25,'Monthly Report July-26'!$F:$F,"Closed",'Monthly Report July-26'!$X:$X,">="&DATE(2026,7,1),'Monthly Report July-26'!$X:$X,"<="&DATE(2026,7,31)) -> 20 | D25: =COUNTIFS('Monthly Report July-26'!$C:$C,A25,'Monthly Report July-26'!$F:$F,"WIP") -> 0 | H25: Rajasthan | I25: =COUNTIFS('Monthly Report July-26'!$L:$L,H25,'Monthly Report July-26'!$F:$F,"Closed",'Monthly Report July-26'!$X:$X,">="&DATE(2026,7,1),'Monthly Report July-26'!$X:$X,"<="&DATE(2026,7,31)) -> 3 | J25: =I25/$I$29 -> 0.0034965035
A26: Arsiga Solar | B26: =COUNTIF('Monthly Report July-26'!$C$2:$C$906,A26) -> 4 | C26: =COUNTIFS('Monthly Report July-26'!$C:$C,A26,'Monthly Report July-26'!$F:$F,"Closed",'Monthly Report July-26'!$X:$X,">="&DATE(2026,7,1),'Monthly Report July-26'!$X:$X,"<="&DATE(2026,7,31)) -> 4 | D26: =COUNTIFS('Monthly Report July-26'!$C:$C,A26,'Monthly Report July-26'!$F:$F,"WIP") -> 0 | H26: Telangana | I26: =COUNTIFS('Monthly Report July-26'!$L:$L,H26,'Monthly Report July-26'!$F:$F,"Closed",'Monthly Report July-26'!$X:$X,">="&DATE(2026,7,1),'Monthly Report July-26'!$X:$X,"<="&DATE(2026,7,31)) -> 1 | J26: =I26/$I$29 -> 0.0011655012
A27: Vashi | B27: =COUNTIF('Monthly Report July-26'!$C$2:$C$906,A27) -> 91 | C27: =COUNTIFS('Monthly Report July-26'!$C:$C,A27,'Monthly Report July-26'!$F:$F,"Closed",'Monthly Report July-26'!$X:$X,">="&DATE(2026,7,1),'Monthly Report July-26'!$X:$X,"<="&DATE(2026,7,31)) -> 84 | D27: =COUNTIFS('Monthly Report July-26'!$C:$C,A27,'Monthly Report July-26'!$F:$F,"WIP") -> 7 | H27: Haryana | I27: =COUNTIFS('Monthly Report July-26'!$L:$L,H27,'Monthly Report July-26'!$F:$F,"Closed",'Monthly Report July-26'!$X:$X,">="&DATE(2026,7,1),'Monthly Report July-26'!$X:$X,"<="&DATE(2026,7,31)) -> 3 | J27: =I27/$I$29 -> 0.0034965035
A28: DSH Trading | B28: =COUNTIF('Monthly Report July-26'!$C$2:$C$906,A28) -> 2 | C28: =COUNTIFS('Monthly Report July-26'!$C:$C,A28,'Monthly Report July-26'!$F:$F,"Closed",'Monthly Report July-26'!$X:$X,">="&DATE(2026,7,1),'Monthly Report July-26'!$X:$X,"<="&DATE(2026,7,31)) -> 2 | D28: =COUNTIFS('Monthly Report July-26'!$C:$C,A28,'Monthly Report July-26'!$F:$F,"WIP") -> 0 | H28: Karnataka | I28: =COUNTIFS('Monthly Report July-26'!$L:$L,H28,'Monthly Report July-26'!$F:$F,"Closed",'Monthly Report July-26'!$X:$X,">="&DATE(2026,7,1),'Monthly Report July-26'!$X:$X,"<="&DATE(2026,7,31)) -> 1 | J28: =I28/$I$29 -> 0.0011655012
A29: Axitec Energy | B29: =COUNTIF('Monthly Report July-26'!$C$2:$C$906,A29) -> 2 | C29: =COUNTIFS('Monthly Report July-26'!$C:$C,A29,'Monthly Report July-26'!$F:$F,"Closed",'Monthly Report July-26'!$X:$X,">="&DATE(2026,7,1),'Monthly Report July-26'!$X:$X,"<="&DATE(2026,7,31)) -> 2 | D29: =COUNTIFS('Monthly Report July-26'!$C:$C,A29,'Monthly Report July-26'!$F:$F,"WIP") -> 0 | H29: TOTAL | I29: =SUM(I19:I28) -> 858 | J29: =SUM(J19:J28) -> 1
A30: Nabhas Construction | B30: =COUNTIF('Monthly Report July-26'!$C$2:$C$906,A30) -> 0 | C30: =COUNTIFS('Monthly Report July-26'!$C:$C,A30,'Monthly Report July-26'!$F:$F,"Closed",'Monthly Report July-26'!$X:$X,">="&DATE(2026,7,1),'Monthly Report July-26'!$X:$X,"<="&DATE(2026,7,31)) -> 0 | D30: =COUNTIFS('Monthly Report July-26'!$C:$C,A30,'Monthly Report July-26'!$F:$F,"WIP") -> 0
A31: TOTAL | B31: =SUM(B19:B32) -> 875 | C31: =SUM(C19:C32) -> 858 | D31: =SUM(D19:D30) -> 23
H34: RESOLUTION TYPE
H35: Resolution | I35: Modules | J35: % Share
H36: Repair | I36: =COUNTIFS('Monthly Report July-26'!$W:$W,H36,'Monthly Report July-26'!$X:$X,">="&DATE(2026,7,1),'Monthly Report July-26'!$X:$X,"<="&DATE(2026,7,31)) -> 719 | J36: =I36/$I$41 -> 0.82548794
H37: Rejected | I37: =COUNTIFS('Monthly Report July-26'!$W:$W,H37,'Monthly Report July-26'!$X:$X,">="&DATE(2026,7,1),'Monthly Report July-26'!$X:$X,"<="&DATE(2026,7,31)) -> 112 | J37: =I37/$I$41 -> 0.12858783
A38: DAILY COMPLAINTS TREND - JAN 2026 | H38: Credit Note | I38: =COUNTIFS('Monthly Report July-26'!$W:$W,H38,'Monthly Report July-26'!$X:$X,">="&DATE(2026,7,1),'Monthly Report July-26'!$X:$X,"<="&DATE(2026,7,31)) -> 25 | J38: =I38/$I$41 -> 0.028702641
A39: Date | B39: Modules Visited | C39: Closed | D39: WIP | H39: Under Investigation | I39: =COUNTIFS('Monthly Report July-26'!$W:$W,H39,'Monthly Report July-26'!$A:$A,">="&DATE(2026,7,1),'Monthly Report July-26'!$A:$A,"<="&DATE(2026,7,31)) -> 13 | J39: =I39/$I$41 -> 0.014925373
A40: 46204 | B40: =COUNTIF('Monthly Report July-26'!$Z:$Z,A40) -> 40 | C40: =COUNTIFS('Monthly Report July-26'!$X:X,A40,'Monthly Report July-26'!F:F,"Closed") -> 40 | D40: =COUNTIFS('Monthly Report July-26'!$Z:$Z,A40,'Monthly Report July-26'!F:F,"WIP") -> 0 | H40: Refund | I40: =COUNTIFS('Monthly Report July-26'!$W:$W,H40,'Monthly Report July-26'!$X:$X,">="&DATE(2026,7,1),'Monthly Report July-26'!$X:$X,"<="&DATE(2026,7,31)) -> 2 | J40: =I40/$I$41 -> 0.0022962113
A41: 46205 | B41: =COUNTIF('Monthly Report July-26'!$Z:$Z,A41) -> 46 | C41: =COUNTIFS('Monthly Report July-26'!$X:X,A41,'Monthly Report July-26'!F:F,"Closed") -> 46 | D41: =COUNTIFS('Monthly Report July-26'!$Z:$Z,A41,'Monthly Report July-26'!F:F,"WIP") -> 0 | H41: TOTAL | I41: =SUM(I36:I40) -> 871 | J41: =SUM(J34:J40) -> 1
A42: 46206 | B42: =COUNTIF('Monthly Report July-26'!$Z:$Z,A42) -> 51 | C42: =COUNTIFS('Monthly Report July-26'!$X:X,A42,'Monthly Report July-26'!F:F,"Closed") -> 51 | D42: =COUNTIFS('Monthly Report July-26'!$Z:$Z,A42,'Monthly Report July-26'!F:F,"WIP") -> 0
A43: 46207 | B43: =COUNTIF('Monthly Report July-26'!$Z:$Z,A43) -> 54 | C43: =COUNTIFS('Monthly Report July-26'!$X:X,A43,'Monthly Report July-26'!F:F,"Closed") -> 54 | D43: =COUNTIFS('Monthly Report July-26'!$Z:$Z,A43,'Monthly Report July-26'!F:F,"WIP") -> 0
A44: 46208 | B44: =COUNTIF('Monthly Report July-26'!$Z:$Z,A44) -> 0 | C44: =COUNTIFS('Monthly Report July-26'!$X:X,A44,'Monthly Report July-26'!F:F,"Closed") -> 0 | D44: =COUNTIFS('Monthly Report July-26'!$Z:$Z,A44,'Monthly Report July-26'!F:F,"WIP") -> 0 | H44: MANUFACTURING PLANT-WISE
A45: 46209 | B45: =COUNTIF('Monthly Report July-26'!$Z:$Z,A45) -> 46 | C45: =COUNTIFS('Monthly Report July-26'!$X:X,A45,'Monthly Report July-26'!F:F,"Closed") -> 46 | D45: =COUNTIFS('Monthly Report July-26'!$Z:$Z,A45,'Monthly Report July-26'!F:F,"WIP") -> 0 | H45: Plant | I45: Modules | J45: % Share
A46: 46210 | B46: =COUNTIF('Monthly Report July-26'!$Z:$Z,A46) -> 38 | C46: =COUNTIFS('Monthly Report July-26'!$X:X,A46,'Monthly Report July-26'!F:F,"Closed") -> 28 | D46: =COUNTIFS('Monthly Report July-26'!$Z:$Z,A46,'Monthly Report July-26'!F:F,"WIP") -> 10 | H46: P4 - PEIPL | I46: =COUNTIFS('Monthly Report July-26'!$T:$T,H46,'Monthly Report July-26'!$F:$F,"Closed",'Monthly Report July-26'!$X:$X,">="&DATE(2026,6,1),'Monthly Report July-26'!$X:$X,"<="&DATE(2026,6,310)) -> 228 | J46: =I46/$I$50 -> 0.26573427
A47: 46211 | B47: =COUNTIF('Monthly Report July-26'!$Z:$Z,A47) -> 12 | C47: =COUNTIFS('Monthly Report July-26'!$X:X,A47,'Monthly Report July-26'!F:F,"Closed") -> 12 | D47: =COUNTIFS('Monthly Report July-26'!$Z:$Z,A47,'Monthly Report July-26'!F:F,"WIP") -> 0 | H47: P2 - PEPPL | I47: =COUNTIFS('Monthly Report July-26'!$T:$T,H47,'Monthly Report July-26'!$F:$F,"Closed",'Monthly Report July-26'!$X:$X,">="&DATE(2026,6,1),'Monthly Report July-26'!$X:$X,"<="&DATE(2026,6,310)) -> 524 | J47: =I47/$I$50 -> 0.61072261
...

Sheet Daily Report July -26 
A1: Date | B1: Day | C1: Site | D1: Area | E1: State | F1: No Of Complaints | G1: Visited by | H1: Complaint ID | I1: Status | J1: Remarks | K1: Complaints Register Link | L1: Start Date | M1: End Day | N1: Remarka
A2: 46204 | B2: =TEXT(A2,"dddd") -> Wednesday | C2: TRUE SUN TRADING COMPANY | D2: Iverkala | E2: Kerala | F2: 1 | G2: Pavan | H2: PE16062604 | I2: Closed | J2: Retrofit | K2: PE16062604 | L2: 46204 | M2: 46205
A3: 46204 | C3: Ayana | D3: Zura | E3: Gujarat | F3: 29 | G3: Kamal + Raja + Kunal | H3: PE04062601 | I3: Closed | J3: Retrofit | K3: PE04062601 | L3: 46204
A4: 46204 | B4: =TEXT(A4,"dddd") -> Wednesday | C4: First Energy | D4: Tirunelveli | E4: Tamil Nadu | F4: 10 | G4: Bhimsen + Bani + Gourab | H4: PE22042601 | I4: Closed | J4: Retrofit | K4: PE22042601 | L4: 46204
A5: 46205 | B5: =TEXT(A5,"dddd") -> Thursday | C5: Ayana | D5: Zura | E5: Gujarat | F5: 46 | G5: Kamal + Raja + Kunal | H5: PE04062601 | I5: Closed | J5: Retrofit | K5: PE04062601
A6: 46206 | B6: =TEXT(A6,"dddd") -> Friday | C6: First Energy | D6: Tirunelveli | E6: Tamil Nadu | F6: 17 | G6: Bhimsen + Bani + Gourab | H6: PE22042601 | I6: Closed | J6: Retrofit | K6: PE22042601
A7: 46206 | B7: =TEXT(A7,"dddd") -> Friday | C7: First Energy | D7: Tirunelveli | E7: Tamil Nadu | F7: 1 | G7: Bhimsen + Bani + Gourab | H7: PE22042601 | I7: Closed | J7: Inspection | K7: PE22042601
A8: 46206 | B8: =TEXT(A8,"dddd") -> Friday | C8: Ayana | D8: Zura | E8: Gujarat | F8: 32 | G8: Kamal + Raja + Kunal | H8: PE04062601 | I8: Closed | J8: Retrofit | K8: PE04062601
A9: 46206 | B9: =TEXT(A9,"dddd") -> Friday | C9: Ayana | D9: Zura | E9: Gujarat | F9: 1 | G9: Kamal + Raja + Kunal | H9: PE04062601 | I9: Closed | J9: Inspection | K9: PE04062601
A10: 46207 | B10: =TEXT(A10,"dddd") -> Saturday | C10: Ayana | D10: Zura | E10: Gujarat | F10: 53 | G10: Kamal + Raja + Kunal | H10: PE04062601 | I10: Closed | J10: Retrofit | K10: PE04062601
A11: 46207 | B11: =TEXT(A11,"dddd") -> Saturday | C11: Ayana | D11: Zura | E11: Gujarat | F11: 1 | G11: Kamal + Raja + Kunal | H11: PE04062601 | I11: Closed | J11: Inspection | K11: PE04062601
A12: 46209 | B12: =TEXT(A12,"dddd") -> Monday | C12: Ayana | D12: Zura | E12: Gujarat | F12: 46 | G12: Kamal + Raja + Kunal | H12: PE04062601 | I12: Closed | J12: Retrofit | K12: PE04062601
A13: 46210 | B13: =TEXT(A13,"dddd") -> Tuesday | C13: Ayana | D13: Zura | E13: Gujarat | F13: 16 | G13: Kamal + Raja + Kunal | H13: PE04062601 | I13: Closed | J13: Retrofit | K13: PE04062601 | M13: 46213
A14: 46210 | B14: =TEXT(A14,"dddd") -> Tuesday | C14: First Energy | D14: Tirunelveli | E14: Tamil Nadu | F14: 10 | G14: Bhimsen | H14: PE22042601 | I14: Closed | J14: Retrofit | K14: PE22042601
A15: 46210 | B15: =TEXT(A15,"dddd") -> Tuesday | C15: Yanara Power | D15: Holi | E15: Maharashtra | F15: 10 | G15: Amit | H15: PE01052601 | I15: WIP | J15: Inspection | K15: PE01052601 | L15: 46209
A16: 46210 | B16: =TEXT(A16,"dddd") -> Tuesday | C16: Yanara Power | D16: Holi | E16: Maharashtra | F16: 2 | G16: Amit | H16: PE01052601 | I16: Closed | J16: Inspection | K16: PE01052601
A17: 46211 | B17: =TEXT(A17,"dddd") -> Wednesday | C17: First Energy | D17: Tirunelveli | E17: Tamil Nadu | F17: 12 | G17: Bhimsen | H17: PE22042601 | I17: Closed | J17: Retrofit | K17: PE22042601
A18: 46212 | B18: =TEXT(A18,"dddd") -> Thursday | C18: Freyr Energy | D18: Kurnool | E18: Andhra Pradesh | F18: 3 | G18: Pavan | H18: PE19062602 | I18: Closed | J18: Retrofit | K18: PE19062602 | L18: 46212 | M18: 46212
A19: 46212 | B19: =TEXT(A19,"dddd") -> Thursday | C19: Panasonic | D19: Nagpur | E19: Maharashtra | F19: 7 | G19: Amit | H19: PE26062602 | I19: Closed | J19: Retrofit | K19: PE26062602
A20: 46212 | B20: =TEXT(A20,"dddd") -> Thursday | C20: Arsiga Solar | D20: Lucknow | E20: UP | F20: 1 | G20: By Mail | H20: PE09072601 | I20: Closed | J20: Vertual Inspection | K20: PE09072601
A21: 46213 | B21: =TEXT(A21,"dddd") -> Friday | C21: Solar Square | D21: Pune | E21: Maharashtra | F21: 22 | G21: By Mail | H21: PE02012603 | I21: Closed | J21: Inspection | K21: PE02012603
A22: 46213 | B22: =TEXT(A22,"dddd") -> Friday | C22: Solar Square | D22: Nagpur | E22: Maharashtra | F22: 1 | G22: By Mail | H22: PE08052602 | I22: Closed | J22: Vertual Inspection | K22: PE08052602
A23: 46214 | B23: =TEXT(A23,"dddd") -> Saturday | C23: First Energy | D23: Tirunelveli | E23: Tamil Nadu | F23: 29 | G23: Bhimsen | H23: PE22042601 | I23: Closed | J23: Retrofit | K23: PE22042601
A24: 46214 | B24: =TEXT(A24,"dddd") -> Saturday | C24: First Energy | D24: Tirunelveli | E24: Tamil Nadu | F24: 1 | G24: Bhimsen | H24: PE22042601 | I24: Closed | J24: Inspection | K24: PE22042601
A25: 46214 | B25: =TEXT(A25,"dddd") -> Saturday | C25: Solar Square | D25: Nagpur | E25: Maharashtra | F25: 8 | G25: Amit | H25: PE02072601 | I25: Closed | J25: Inspection | K25: PE02072601 | M25: 46215
A26: 46216 | B26: =TEXT(A26,"dddd") -> Monday | C26: Arsiga Solar | D26: Jaipur | E26: Rajasthan | F26: 1 | G26: By Mail | H26: PE28042601 | I26: Closed | J26: Vertual Inspection | K26: PE28042601
A27: 46216 | B27: =TEXT(A27,"dddd") -> Monday | C27: Arsiga Solar | D27: KANPUR | E27: UP | F27: 2 | G27: By Mail | H27: PE02072606 | I27: Closed | J27: Vertual Inspection | K27: PE02072606
A28: 46216 | B28: =TEXT(A28,"dddd") -> Monday | C28: First Energy | D28: Tirunelveli | E28: Tamil Nadu | F28: 19 | G28: Bhimsen | H28: PE22042601 | I28: Closed | J28: Retrofit | K28: PE22042601
A29: 46216 | B29: =TEXT(A29,"dddd") -> Monday | C29: Solar Square | D29: Hyderabad | E29: Telangana | F29: 6 | G29: Pavan | H29: PE13072601 | I29: WIP | J29: Inspection | K29: PE13072601
A30: 46218 | B30: =TEXT(A30,"dddd") -> Wednesday | C30: First Energy | D30: Tirunelveli | E30: Tamil Nadu | F30: 30 | G30: Bhimsen | H30: PE22042601 | I30: Closed | J30: Retrofit | K30: PE22042601
A31: 46219 | B31: =TEXT(A31,"dddd") -> Thursday | C31: Vashi | D31: Kolhapur | E31: Maharashtra | F31: 80 | G31: By Mail | H31: PE16072601 | I31: Closed | J31: Vertual Inspection | K31: PE16072601
A32: 46219 | B32: =TEXT(A32,"dddd") -> Thursday | C32: DSH Trading | D32: Nagpur | E32: Maharashtra | F32: 1 | G32: By Mail | H32: PE17062602 | I32: Closed | J32: Vertual Inspection | K32: PE17062602
A33: 46219 | B33: =TEXT(A33,"dddd") -> Thursday | C33: First Energy | D33: Tirunelveli | E33: Tamil Nadu | F33: 28 | G33: Bhimsen | H33: PE22042601 | I33: Closed | J33: Retrofit | K33: PE22042601
A34: 46220 | B34: =TEXT(A34,"dddd") -> Friday | C34: Axitec Energy | D34: Trivandrum | E34: Kerala | F34: 2 | G34: By Mail | H34: PE17062601 | I34: Closed | J34: Inspection & Vertual Inspection | K34: PE17062601
A35: 46220 | B35: =TEXT(A35,"dddd") -> Friday | C35: Vashi | D35: Pune | E35: Maharashtra | F35: 1 | G35: By Mail | H35: PE16072603 | I35: Closed | J35: Vertual Inspection | K35: PE16072603
A36: 46220 | B36: =TEXT(A36,"dddd") -> Friday | C36: First Energy | D36: Tirunelveli | E36: Tamil Nadu | F36: 29 | G36: Bhimsen | H36: PE22042601 | I36: Closed | J36: Retrofit | K36: PE22042601
A37: 46221 | B37: =TEXT(A37,"dddd") -> Saturday | C37: Nabhas Construction | D37: Hyderabad | E37: Telangana | F37: 1 | G37: Gaurab | H37: PE17072601 | I37: Closed | J37: Retrofit | K37: PE17072601 | L37: 46221 | M37: 46221
A38: 46223 | B38: =TEXT(A38,"dddd") -> Monday | C38: Panasonic | D38: Gurugram | E38: Haryana | F38: 2 | G38: Kamal | H38: PE03072601 | I38: Closed | J38: Retrofit | K38: PE03072601 | L38: 46223
A39: 46223 | B39: =TEXT(A39,"dddd") -> Monday | C39: Panasonic | D39: Gurugram | E39: Haryana | F39: 1 | G39: Kamal | H39: PE15072602 | I39: Closed | J39: Retrofit | K39: PE15072602 | M39: 46223
A40: 46224 | B40: =TEXT(A40,"dddd") -> Tuesday | C40: First Energy | D40: Tirunelveli | E40: Tamil Nadu | F40: 31 | G40: Bhimsen | H40: PE22042601 | I40: Closed | J40: Retrofit | K40: PE22042601
...

Sheet Monthly Report July-26
A1: Date | B1: Year | C1: Complaint Raised By | D1: Client Type | E1: Project Name | F1: Current Status | G1: Claim Reported By | H1: Contact No. | I1: Contract / Complaint / Invoice No. | J1: Customer Reported Problem | K1: Venue / Location | L1: State | M1: Field Evaluation | N1: Our Evaluation | O1: PV Panels Wp | P1: Module Serial Number | Q1: Module Make Year | R1: Module Make Month | S1: Module Type | T1: Manufacturing Plant | U1: Remark | V1: Action Taken | W1: Resolution Type | X1: Date of Claim Settled | Y1: Claim Settlement Duration | Z1: Visit Date | AA1: Rework Srl No. | AB1: Work details
A2: 46189 | B2: 2026 | C2: True Sun Trading Company | D2: Channel Sales | F2: Closed | G2: Sarath Ananda | H2: 8848944464 | I2: PE16062604 | J2: Low VOC | K2: Iverkala | L2: Kerala | M2: PR | N2: JB Issue | O2: 515 | P2: NSMP2303564668 | Q2: =MID(P2,5,2) -> 23 | R2: =MID(P2,7,2) -> 03 | S2: G2B | T2: P2 - PEPPL | U2: P JB Issue | V2: JB Changed | W2: Repair | X2: 46204 | Y2: =X2-A2 -> 15 | Z2: 46204 | AD2: =IF(AND(F2="Closed",X2>=DATE(2026,7,1),X2<=DATE(2026,7,31)),"Closed In July","Other") -> Closed In July
A3: 46177 | B3: 2026 | C3: Ayana | D3: IPP/Utility | F3: Closed | G3: Vasu.N | H3: 9578099893 | I3: PE04062601 | J3: Module burnt | K3: Zura | L3: Gujarat | M3: NS | N3: Cold Soldering | O3: 590 | P3: NSMI24100660910 | Q3: =MID(P3,5,2) -> 24 | R3: =MID(P3,7,2) -> 10 | S3: G2G | T3: P4 - PEIPL | U3: N JB Cold Soldering | V3: Soldering | W3: Repair | X3: 46204 | Y3: =X3-A3 -> 27 | Z3: 46204 | AD3: =IF(AND(F3="Closed",X3>=DATE(2026,7,1),X3<=DATE(2026,7,31)),"Closed In July","Other") -> Closed In July
A4: 46177 | B4: 2026 | C4: Ayana | D4: IPP/Utility | F4: Closed | G4: Vasu.N | H4: 9578099893 | I4: PE04062601 | J4: Module burnt | K4: Zura | L4: Gujarat | M4: PR | N4: JB Issue | O4: 590 | P4: NSMI24100645556 | Q4: =MID(P4,5,2) -> 24 | R4: =MID(P4,7,2) -> 10 | S4: G2G | T4: P4 - PEIPL | U4: P JB Diode Issue | V4: JB Changed | W4: Repair | X4: 46204 | Y4: =X4-A4 -> 27 | Z4: 46204 | AD4: =IF(AND(F4="Closed",X4>=DATE(2026,7,1),X4<=DATE(2026,7,31)),"Closed In July","Other") -> Closed In July
A5: 46177 | B5: 2026 | C5: Ayana | D5: IPP/Utility | F5: Closed | G5: Vasu.N | H5: 9578099893 | I5: PE04062601 | J5: Module burnt | K5: Zura | L5: Gujarat | M5: PS | N5: Cold Soldering | O5: 590 | P5: NSMI24100686458 | Q5: =MID(P5,5,2) -> 24 | R5: =MID(P5,7,2) -> 10 | S5: G2G | T5: P4 - PEIPL | U5: P JB Cold Soldering | V5: Soldering | W5: Repair | X5: 46204 | Y5: =X5-A5 -> 27 | Z5: 46204 | AD5: =IF(AND(F5="Closed",X5>=DATE(2026,7,1),X5<=DATE(2026,7,31)),"Closed In July","Other") -> Closed In July
A6: 46177 | B6: 2026 | C6: Ayana | D6: IPP/Utility | F6: Closed | G6: Vasu.N | H6: 9578099893 | I6: PE04062601 | J6: Module burnt | K6: Zura | L6: Gujarat | M6: PS | N6: Cold Soldering | O6: 590 | P6: NSMI24100687353 | Q6: =MID(P6,5,2) -> 24 | R6: =MID(P6,7,2) -> 10 | S6: G2G | T6: P4 - PEIPL | U6: P JB Cold Soldering | V6: Soldering | W6: Repair | X6: 46204 | Y6: =X6-A6 -> 27 | Z6: 46204 | AD6: =IF(AND(F6="Closed",X6>=DATE(2026,7,1),X6<=DATE(2026,7,31)),"Closed In July","Other") -> Closed In July
A7: 46177 | B7: 2026 | C7: Ayana | D7: IPP/Utility | F7: Closed | G7: Vasu.N | H7: 9578099893 | I7: PE04062601 | J7: Module burnt | K7: Zura | L7: Gujarat | M7: PS | N7: Cold Soldering | O7: 590 | P7: NSMI24100686144 | Q7: =MID(P7,5,2) -> 24 | R7: =MID(P7,7,2) -> 10 | S7: G2G | T7: P4 - PEIPL | U7: P JB Cold Soldering | V7: Soldering | W7: Repair | X7: 46204 | Y7: =X7-A7 -> 27 | Z7: 46204 | AD7: =IF(AND(F7="Closed",X7>=DATE(2026,7,1),X7<=DATE(2026,7,31)),"Closed In July","Other") -> Closed In July
A8: 46177 | B8: 2026 | C8: Ayana | D8: IPP/Utility | F8: Closed | G8: Vasu.N | H8: 9578099893 | I8: PE04062601 | J8: Module burnt | K8: Zura | L8: Gujarat | M8: NS | N8: Cold Soldering | O8: 590 | P8: NSMI24100666184 | Q8: =MID(P8,5,2) -> 24 | R8: =MID(P8,7,2) -> 10 | S8: G2G | T8: P4 - PEIPL | U8: N JB Cold Soldering | V8: Soldering | W8: Repair | X8: 46204 | Y8: =X8-A8 -> 27 | Z8: 46204 | AD8: =IF(AND(F8="Closed",X8>=DATE(2026,7,1),X8<=DATE(2026,7,31)),"Closed In July","Other") -> Closed In July
A9: 46177 | B9: 2026 | C9: Ayana | D9: IPP/Utility | F9: Closed | G9: Vasu.N | H9: 9578099893 | I9: PE04062601 | J9: Module burnt | K9: Zura | L9: Gujarat | M9: PNS | N9: Cold Soldering | O9: 590 | P9: NSMI24110794434 | Q9: =MID(P9,5,2) -> 24 | R9: =MID(P9,7,2) -> 11 | S9: G2G | T9: P4 - PEIPL | U9: P & N JB Cold Soldering | V9: Soldering | W9: Repair | X9: 46204 | Y9: =DATEDIF(A9,X9,"D") -> 27 | Z9: 46204 | AD9: =IF(AND(F9="Closed",X9>=DATE(2026,7,1),X9<=DATE(2026,7,31)),"Closed In July","Other") -> Closed In July
A10: 46177 | B10: 2026 | C10: Ayana | D10: IPP/Utility | F10: Closed | G10: Vasu.N | H10: 9578099893 | I10: PE04062601 | J10: Module burnt | K10: Zura | L10: Gujarat | M10: NS | N10: Cold Soldering | O10: 590 | P10: NSMI24100665977 | Q10: =MID(P10,5,2) -> 24 | R10: =MID(P10,7,2) -> 10 | S10: G2G | T10: P4 - PEIPL | U10: N JB Cold Soldering | V10: Soldering | W10: Repair | X10: 46204 | Y10: =X10-A10 -> 27 | Z10: 46204 | AD10: =IF(AND(F10="Closed",X10>=DATE(2026,7,1),X10<=DATE(2026,7,31)),"Closed In July","Other") -> Closed In July
A11: 46177 | B11: 2026 | C11: Ayana | D11: IPP/Utility | F11: Closed | G11: Vasu.N | H11: 9578099893 | I11: PE04062601 | J11: Module burnt | K11: Zura | L11: Gujarat | M11: PS | N11: Cold Soldering | O11: 590 | P11: NSMI24110798123 | Q11: =MID(P11,5,2) -> 24 | R11: =MID(P11,7,2) -> 11 | S11: G2G | T11: P4 - PEIPL | U11: P JB Cold Soldering | V11: Soldering | W11: Repair | X11: 46204 | Y11: =X11-A11 -> 27 | Z11: 46204 | AD11: =IF(AND(F11="Closed",X11>=DATE(2026,7,1),X11<=DATE(2026,7,31)),"Closed In July","Other") -> Closed In July
A12: 46177 | B12: 2026 | C12: Ayana | D12: IPP/Utility | F12: Closed | G12: Vasu.N | H12: 9578099893 | I12: PE04062601 | J12: Module burnt | K12: Zura | L12: Gujarat | M12: PS | N12: Cold Soldering | O12: 590 | P12: NSMI24100649135 | Q12: =MID(P12,5,2) -> 24 | R12: =MID(P12,7,2) -> 10 | S12: G2G | T12: P4 - PEIPL | U12: P JB Cold Soldering | V12: Soldering | W12: Repair | X12: 46204 | Y12: =X12-A12 -> 27 | Z12: 46204 | AD12: =IF(AND(F12="Closed",X12>=DATE(2026,7,1),X12<=DATE(2026,7,31)),"Closed In July","Other") -> Closed In July
A13: 46177 | B13: 2026 | C13: Ayana | D13: IPP/Utility | F13: Closed | G13: Vasu.N | H13: 9578099893 | I13: PE04062601 | J13: Module burnt | K13: Zura | L13: Gujarat | M13: NS | N13: Cold Soldering | O13: 590 | P13: NSMI24110795313 | Q13: =MID(P13,5,2) -> 24 | R13: =MID(P13,7,2) -> 11 | S13: G2G | T13: P4 - PEIPL | U13: N JB Cold Soldering | V13: Soldering | W13: Repair | X13: 46204 | Y13: =X13-A13 -> 27 | Z13: 46204 | AD13: =IF(AND(F13="Closed",X13>=DATE(2026,7,1),X13<=DATE(2026,7,31)),"Closed In July","Other") -> Closed In July
A14: 46177 | B14: 2026 | C14: Ayana | D14: IPP/Utility | F14: Closed | G14: Vasu.N | H14: 9578099893 | I14: PE04062601 | J14: Module burnt | K14: Zura | L14: Gujarat | M14: NS | N14: Cold Soldering | O14: 590 | P14: NSMI24110795306 | Q14: =MID(P14,5,2) -> 24 | R14: =MID(P14,7,2) -> 11 | S14: G2G | T14: P4 - PEIPL | U14: N JB Cold Soldering | V14: Soldering | W14: Repair | X14: 46204 | Y14: =X14-A14 -> 27 | Z14: 46204 | AD14: =IF(AND(F14="Closed",X14>=DATE(2026,7,1),X14<=DATE(2026,7,31)),"Closed In July","Other") -> Closed In July
A15: 46177 | B15: 2026 | C15: Ayana | D15: IPP/Utility | F15: Closed | G15: Vasu.N | H15: 9578099893 | I15: PE04062601 | J15: Module burnt | K15: Zura | L15: Gujarat | M15: NS | N15: Cold Soldering | O15: 590 | P15: NSMI24110795454 | Q15: =MID(P15,5,2) -> 24 | R15: =MID(P15,7,2) -> 11 | S15: G2G | T15: P4 - PEIPL | U15: N JB Cold Soldering | V15: Soldering | W15: Repair | X15: 46204 | Y15: =X15-A15 -> 27 | Z15: 46204 | AD15: =IF(AND(F15="Closed",X15>=DATE(2026,7,1),X15<=DATE(2026,7,31)),"Closed In July","Other") -> Closed In July
A16: 46177 | B16: 2026 | C16: Ayana | D16: IPP/Utility | F16: Closed | G16: Vasu.N | H16: 9578099893 | I16: PE04062601 | J16: Module burnt | K16: Zura | L16: Gujarat | M16: PS | N16: Cold Soldering | O16: 590 | P16: NSMI24100663588 | Q16: =MID(P16,5,2) -> 24 | R16: =MID(P16,7,2) -> 10 | S16: G2G | T16: P4 - PEIPL | U16: P JB Cold Soldering | V16: Soldering | W16: Repair | X16: 46204 | Y16: =X16-A16 -> 27 | Z16: 46204 | AD16: =IF(AND(F16="Closed",X16>=DATE(2026,7,1),X16<=DATE(2026,7,31)),"Closed In July","Other") -> Closed In July
A17: 46177 | B17: 2026 | C17: Ayana | D17: IPP/Utility | F17: Closed | G17: Vasu.N | H17: 9578099893 | I17: PE04062601 | J17: Module burnt | K17: Zura | L17: Gujarat | M17: PS | N17: Cold Soldering | O17: 590 | P17: NSMI24100663787 | Q17: =MID(P17,5,2) -> 24 | R17: =MID(P17,7,2) -> 10 | S17: G2G | T17: P4 - PEIPL | U17: P JB Cold Soldering | V17: Soldering | W17: Repair | X17: 46204 | Y17: =X17-A17 -> 27 | Z17: 46204 | AD17: =IF(AND(F17="Closed",X17>=DATE(2026,7,1),X17<=DATE(2026,7,31)),"Closed In July","Other") -> Closed In July
A18: 46177 | B18: 2026 | C18: Ayana | D18: IPP/Utility | F18: Closed | G18: Vasu.N | H18: 9578099893 | I18: PE04062601 | J18: Module burnt | K18: Zura | L18: Gujarat | M18: PS | N18: Cold Soldering | O18: 590 | P18: NSMI24100668842 | Q18: =MID(P18,5,2) -> 24 | R18: =MID(P18,7,2) -> 10 | S18: G2G | T18: P4 - PEIPL | U18: P JB Cold Soldering | V18: Soldering | W18: Repair | X18: 46204 | Y18: =X18-A18 -> 27 | Z18: 46204 | AD18: =IF(AND(F18="Closed",X18>=DATE(2026,7,1),X18<=DATE(2026,7,31)),"Closed In July","Other") -> Closed In July
A19: 46177 | B19: 2026 | C19: Ayana | D19: IPP/Utility | F19: Closed | G19: Vasu.N | H19: 9578099893 | I19: PE04062601 | J19: Module burnt | K19: Zura | L19: Gujarat | M19: PS | N19: Cold Soldering | O19: 590 | P19: NSMI24100649814 | Q19: =MID(P19,5,2) -> 24 | R19: =MID(P19,7,2) -> 10 | S19: G2G | T19: P4 - PEIPL | U19: P JB Cold Soldering | V19: Soldering | W19: Repair | X19: 46204 | Y19: =X19-A19 -> 27 | Z19: 46204 | AD19: =IF(AND(F19="Closed",X19>=DATE(2026,7,1),X19<=DATE(2026,7,31)),"Closed In July","Other") -> Closed In July
A20: 46177 | B20: 2026 | C20: Ayana | D20: IPP/Utility | F20: Closed | G20: Vasu.N | H20: 9578099893 | I20: PE04062601 | J20: Module burnt | K20: Zura | L20: Gujarat | M20: PS | N20: Cold Soldering | O20: 590 | P20: NSMI24100658637 | Q20: =MID(P20,5,2) -> 24 | R20: =MID(P20,7,2) -> 10 | S20: G2G | T20: P4 - PEIPL | U20: P JB Cold Soldering | V20: Soldering | W20: Repair | X20: 46204 | Y20: =X20-A20 -> 27 | Z20: 46204 | AD20: =IF(AND(F20="Closed",X20>=DATE(2026,7,1),X20<=DATE(2026,7,31)),"Closed In July","Other") -> Closed In July
A21: 46177 | B21: 2026 | C21: Ayana | D21: IPP/Utility | F21: Closed | G21: Vasu.N | H21: 9578099893 | I21: PE04062601 | J21: Module burnt | K21: Zura | L21: Gujarat | M21: PS | N21: Cold Soldering | O21: 590 | P21: NSMI24100643199 | Q21: =MID(P21,5,2) -> 24 | R21: =MID(P21,7,2) -> 10 | S21: G2G | T21: P4 - PEIPL | U21: P JB Cold Soldering | V21: Soldering | W21: Repair | X21: 46204 | Y21: =X21-A21 -> 27 | Z21: 46204 | AD21: =IF(AND(F21="Closed",X21>=DATE(2026,7,1),X21<=DATE(2026,7,31)),"Closed In July","Other") -> Closed In July
... A264: 46134 | B264: 2026 | C264: First Energy | D264: Utility and C&I | F264: Closed | G264: Saravanakumar | H264: 8248438488 | I264: PE22042601 | J264: Anomalies/defects in the modules | K264: Tirunelveli | L264: Tamil Nadu | M264: PS | N264: Cold Soldering | O264: 550 | P264: NSMP2306323053 | Q264: =MID(P264,5,2) -> 23 | R264: =MID(P264,7,2) -> 06 | S264: G2B | T264: P2 - PEPPL | U264: P JB Cold Soldering | V264: Soldering | W264: Repair | X264: 46210 | Y264: =X264-A264 -> 76 | Z264: 46210 | AD264: =IF(AND(F264="Closed",X264>=DATE(2026,7,1),X264<=DATE(2026,7,31)),"Closed In July","Other") -> Closed In July
A265: 46143 | B265: 2026 | C265: Yanara Power | D265: IPP/Utility | F265: WIP | G265: Ashish Jindal | H265: 9983975581 | I265: PE01052601 | J265: Hotspot Issues | K265: Holi | L265: Maharashtra | M265: MULTIPLE HOTSPOT | N265: Hotspot | O265: 575 | P265: NSMI24070192988 | Q265: =MID(P265,5,2) -> 24 | R265: =MID(P265,7,2) -> 07 | S265: G2G | T265: P4 - PEIPL | U265: Multiple Hotspot Issue | V265: Onsite Inspection | W265: Under Investigation | Y265: =X265-A265 -> -46143 | Z265: 46210 | AD265: =IF(AND(F265="Closed",X265>=DATE(2026,7,1),X265<=DATE(2026,7,31)),"Closed In July","Other") -> Other
A266: 46143 | B266: 2026 | C266: Yanara Power | D266: IPP/Utility | F266: WIP | G266: Ashish Jindal | H266: 9983975581 | I266: PE01052601 | J266: Hotspot Issues | K266: Holi | L266: Maharashtra | M266: MULTIPLE HOTSPOT | N266: Hotspot | O266: 575 | P266: NSMI24070198984 | Q266: =MID(P266,5,2) -> 24 | R266: =MID(P266,7,2) -> 07 | S266: G2G | T266: P4 - PEIPL | U266: Multiple Hotspot Issue | V266: Onsite Inspection | W266: Under Investigation | Y266: =X266-A266 -> -46143 | Z266: 46210 | AD266: =IF(AND(F266="Closed",X266>=DATE(2026,7,1),X266<=DATE(2026,7,31)),"Closed In July","Other") -> Other
A267: 46143 | B267: 2026 | C267: Yanara Power | D267: IPP/Utility | F267: WIP | G267: Ashish Jindal | H267: 9983975581 | I267: PE01052601 | J267: Hotspot Issues | K267: Holi | L267: Maharashtra | M267: MULTIPLE HOTSPOT | N267: Hotspot | O267: 575 | P267: NSMI24070196603 | Q267: =MID(P267,5,2) -> 24 | R267: =MID(P267,7,2) -> 07 | S267: G2G | T267: P4 - PEIPL | U267: Multiple Hotspot Issue | V267: Onsite Inspection | W267: Under Investigation | Y267: =X267-A267 -> -46143 | Z267: 46210 | AD267: =IF(AND(F267="Closed",X267>=DATE(2026,7,1),X267<=DATE(2026,7,31)),"Closed In July","Other") -> Other
A268: 46143 | B268: 2026 | C268: Yanara Power | D268: IPP/Utility | F268: WIP | G268: Ashish Jindal | H268: 9983975581 | I268: PE01052601 | J268: Hotspot Issues | K268: Holi | L268: Maharashtra | M268: MULTIPLE HOTSPOT | N268: Hotspot | O268: 575 | P268: NSMI24070196596 | Q268: =MID(P268,5,2) -> 24 | R268: =MID(P268,7,2) -> 07 | S268: G2G | T268: P4 - PEIPL | U268: Multiple Hotspot Issue | V268: Onsite Inspection | W268: Under Investigation | Y268: =X268-A268 -> -46143 | Z268: 46210 | AD268: =IF(AND(F268="Closed",X268>=DATE(2026,7,1),X268<=DATE(2026,7,31)),"Closed In July","Other") -> Other
A269: 46143 | B269: 2026 | C269: Yanara Power | D269: IPP/Utility | F269: WIP | G269: Ashish Jindal | H269: 9983975581 | I269: PE01052601 | J269: Hotspot Issues | K269: Holi | L269: Maharashtra | M269: MULTIPLE HOTSPOT | N269: Hotspot | O269: 575 | P269: NSMI24070192686 | Q269: =MID(P269,5,2) -> 24 | R269: =MID(P269,7,2) -> 07 | S269: G2G | T269: P4 - PEIPL | U269: Multiple Hotspot Issue | V269: Onsite Inspection | W269: Under Investigation | Y269: =X269-A269 -> -46143 | Z269: 46210 | AD269: =IF(AND(F269="Closed",X269>=DATE(2026,7,1),X269<=DATE(2026,7,31)),"Closed In July","Other") -> Other
A270: 46143 | B270: 2026 | C270: Yanara Power | D270: IPP/Utility | F270: WIP | G270: Ashish Jindal | H270: 9983975581 | I270: PE01052601 | J270: Hotspot Issues | K270: Holi | L270: Maharashtra | M270: MULTIPLE HOTSPOT | N270: Hotspot | O270: 575 | P270: NSMI24080307804 | Q270: =MID(P270,5,2) -> 24 | R270: =MID(P270,7,2) -> 08 | S270: G2G | T270: P4 - PEIPL | U270: Multiple Hotspot Issue | V270: Onsite Inspection | W270: Under Investigation | Y270: =X270-A270 -> -46143 | Z270: 46210 | AD270: =IF(AND(F270="Closed",X270>=DATE(2026,7,1),X270<=DATE(2026,7,31)),"Closed In July","Other") -> Other
A271: 46143 | B271: 2026 | C271: Yanara Power | D271: IPP/Utility | F271: Closed | G271: Ashish Jindal | H271: 9983975581 | I271: PE01052601 | J271: Hotspot Issues | K271: Holi | L271: Maharashtra | M271: GLASS BROKEN | N271: Glass Breakage | O271: 575 | P271: NSMI24070202226 | Q271: =MID(P271,5,2) -> 24 | R271: =MID(P271,7,2) -> 07 | S271: G2G | T271: P4 - PEIPL | U271: Glass Breakage due to JB Tampering | V271: Onsite Inspection | W271: Rejected | X271: 46210 | Y271: =X271-A271 -> 67 | Z271: 46210 | AD271: =IF(AND(F271="Closed",X271>=DATE(2026,7,1),X271<=DATE(2026,7,31)),"Closed In July","Other") -> Closed In July
A272: 46143 | B272: 2026 | C272: Yanara Power | D272: IPP/Utility | F272: Closed | G272: Ashish Jindal | H272: 9983975581 | I272: PE01052601 | J272: Hotspot Issues | K272: Holi | L272: Maharashtra | M272: GLASS BROKEN | N272: Glass Breakage | O272: 575 | P272: NSMI24070191326 | Q272: =MID(P272,5,2) -> 24 | R272: =MID(P272,7,2) -> 07 | S272: G2G | T272: P4 - PEIPL | U272: Glass Breakage due to JB Tampering | V272: Onsite Inspection | W272: Rejected | X272: 46210 | Y272: =X272-A272 -> 67 | Z272: 46210 | AD272: =IF(AND(F272="Closed",X272>=DATE(2026,7,1),X272<=DATE(2026,7,31)),"Closed In July","Other") -> Closed In July
A273: 46143 | B273: 2026 | C273: Yanara Power | D273: IPP/Utility | F273: WIP | G273: Ashish Jindal | H273: 9983975581 | I273: PE01052601 | J273: Hotspot Issues | K273: Holi | L273: Maharashtra | M273: MULTIPLE HOTSPOT | N273: Hotspot | O273: 575 | P273: NSMI24070191746 | Q273: =MID(P273,5,2) -> 24 | R273: =MID(P273,7,2) -> 07 | S273: G2G | T273: P4 - PEIPL | U273: Multiple Hotspot Issue | V273: Onsite Inspection | W273: Under Investigation | Y273: =X273-A273 -> -46143 | Z273: 46210 | AD273: =IF(AND(F273="Closed",X273>=DATE(2026,7,1),X273<=DATE(2026,7,31)),"Closed In July","Other") -> Other
A274: 46143 | B274: 2026 | C274: Yanara Power | D274: IPP/Utility | F274: WIP | G274: Ashish Jindal | H274: 9983975581 | I274: PE01052601 | J274: Hotspot Issues | K274: Holi | L274: Maharashtra | M274: MULTIPLE HOTSPOT | N274: Hotspot | O274: 575 | P274: NSMI24070194735 | Q274: =MID(P274,5,2) -> 24 | R274: =MID(P274,7,2) -> 07 | S274: G2G | T274: P4 - PEIPL | U274: Multiple Hotspot Issue | V274: Onsite Inspection | W274: Under Investigation | Y274: =X274-A274 -> -46143 | Z274: 46210 | AD274: =IF(AND(F274="Closed",X274>=DATE(2026,7,1),X274<=DATE(2026,7,31)),"Closed In July","Other") -> Other
A275: 46143 | B275: 2026 | C275: Yanara Power | D275: IPP/Utility | F275: WIP | G275: Ashish Jindal | H275: 9983975581 | I275: PE01052601 | J275: Hotspot Issues | K275: Holi | L275: Maharashtra | M275: MULTIPLE HOTSPOT | N275: Hotspot | O275: 575 | P275: NSMI24070193981 | Q275: =MID(P275,5,2) -> 24 | R275: =MID(P275,7,2) -> 07 | S275: G2G | T275: P4 - PEIPL | U275: Multiple Hotspot Issue | V275: Onsite Inspection | W275: Under Investigation | Y275: =X275-A275 -> -46143 | Z275: 46210 | AD275: =IF(AND(F275="Closed",X275>=DATE(2026,7,1),X275<=DATE(2026,7,31)),"Closed In July","Other") -> Other
A276: 46143 | B276: 2026 | C276: Yanara Power | D276: IPP/Utility | F276: WIP | G276: Ashish Jindal | H276: 9983975581 | I276: PE01052601 | J276: Hotspot Issues | K276: Holi | L276: Maharashtra | M276: MULTIPLE HOTSPOT | N276: Hotspot | O276: 575 | P276: NSMI24070193969 | Q276: =MID(P276,5,2) -> 24 | R276: =MID(P276,7,2) -> 07 | S276: G2G | T276: P4 - PEIPL | U276: Multiple Hotspot Issue | V276: Onsite Inspection | W276: Under Investigation | Y276: =X276-A276 -> -46143 | Z276: 46210 | AD276: =IF(AND(F276="Closed",X276>=DATE(2026,7,1),X276<=DATE(2026,7,31)),"Closed In July","Other") -> Other
A277: 46134 | B277: 2026 | C277: First Energy | D277: Utility and C&I | F277: Closed | G277: Saravanakumar | H277: 8248438488 | I277: PE22042601 | J277: Anomalies/defects in the modules | K277: Tirunelveli | L277: Tamil Nadu | M277: PS | N277: Cold Soldering | O277: 550 | P277: NSMP2306223153 | Q277: =MID(P277,5,2) -> 23 | R277: =MID(P277,7,2) -> 06 | S277: G2B | T277: P2 - PEPPL | U277: P JB Cold Soldering | V277: Soldering | W277: Repair | X277: 46211 | Y277: =X277-A277 -> 77 | Z277: 46211 | AD277: =IF(AND(F277="Closed",X277>=DATE(2026,7,1),X277<=DATE(2026,7,31)),"Closed In July","Other") -> Closed In July
A278: 46134 | B278: 2026 | C278: First Energy | D278: Utility and C&I | F278: Closed | G278: Saravanakumar | H278: 8248438488 | I278: PE22042601 | J278: Anomalies/defects in the modules | K278: Tirunelveli | L278: Tamil Nadu | M278: PS | N278: Cold Soldering | O278: 550 | P278: NSMP2305158511 | Q278: =MID(P278,5,2) -> 23 | R278: =MID(P278,7,2) -> 05 | S278: G2B | T278: P2 - PEPPL | U278: P JB Cold Soldering | V278: Soldering | W278: Repair | X278: 46211 | Y278: =X278-A278 -> 77 | Z278: 46211 | AD278: =IF(AND(F278="Closed",X278>=DATE(2026,7,1),X278<=DATE(2026,7,31)),"Closed In July","Other") -> Closed In July
A279: 46134 | B279: 2026 | C279: First Energy | D279: Utility and C&I | F279: Closed | G279: Saravanakumar | H279: 8248438488 | I279: PE22042601 | J279: Anomalies/defects in the modules | K279: Tirunelveli | L279: Tamil Nadu | M279: PS | N279: Cold Soldering | O279: 550 | P279: NSMP2306224023 | Q279: =MID(P279,5,2) -> 23 | R279: =MID(P279,7,2) -> 06 | S279: G2B | T279: P2 - PEPPL | U279: P JB Cold Soldering | V279: Soldering | W279: Repair | X279: 46211 | Y279: =X279-A279 -> 77 | Z279: 46211 | AD279: =IF(AND(F279="Closed",X279>=DATE(2026,7,1),X279<=DATE(2026,7,31)),"Closed In July","Other") -> Closed In July
A280: 46134 | B280: 2026 | C280: First Energy | D280: Utility and C&I | F280: Closed | G280: Saravanakumar | H280: 8248438488 | I280: PE22042601 | J280: Anomalies/defects in the modules | K280: Tirunelveli | L280: Tamil Nadu | M280: PS | N280: Cold Soldering | O280: 550 | P280: NSMP2305160761 | Q280: =MID(P280,5,2) -> 23 | R280: =MID(P280,7,2) -> 05 | S280: G2B | T280: P2 - PEPPL | U280: P JB Cold Soldering | V280: Soldering | W280: Repair | X280: 46211 | Y280: =X280-A280 -> 77 | Z280: 46211 | AD280: =IF(AND(F280="Closed",X280>=DATE(2026,7,1),X280<=DATE(2026,7,31)),"Closed In July","Other") -> Closed In July
A281: 46134 | B281: 2026 | C281: First Energy | D281: Utility and C&I | F281: Closed | G281: Saravanakumar | H281: 8248438488 | I281: PE22042601 | J281: Anomalies/defects in the modules | K281: Tirunelveli | L281: Tamil Nadu | M281: PS | N281: Cold Soldering | O281: 550 | P281: NSMP2305160592 | Q281: =MID(P281,5,2) -> 23 | R281: =MID(P281,7,2) -> 05 | S281: G2B | T281: P2 - PEPPL | U281: P JB Cold Soldering | V281: Soldering | W281: Repair | X281: 46211 | Y281: =X281-A281 -> 77 | Z281: 46211 | AD281: =IF(AND(F281="Closed",X281>=DATE(2026,7,1),X281<=DATE(2026,7,31)),"Closed In July","Other") -> Closed In July
A282: 46134 | B282: 2026 | C282: First Energy | D282: Utility and C&I | F282: Closed | G282: Saravanakumar | H282: 8248438488 | I282: PE22042601 | J282: Anomalies/defects in the modules | K282: Tirunelveli | L282: Tamil Nadu | M282: PS | N282: Cold Soldering | O282: 550 | P282: NSMP2305158542 | Q282: =MID(P282,5,2) -> 23 | R282: =MID(P282,7,2) -> 05 | S282: G2B | T282: P2 - PEPPL | U282: P JB Cold Soldering | V282: Soldering | W282: Repair | X282: 46211 | Y282: =X282-A282 -> 77 | Z282: 46211 | AD282: =IF(AND(F282="Closed",X282>=DATE(2026,7,1),X282<=DATE(2026,7,31)),"Closed In July","Other") -> Closed In July
...
