Workbook

Sheet Dashboard
U1: CHART DATA (linked)
B2: FIELD SERVICE DASHBOARD
B3: May 2026 • Solar Module Complaints & Defect Analysis | U3: Site | V3: Modules
U4: ='May-26 Analysis'!A19 | V4: ='May-26 Analysis'!B19
B5: Total Complaints | E5: Closed Modules | H5: WIP / Open | K5: Closure Rate | N5: Avg Resolution | U5: ='May-26 Analysis'!A20 | V5: ='May-26 Analysis'!B20
B6: ='May-26 Analysis'!B5 | E6: ='May-26 Analysis'!C5 | H6: ='May-26 Analysis'!D5 | K6: ='May-26 Analysis'!F5 | N6: ='May-26 Analysis'!I5 | U6: ='May-26 Analysis'!A21 | V6: ='May-26 Analysis'!B21
U7: ='May-26 Analysis'!A22 | V7: ='May-26 Analysis'!B22
B8: Daily Complaints Trend - May 2026 | U8: ='May-26 Analysis'!A23 | V8: ='May-26 Analysis'!B23
U9: ='May-26 Analysis'!A24 | V9: ='May-26 Analysis'!B24
U10: ='May-26 Analysis'!A25 | V10: ='May-26 Analysis'!B25
U11: ='May-26 Analysis'!A26 | V11: ='May-26 Analysis'!B26
U12: State | V12: Modules
U13: ='May-26 Analysis'!G19 | V13: ='May-26 Analysis'!H19
U14: ='May-26 Analysis'!G20 | V14: ='May-26 Analysis'!H20
U15: ='May-26 Analysis'!G21 | V15: ='May-26 Analysis'!H21
U16: ='May-26 Analysis'!G22 | V16: ='May-26 Analysis'!H22
U17: ='May-26 Analysis'!G23 | V17: ='May-26 Analysis'!H23
U18: ='May-26 Analysis'!G24 | V18: ='May-26 Analysis'!H24
U19: ='May-26 Analysis'!G25 | V19: ='May-26 Analysis'!H25
U20: ='May-26 Analysis'!G26 | V20: ='May-26 Analysis'!H26
U22: Defect Type | V22: Count
B23: Complaints by Site (Top 8) | H23: Complaints by State | N23: Defect Type Mix | U23: ='Defect Analysis May-26'!A9 | V23: ='Defect Analysis May-26'!B9
U24: ='Defect Analysis May-26'!A13 | V24: ='Defect Analysis May-26'!B13
U25: ='Defect Analysis May-26'!A16 | V25: ='Defect Analysis May-26'!B16
U26: ='Defect Analysis May-26'!A11 | V26: ='Defect Analysis May-26'!B11
U27: Others | V27: ='Defect Analysis May-26'!B18+'Defect Analysis May-26'!B6+'Defect Analysis May-26'!B7+'Defect Analysis May-26'!B8+'Defect Analysis May-26'!B10+'Defect Analysis May-26'!B12+'Defect Analysis May-26'!B14+'Defect Analysis May-26'!B17
U37: Week | V37: Modules
U38: ='May-26 Analysis'!G46 | V38: ='May-26 Analysis'!H46
U39: ='May-26 Analysis'!G47 | V39: ='May-26 Analysis'!H47
B40: Resolution Time (TAT) Distribution | H40: Weekly Complaint Volume | U40: ='May-26 Analysis'!G48 | V40: ='May-26 Analysis'!H48
U41: ='May-26 Analysis'!G49 | V41: ='May-26 Analysis'!H49
U42: ='May-26 Analysis'!G50 | V42: ='May-26 Analysis'!H50
U45: Date | V45: Visited | W45: Closed
U46: ='May-26 Analysis'!A40 | V46: ='May-26 Analysis'!B40 | W46: ='May-26 Analysis'!C40
U47: ='May-26 Analysis'!A41 | V47: ='May-26 Analysis'!B41 | W47: ='May-26 Analysis'!C41
U48: ='May-26 Analysis'!A42 | V48: ='May-26 Analysis'!B42 | W48: ='May-26 Analysis'!C42
U49: ='May-26 Analysis'!A43 | V49: ='May-26 Analysis'!B43 | W49: ='May-26 Analysis'!C43
U50: ='May-26 Analysis'!A44 | V50: ='May-26 Analysis'!B44 | W50: ='May-26 Analysis'!C44
U51: ='May-26 Analysis'!A45 | V51: ='May-26 Analysis'!B45 | W51: ='May-26 Analysis'!C45
U52: ='May-26 Analysis'!A46 | V52: ='May-26 Analysis'!B46 | W52: ='May-26 Analysis'!C46
...

Sheet Daily Report May-26 
A1: Date | B1: Site | C1: Area | D1: State | E1: No Of Complaints | F1: Visited by | G1: Complaint ID | H1: Status | I1: Remarks | J1: Complaints Register Link | K1: Start Date | L1: End Day | M1: Remarka
A2: 46143 | B2: Panasonic | C2: Mysore | D2: Karnataka | E2: 1 | F2: Amit | G2: PE28042604 | H2: Closed | I2: Retrofit | J2: PE28042604 | K2: 46143 | L2: 46144
A3: 46143 | B3: Axitec Energy | C3: Chinchwad | D3: Maharashtra | E3: 2 | F3: Bani | G3: PE21042602 | H3: Closed | I3: Retrofit | J3: PE21042602 | K3: 46143
A4: 46143 | B4: First Energy | C4: Rajkot | D4: Gujarat | E4: 24 | F4: Kunal & Nilanjan | G4: PE25032601 | H4: WIP | I4: Inspection | J4: PE25032601 | K4: 46143
A5: 46144 | B5: First Energy | C5: Rajkot | D5: Gujarat | E5: 20 | F5: Kunal & Nilanjan | G5: PE25032601 | H5: WIP | I5: Inspection | J5: PE25032601
A6: 46144 | B6: Blupine | C6: Sadla | D6: Gujarat | E6: 52 | F6: Bhimsen + Raja | G6: PE26032601 | H6: Closed | I6: Retrofit | J6: PE26032601 | K6: 46143
A7: 46144 | B7: Panasonic | C7: Dhule | D7: Maharashtra | E7: 1 | F7: Bani | G7: PE06042602 | H7: Closed | I7: Rejected | J7: PE06042602
A8: 46144 | B8: Panasonic | C8: Dhule | D8: Maharashtra | E8: 1 | F8: Bani | G8: PE06042602 | H8: WIP | I8: Inspection | J8: PE06042602
A9: 46146 | B9: Solar Square | C9: Hyderabad | D9: Telangana | E9: 4 | F9: By Mail | G9: PE26032602 | H9: Closed | I9: CN | J9: PE26032602
A10: 46146 | B10: TRUE SUN TRADING COMPANY | C10: CHANGANASSERRY | D10: Kerala | E10: 1 | F10: By Mail | G10: PE27042603 | H10: Closed | I10: CN | J10: PE27042603
A11: 46146 | B11: RA GREEN ENERGks | C11: Nagpur | D11: Maharashtra | E11: 1 | F11: Bani | G11: PE31032602 | H11: Closed | I11: Retrofit | J11: PE31032602
A12: 46146 | B12: Panasonic | C12: Lucknow | D12: UP | E12: 3 | F12: Kamal | G12: PE07042601 | H12: Closed | I12: Repair | J12: PE07042601 | K12: 46145
A13: 46146 | B13: Oyster Technocon | C13: Nagpur | D13: Maharashtra | E13: 12 | F13: Bani | G13: PE02052601 | H13: Closed | I13: Retrofit | J13: PE02052601
A14: 46146 | B14: First Energy | C14: Rajkot | D14: Gujarat | E14: 53 | F14: Kunal & Nilanjan | G14: PE25032601 | H14: WIP | I14: Inspection | J14: PE25032601
A15: 46146 | B15: Blupine | C15: Sadla | D15: Gujarat | E15: 64 | F15: Bhimsen + Raja | G15: PE26032601 | H15: Closed | I15: Retrofit | J15: PE26032601
A16: 46147 | B16: Solar Square | C16: Kanpur | D16: UP | E16: 1 | F16: Kamal | G16: PE30042601 | H16: Closed | I16: Retrofit | J16: PE30042601 | L16: 46147
A17: 46147 | B17: Solar Square | C17: Jabalpur | D17: MP | E17: 1 | F17: Bani | G17: PE29042602 | H17: Closed | I17: Retrofit | J17: PE29042602
A18: 46147 | B18: Solar Square | C18: Jabalpur | D18: MP | E18: 1 | F18: Bani | G18: PE09042601 | H18: Closed | I18: Retrofit | J18: PE09042601
A19: 46147 | B19: First Energy | C19: Rajkot | D19: Gujarat | E19: 55 | F19: Kunal & Nilanjan | G19: PE25032601 | H19: WIP | I19: Inspection | J19: PE25032601
A20: 46147 | B20: Blupine | C20: Sadla | D20: Gujarat | E20: 53 | F20: Bhimsen + Raja | G20: PE26032601 | H20: Closed | I20: Retrofit | J20: PE26032601
A21: 46147 | B21: TRUE SUN TRADING COMPANY | C21: Trivandram | D21: Kerala | E21: 1 | F21: By Mail | G21: PE18022602 | H21: Closed | I21: CN | J21: PE18022602
A22: 46147 | B22: TRUE SUN TRADING COMPANY | C22: Thrissur | D22: Kerala | E22: 1 | F22: By Mail | G22: PE20022602 | H22: Closed | I22: CN | J22: PE20022602
A23: 46147 | B23: TRUE SUN TRADING COMPANY | C23: TRIVANDRAM | D23: Kerala | E23: 1 | F23: By Mail | G23: PE24042601 | H23: Closed | I23: CN | J23: PE24042601
A24: 46147 | B24: TRUE SUN TRADING COMPANY | C24: TRIVANDRAM | D24: Kerala | E24: 1 | F24: By Mail | G24: PE24042602 | H24: Closed | I24: CN | J24: PE24042602
A25: 46148 | B25: Solar Square | C25: Indore | D25: MP | E25: 2 | F25: Bani | G25: PE26022602 | H25: Closed | I25: Retrofit | J25: PE26022602 | M25: 46150
A26: 46148 | B26: Blupine | C26: Sadla | D26: Gujarat | E26: 58 | F26: Bhimsen + Raja | G26: PE26032601 | H26: Closed | I26: Retrofit | J26: PE26032601
A27: 46148 | B27: First Energy | C27: Rajkot | D27: Gujarat | E27: 34 | F27: Kunal & Nilanjan | G27: PE25032601 | H27: WIP | I27: Inspection | J27: PE25032601
A28: 46149 | B28: First Energy | C28: Rajkot | D28: Gujarat | E28: 5 | F28: Kunal & Nilanjan | G28: PE25032601 | H28: WIP | I28: Inspection | J28: PE25032601 | L28: 46149
A29: 46149 | B29: Blupine | C29: Sadla | D29: Gujarat | E29: 44 | F29: Bhimsen + Raja | G29: PE26032601 | H29: Closed | I29: Retrofit | J29: PE26032601
A30: 46150 | B30: Cresta solar | C30: Hyderabad | D30: Telangana | E30: 1 | F30: By Mail | G30: PE07052601 | H30: Closed | I30: Replacement | J30: PE07052601
A31: 46150 | B31: Blupine | C31: Sadla | D31: Gujarat | E31: 52 | F31: Bhimsen + Raja | G31: PE26032601 | H31: Closed | I31: Retrofit | J31: PE26032601
A32: 46151 | B32: Blupine | C32: Sadla | D32: Gujarat | E32: 80 | F32: Bhimsen + Raja + Nilanjan + Kunal | G32: PE26032601 | H32: Closed | I32: Retrofit | J32: PE26032601
A33: 46153 | B33: Blupine | C33: Sadla | D33: Gujarat | E33: 85 | F33: Bhimsen + Raja + Nilanjan + Kunal | G33: PE26032601 | H33: Closed | I33: Retrofit | J33: PE26032601
A34: 46153 | B34: Yanara Power | C34: Holi | D34: Maharashtra | E34: 26 | F34: Gourab + Amit + Bani | G34: PE01052601 | H34: Closed | I34: Retrofit | J34: PE01052601 | K34: 46149
A35: 46154 | B35: Blupine | C35: Sadla | D35: Gujarat | E35: 88 | F35: Bhimsen + Raja + Nilanjan + Kunal | G35: PE26032601 | H35: Closed | I35: Retrofit | J35: PE26032601
A36: 46155 | B36: Uma Trading | C36: Sangli | D36: Maharashtra | E36: 1 | F36: By Mail | G36: PE12052604 | H36: Closed | I36: Rejected | J36: PE12052604
A37: 46155 | B37: Blupine | C37: Sadla | D37: Gujarat | E37: 55 | F37: Bhimsen + Raja + Kunal + Kamal | G37: PE26032601 | H37: Closed | I37: Retrofit | J37: PE26032601
A38: 46155 | B38: Yanara Power | C38: Holi | D38: Maharashtra | E38: 37 | F38: Gourab + Amit + Bani | G38: PE01052601 | H38: Closed | I38: Retrofit | J38: PE01052601
A39: 46156 | B39: Solar Square | C39: Hyderabad | D39: Telangana | E39: 1 | F39: Pavan | G39: PE27042601 | H39: Closed | I39: Retrofit | J39: PE27042601 | K39: 46156
A40: 46156 | B40: Solar Square | C40: Hyderabad | D40: Telangana | E40: 2 | F40: Pavan | G40: PE27042602 | H40: Closed | I40: Retrofit | J40: PE27042602 | M40: 46156
...

Sheet Monthly Report May-26 (2)
A1: Date | B1: Year | C1: Complaint Raised By | D1: Customer Type | E1: Project Name | F1: Current Status | G1: Claim Reported By | H1: Contact No. | I1: Contract / Complaint / Invoice No. | J1: Customer Reported Problem | K1: Venue / Location | L1: State | M1: Field Evaluation | N1: Our Evaluation | O1: PV Panels Wp | P1: Module Serial Number | Q1: Module Make Year | R1: Module Make Month | S1: Moduel Type | T1: Manufacturing Plant | U1: Remark | V1: Action Taken | W1: Resolution Type | X1: Date of Claim Settled | Y1: Claim Settlement Duration | Z1: Visit Date | AA1: Rework Srl No. | AB1: Work details
A2: 46140 | B2: 2026 | C2: Panasonic | D2: OEM | F2: Closed | G2: Chirag Tare | H2: 7719846027 | I2: PE28042604 | J2: Low VOC | K2: Mysore | L2: Karnataka | M2: JB Issue | N2: JB Issue | O2: 550 | P2: NSMP2304007550 | Q2: =MID(P2,5,2) | R2: =MID(P2,7,2) | S2: G2B | T2: P2 | U2: All JB Issue | V2: JB Changed | W2: Repair | X2: 46143 | Y2: =X2-A2 | Z2: 46143
A3: 46133 | B3: 2026 | C3: Axitec Energy | D3: OEM | F3: Closed | G3: Dushyant | H3: 8826633540 | I3: PE21042602 | J3: Diode Failure | K3: Chinchwad | L3: Maharashtra | M3: Cold Soldering | N3: Cold Soldering | O3: 520 | P3: 26230431008130 | Q3: =MID(P3,3,2) | R3: =MID(P3,5,2) | S3: G2B | T3: P2 | U3: P JB Cold Soldering | V3: Soldering | W3: Repair | X3: 46143 | Y3: =X3-A3 | Z3: 46143
A4: 46133 | B4: 2026 | C4: Axitec Energy | D4: OEM | F4: Closed | G4: Dushyant | H4: 8826633540 | I4: PE21042602 | J4: Diode Failure | K4: Chinchwad | L4: Maharashtra | M4: Cold Soldering | N4: Cold Soldering | O4: 520 | P4: 26230431008116 | Q4: =MID(P4,3,2) | R4: =MID(P4,5,2) | S4: G2B | T4: P2 | U4: P JB Cold Soldering | V4: Soldering | W4: Repair | X4: 46143 | Y4: =X4-A4 | Z4: 46143
A5: 46106 | B5: 2026 | C5: First Energy | D5: Utility and C&I | F5: WIP | G5: Mr. Gaurav | H5: 9979185999 | I5: PE25032601 | J5: Module Defects | K5: Rajkot | L5: Gujarat | M5: hotspot found | N5: Hotspot | O5: 550 | P5: NSMP2409546021 | Q5: =MID(P5,5,2) | R5: =MID(P5,7,2) | S5: G2TB | T5: P2 | U5: Multi Cell Hotspot | V5: Inspection | W5: WIP | Y5: =X5-A5 | Z5: 46143
A6: 46106 | B6: 2026 | C6: First Energy | D6: Utility and C&I | F6: WIP | G6: Mr. Gaurav | H6: 9979185999 | I6: PE25032601 | J6: Module Defects | K6: Rajkot | L6: Gujarat | M6: hotspot found | N6: Hotspot | O6: 550 | P6: NSMP2212269256 | Q6: =MID(P6,5,2) | R6: =MID(P6,7,2) | S6: G2TB | T6: P2 | U6: Multi Cell Hotspot | V6: Inspection | W6: WIP | Y6: =X6-A6 | Z6: 46143
A7: 46106 | B7: 2026 | C7: First Energy | D7: Utility and C&I | F7: WIP | G7: Mr. Gaurav | H7: 9979185999 | I7: PE25032601 | J7: Module Defects | K7: Rajkot | L7: Gujarat | M7: hotspot found | N7: Hotspot | O7: 550 | P7: NSMP2212269311 | Q7: =MID(P7,5,2) | R7: =MID(P7,7,2) | S7: G2TB | T7: P2 | U7: Multi Cell Hotspot | V7: Inspection | W7: WIP | Y7: =X7-A7 | Z7: 46143
A8: 46106 | B8: 2026 | C8: First Energy | D8: Utility and C&I | F8: WIP | G8: Mr. Gaurav | H8: 9979185999 | I8: PE25032601 | J8: Module Defects | K8: Rajkot | L8: Gujarat | M8: hotspot found | N8: Hotspot | O8: 550 | P8: NSMP2212269144 | Q8: =MID(P8,5,2) | R8: =MID(P8,7,2) | S8: G2TB | T8: P2 | U8: Single Cell Hotspot | V8: Inspection | W8: WIP | Y8: =X8-A8 | Z8: 46143
A9: 46106 | B9: 2026 | C9: First Energy | D9: Utility and C&I | F9: WIP | G9: Mr. Gaurav | H9: 9979185999 | I9: PE25032601 | J9: Module Defects | K9: Rajkot | L9: Gujarat | M9: hotspot found | N9: Hotspot | O9: 550 | P9: NSMP2301302211 | Q9: =MID(P9,5,2) | R9: =MID(P9,7,2) | S9: G2TB | T9: P2 | U9: Multi Cell Hotspot | V9: Inspection | W9: WIP | Y9: =X9-A9 | Z9: 46143
A10: 46106 | B10: 2026 | C10: First Energy | D10: Utility and C&I | F10: WIP | G10: Mr. Gaurav | H10: 9979185999 | I10: PE25032601 | J10: Module Defects | K10: Rajkot | L10: Gujarat | M10: hotspot found | N10: Hotspot | O10: 550 | P10: NSMP2301328092 | Q10: =MID(P10,5,2) | R10: =MID(P10,7,2) | S10: G2TB | T10: P2 | U10: Single Cell Hotspot | V10: Inspection | W10: WIP | Y10: =X10-A10 | Z10: 46143
A11: 46106 | B11: 2026 | C11: First Energy | D11: Utility and C&I | F11: WIP | G11: Mr. Gaurav | H11: 9979185999 | I11: PE25032601 | J11: Module Defects | K11: Rajkot | L11: Gujarat | M11: hotspot found | N11: Hotspot | O11: 550 | P11: NSMP2212258292 | Q11: =MID(P11,5,2) | R11: =MID(P11,7,2) | S11: G2TB | T11: P2 | U11: Multi Cell Hotspot | V11: Inspection | W11: WIP | Y11: =X11-A11 | Z11: 46143
A12: 46106 | B12: 2026 | C12: First Energy | D12: Utility and C&I | F12: WIP | G12: Mr. Gaurav | H12: 9979185999 | I12: PE25032601 | J12: Module Defects | K12: Rajkot | L12: Gujarat | M12: hotspot found | N12: Hotspot | O12: 550 | P12: NSMP2212269072 | Q12: =MID(P12,5,2) | R12: =MID(P12,7,2) | S12: G2TB | T12: P2 | U12: Multi Cell Hotspot | V12: Inspection | W12: WIP | Y12: =X12-A12 | Z12: 46143
A13: 46106 | B13: 2026 | C13: First Energy | D13: Utility and C&I | F13: WIP | G13: Mr. Gaurav | H13: 9979185999 | I13: PE25032601 | J13: Module Defects | K13: Rajkot | L13: Gujarat | M13: Broken Module | N13: Hotspot | O13: 550 | P13: NSMP2212277874 | Q13: =MID(P13,5,2) | R13: =MID(P13,7,2) | S13: G2TB | T13: P2 | U13: Multi Cell Hotspot | V13: Inspection | W13: WIP | Y13: =X13-A13 | Z13: 46143
A14: 46106 | B14: 2026 | C14: First Energy | D14: Utility and C&I | F14: WIP | G14: PE02052602 | H14: 9979185999 | I14: PE25032601 | J14: Module Defects | K14: Rajkot | L14: Gujarat | M14: hotspot found | N14: Hotspot | O14: 550 | P14: NSMP2212277882 | Q14: =MID(P14,5,2) | R14: =MID(P14,7,2) | S14: G2TB | T14: P2 | U14: Multi Cell Hotspot | V14: Inspection | W14: WIP | Y14: =X14-A14 | Z14: 46143
A15: 46106 | B15: 2026 | C15: First Energy | D15: Utility and C&I | F15: WIP | G15: Mr. Gaurav | H15: 9979185999 | I15: PE25032601 | J15: Module Defects | K15: Rajkot | L15: Gujarat | M15: hotspot found | N15: Hotspot | O15: 550 | P15: NSMP2212270587 | Q15: =MID(P15,5,2) | R15: =MID(P15,7,2) | S15: G2TB | T15: P2 | U15: Multi Cell Hotspot | V15: Inspection | W15: WIP | Y15: =X15-A15 | Z15: 46143
A16: 46106 | B16: 2026 | C16: First Energy | D16: Utility and C&I | F16: WIP | G16: Mr. Gaurav | H16: 9979185999 | I16: PE25032601 | J16: Module Defects | K16: Rajkot | L16: Gujarat | M16: hotspot found | N16: Hotspot | O16: 550 | P16: NSMP2212277215 | Q16: =MID(P16,5,2) | R16: =MID(P16,7,2) | S16: G2TB | T16: P2 | U16: Multi Cell Hotspot | V16: Inspection | W16: WIP | Y16: =X16-A16 | Z16: 46143
... A48: 46106 | B48: 2026 | C48: First Energy | D48: Utility and C&I | F48: WIP | G48: Mr. Gaurav | H48: 9979185999 | I48: PE25032601 | J48: Module Defects | K48: Rajkot | L48: Gujarat | M48: hotspot found | N48: Hotspot | O48: 550 | P48: NSMP2212283852 | Q48: =MID(P48,5,2) | R48: =MID(P48,7,2) | S48: G2TB | T48: P2 | U48: Single Cell Hotspot | V48: Inspection | W48: WIP | Y48: =X48-A48 | Z48: 46144
A49: 46107 | B49: 2026 | C49: Blupine | D49: Utility and C&I | F49: Closed | G49: Chandrashekar Patidar | H49: 7879764773 | I49: PE26032601 | J49: Module Diode Failure | K49: Sadla | L49: Gujarat | M49: PS | N49: Cold Soldering | O49: 570 | P49: NSMI24050051443 | Q49: =MID(P49,5,2) | R49: =MID(P49,7,2) | S49: G2G | T49: P4 | U49: P JB Cold Soldering | V49: Soldering | W49: Repair | X49: 46144 | Y49: =X49-A49 | Z49: 46144
A50: 46107 | B50: 2026 | C50: Blupine | D50: Utility and C&I | F50: Closed | G50: Chandrashekar Patidar | H50: 7879764773 | I50: PE26032601 | J50: Module Diode Failure | K50: Sadla | L50: Gujarat | M50: NS | N50: Cold Soldering | O50: 570 | P50: NSMI24050044810 | Q50: =MID(P50,5,2) | R50: =MID(P50,7,2) | S50: G2G | T50: P4 | U50: N JB Cold Soldering | V50: Soldering | W50: Repair | X50: 46144 | Y50: =X50-A50 | Z50: 46144
A51: 46107 | B51: 2026 | C51: Blupine | D51: Utility and C&I | F51: Closed | G51: Chandrashekar Patidar | H51: 7879764773 | I51: PE26032601 | J51: Module Diode Failure | K51: Sadla | L51: Gujarat | M51: NS | N51: Cold Soldering | O51: 570 | P51: NSMI24050047018 | Q51: =MID(P51,5,2) | R51: =MID(P51,7,2) | S51: G2G | T51: P4 | U51: N JB Cold Soldering | V51: Soldering | W51: Repair | X51: 46144 | Y51: =X51-A51 | Z51: 46144
A52: 46107 | B52: 2026 | C52: Blupine | D52: Utility and C&I | F52: Closed | G52: Chandrashekar Patidar | H52: 7879764773 | I52: PE26032601 | J52: Module Diode Failure | K52: Sadla | L52: Gujarat | M52: PR | N52: JB Issue | O52: 570 | P52: NSMI24060074092 | Q52: =MID(P52,5,2) | R52: =MID(P52,7,2) | S52: G2G | T52: P4 | U52: P JB Issue | V52: JB Changed | W52: Repair | X52: 46144 | Y52: =X52-A52 | Z52: 46144
A53: 46107 | B53: 2026 | C53: Blupine | D53: Utility and C&I | F53: Closed | G53: Chandrashekar Patidar | H53: 7879764773 | I53: PE26032601 | J53: Module Diode Failure | K53: Sadla | L53: Gujarat | M53: NR | N53: JB Issue | O53: 570 | P53: NSMI24050045987 | Q53: =MID(P53,5,2) | R53: =MID(P53,7,2) | S53: G2G | T53: P4 | U53: N JB Issue | V53: JB Changed | W53: Repair | X53: 46144 | Y53: =X53-A53 | Z53: 46144
A54: 46107 | B54: 2026 | C54: Blupine | D54: Utility and C&I | F54: Closed | G54: Chandrashekar Patidar | H54: 7879764773 | I54: PE26032601 | J54: Module Diode Failure | K54: Sadla | L54: Gujarat | M54: PS | N54: Cold Soldering | O54: 570 | P54: NSMI24050049041 | Q54: =MID(P54,5,2) | R54: =MID(P54,7,2) | S54: G2G | T54: P4 | U54: P JB Cold Soldering | V54: Soldering | W54: Repair | X54: 46144 | Y54: =X54-A54 | Z54: 46144
A55: 46107 | B55: 2026 | C55: Blupine | D55: Utility and C&I | F55: Closed | G55: Chandrashekar Patidar | H55: 7879764773 | I55: PE26032601 | J55: Module Diode Failure | K55: Sadla | L55: Gujarat | M55: NS | N55: Cold Soldering | O55: 570 | P55: NSMI24050045772 | Q55: =MID(P55,5,2) | R55: =MID(P55,7,2) | S55: G2G | T55: P4 | U55: N JB Cold Soldering | V55: Soldering | W55: Repair | X55: 46144 | Y55: =X55-A55 | Z55: 46144
A56: 46107 | B56: 2026 | C56: Blupine | D56: Utility and C&I | F56: Closed | G56: Chandrashekar Patidar | H56: 7879764773 | I56: PE26032601 | J56: Module Diode Failure | K56: Sadla | L56: Gujarat | M56: NS | N56: Cold Soldering | O56: 570 | P56: NSMI24050045804 | Q56: =MID(P56,5,2) | R56: =MID(P56,7,2) | S56: G2G | T56: P4 | U56: N JB Cold Soldering | V56: Soldering | W56: Repair | X56: 46144 | Y56: =X56-A56 | Z56: 46144
A57: 46107 | B57: 2026 | C57: Blupine | D57: Utility and C&I | F57: Closed | G57: Chandrashekar Patidar | H57: 7879764773 | I57: PE26032601 | J57: Module Diode Failure | K57: Sadla | L57: Gujarat | M57: NS | N57: Cold Soldering | O57: 570 | P57: NSMI24050045790 | Q57: =MID(P57,5,2) | R57: =MID(P57,7,2) | S57: G2G | T57: P4 | U57: N JB Cold Soldering | V57: Soldering | W57: Repair | X57: 46144 | Y57: =X57-A57 | Z57: 46144
A58: 46107 | B58: 2026 | C58: Blupine | D58: Utility and C&I | F58: Closed | G58: Chandrashekar Patidar | H58: 7879764773 | I58: PE26032601 | J58: Module Diode Failure | K58: Sadla | L58: Gujarat | M58: PNS | N58: Cold Soldering | O58: 570 | P58: NSMI24080334590 | Q58: =MID(P58,5,2) | R58: =MID(P58,7,2) | S58: G2G | T58: P4 | U58: P & N JB Cold Soldering | V58: Soldering | W58: Repair | X58: 46144 | Y58: =X58-A58 | Z58: 46144
A59: 46107 | B59: 2026 | C59: Blupine | D59: Utility and C&I | F59: Closed | G59: Chandrashekar Patidar | H59: 7879764773 | I59: PE26032601 | J59: Module Diode Failure | K59: Sadla | L59: Gujarat | M59: NS | N59: Cold Soldering | O59: 570 | P59: NSMI24050045988 | Q59: =MID(P59,5,2) | R59: =MID(P59,7,2) | S59: G2G | T59: P4 | U59: N JB Cold Soldering | V59: Soldering | W59: Repair | X59: 46144 | Y59: =X59-A59 | Z59: 46144
A60: 46107 | B60: 2026 | C60: Blupine | D60: Utility and C&I | F60: Closed | G60: Chandrashekar Patidar | H60: 7879764773 | I60: PE26032601 | J60: Module Diode Failure | K60: Sadla | L60: Gujarat | M60: NS | N60: Cold Soldering | O60: 570 | P60: NSMI24050045952 | Q60: =MID(P60,5,2) | R60: =MID(P60,7,2) | S60: G2G | T60: P4 | U60: N JB Cold Soldering | V60: Soldering | W60: Repair | X60: 46144 | Y60: =X60-A60 | Z60: 46144
... A100: 46107 | B100: 2026 | C100: Blupine | D100: Utility and C&I | F100: Closed | G100: Chandrashekar Patidar | H100: 7879764773 | I100: PE26032601 | J100: Module Diode Failure | K100: Sadla | L100: Gujarat | M100: PS | N100: Cold Soldering | O100: 570 | P100: NSMI24060079795 | Q100: =MID(P100,5,2) | R100: =MID(P100,7,2) | S100: G2G | T100: P4 | U100: P JB Cold Soldering | V100: Soldering | W100: Repair | X100: 46144 | Y100: =X100-A100 | Z100: 46144
A101: 46118 | B101: 2026 | C101: Panasonic | D101: OEM | F101: WIP | G101: Chirag Tare | H101: 7719846027 | I101: PE06042602 | J101: Low VOC | K101: Dhule | L101: Maharashtra | M101: Backsheet Scratches | N101: Backsheet Scratches | O101: 330 | P101: NSM210403505 | Q101: =MID(P101,4,2) | R101: =MID(P101,6,2) | S101: G2B | T101: P1 | U101: Backsheet Scratches | V101: Rejected | W101: Rejected | X101: 46144 | Y101: =X101-A101 | Z101: 46144
A102: 46118 | B102: 2026 | C102: Panasonic | D102: OEM | F102: WIP | G102: Chirag Tare | H102: 7719846027 | I102: PE06042602 | J102: Low VOC | K102: Dhule | L102: Maharashtra | M102: Cell Contamination | N102: Cell Contamination | O102: 330 | P102: NSM210446420 | Q102: =MID(P102,4,2) | R102: =MID(P102,6,2) | S102: G2B | T102: P1 | U102: Cell Contamination | V102: Inspection | W102: WIP | Y102: =X102-A102 | Z102: 46144
A103: 46112 | B103: 2026 | C103: RA GREEN ENERGks | D103: Channel Sales | F103: Closed | G103: Kumar Tale | H103: 9518921202 | I103: PE31032602 | J103: MC 4 Connector Burn | K103: Nagpur | L103: Maharashtra | M103: Found okay | N103: No Issue | O103: 540 | P103: NSMP25050188956 | Q103: =MID(P103,5,2) | R103: =MID(P103,7,2) | S103: G2TB | T103: P2 | U103: No Issue Found | V103: Found OK | W103: Repair | X103: 46146 | Y103: =X103-A103 | Z103: 46146
A104: 46119 | B104: 2026 | C104: Panasonic | D104: OEM | F104: Closed | G104: Chirag Tare | H104: 7719846027 | I104: PE07042601 | J104: Low VOC | K104: Lucknow | L104: UP | M104: Negative JB Soldering | N104: Cold Soldering | O104: 495 | P104: NSMP2211233510 | Q104: =MID(P104,5,2) | R104: =MID(P104,7,2) | S104: G2B | T104: P2 | U104: N JB Cold Soldering | V104: Soldering | W104: Repair | X104: 46146 | Y104: =X104-A104 | Z104: 46146
A105: 46119 | B105: 2026 | C105: Panasonic | D105: OEM | F105: Closed | G105: Chirag Tare | H105: 7719846027 | I105: PE07042601 | J105: Low VOC | K105: Lucknow | L105: UP | M105: Negative JB Soldering | N105: Cold Soldering | O105: 495 | P105: NSMP2211233542 | Q105: =MID(P105,5,2) | R105: =MID(P105,7,2) | S105: G2B | T105: P2 | U105: N JB Cold Soldering | V105: Soldering | W105: Repair | X105: 46146 | Y105: =X105-A105 | Z105: 46146
A106: 46119 | B106: 2026 | C106: Panasonic | D106: OEM | F106: Closed | G106: Chirag Tare | H106: 7719846027 | I106: PE07042601 | J106: Low VOC | K106: Lucknow | L106: UP | M106: Negative JB Soldering | N106: Cold Soldering | O106: 495 | P106: NSMP2211233550 | Q106: =MID(P106,5,2) | R106: =MID(P106,7,2) | S106: G2B | T106: P2 | U106: N JB Cold Soldering | V106: Soldering | W106: Repair | X106: 46146 | Y106: =X106-A106 | Z106: 46146
A107: 46144 | B107: 2026 | C107: Oyster Technocon | D107: Channel Sales | F107: Closed | G107: Inderpal Singh | H107: 9028940248 | I107: PE02052601 | J107: Low solar panel generation | K107: Nagpur | L107: Maharashtra | M107: Found okay | N107: No Issue | O107: 540 | P107: N/A | Q107: =MID(P107,5,2) | R107: =MID(P107,7,2) | S107: G2TB | T107: P2 | U107: No Issue Found | V107: Found OK | W107: Repair | X107: 46146 | Y107: =X107-A107 | Z107: 46146
A108: 46144 | B108: 2026 | C108: Oyster Technocon | D108: Channel Sales | F108: Closed | G108: Inderpal Singh | H108: 9028940248 | I108: PE02052601 | J108: Low solar panel generation | K108: Nagpur | L108: Maharashtra | M108: Found okay | N108: No Issue | O108: 540 | P108: N/A | Q108: =MID(P108,5,2) | R108: =MID(P108,7,2) | S108: G2TB | T108: P2 | U108: No Issue Found | V108: Found OK | W108: Repair | X108: 46146 | Y108: =X108-A108 | Z108: 46146
A109: 46144 | B109: 2026 | C109: Oyster Technocon | D109: Channel Sales | F109: Closed | G109: Inderpal Singh | H109: 9028940248 | I109: PE02052601 | J109: Low solar panel generation | K109: Nagpur | L109: Maharashtra | M109: Found okay | N109: No Issue | O109: 540 | P109: N/A | Q109: =MID(P109,5,2) | R109: =MID(P109,7,2) | S109: G2TB | T109: P2 | U109: No Issue Found | V109: Found OK | W109: Repair | X109: 46146 | Y109: =X109-A109 | Z109: 46146
A110: 46144 | B110: 2026 | C110: Oyster Technocon | D110: Channel Sales | F110: Closed | G110: Inderpal Singh | H110: 9028940248 | I110: PE02052601 | J110: Low solar panel generation | K110: Nagpur | L110: Maharashtra | M110: Found okay | N110: No Issue | O110: 540 | P110: N/A | Q110: =MID(P110,5,2) | R110: =MID(P110,7,2) | S110: G2TB | T110: P2 | U110: No Issue Found | V110: Found OK | W110: Repair | X110: 46146 | Y110: =X110-A110 | Z110: 46146
...

Sheet Monthly Report May-26 Cleaned
A1: Complaint Received Date | B1: Year | C1: Complaint Raised By | D1: Customer Type | E1: Project Name | F1: Current Status | G1: Claim Reported By | H1: Contact No. | I1: Contract / Complaint / Invoice No. | J1: Customer Reported Problem | K1: Venue / Location | L1: State | M1: Field Evaluation | N1: Our Evaluation | O1: PV Panels Wp | P1: Module Serial Number | Q1: Module Make Year | R1: Module Make Month | S1: Moduel Type | T1: Manufacturing Plant | U1: Remark | V1: Action Taken | W1: Resolution Type | X1: Date of Claim Settled | Y1: Claim Settlement Duration | Z1: Visit Date | AA1: Rework Srl No. | AB1: Work details | AF1: May Closed Flag
A2: 46140 | B2: 2026 | C2: Panasonic | D2: OEM | F2: Closed | G2: Chirag Tare | H2: 7719846027 | I2: PE28042604 | J2: Low VOC | K2: Mysore | L2: Karnataka | M2: JB Issue | N2: JB Issue | O2: 550 | P2: NSMP2304007550 | Q2: =MID(P2,5,2) | R2: =MID(P2,7,2) | S2: G2B | T2: P2 | U2: All JB Issue | V2: JB Changed | W2: Repair | X2: 46143 | Y2: =IF(X2="","",X2-A2) | Z2: 46143 | AF2: =IF(AND($F2="Closed",$X2>=DATE(2026,5,1),$X2<=DATE(2026,5,31)),"Closed in May","Other")
A3: 46133 | B3: 2026 | C3: Axitec Energy | D3: OEM | F3: Closed | G3: Dushyant | H3: 8826633540 | I3: PE21042602 | J3: Diode Failure | K3: Chinchwad | L3: Maharashtra | M3: Cold Soldering | N3: Cold Soldering | O3: 520 | P3: 26230431008130 | Q3: =MID(P3,3,2) | R3: =MID(P3,5,2) | S3: G2B | T3: P2 | U3: P JB Cold Soldering | V3: Soldering | W3: Repair | X3: 46143 | Y3: =IF(X3="","",X3-A3) | Z3: 46143 | AF3: =IF(AND($F3="Closed",$X3>=DATE(2026,5,1),$X3<=DATE(2026,5,31)),"Closed in May","Other")
A4: 46133 | B4: 2026 | C4: Axitec Energy | D4: OEM | F4: Closed | G4: Dushyant | H4: 8826633540 | I4: PE21042602 | J4: Diode Failure | K4: Chinchwad | L4: Maharashtra | M4: Cold Soldering | N4: Cold Soldering | O4: 520 | P4: 26230431008116 | Q4: =MID(P4,3,2) | R4: =MID(P4,5,2) | S4: G2B | T4: P2 | U4: P JB Cold Soldering | V4: Soldering | W4: Repair | X4: 46143 | Y4: =IF(X4="","",X4-A4) | Z4: 46143 | AF4: =IF(AND($F4="Closed",$X4>=DATE(2026,5,1),$X4<=DATE(2026,5,31)),"Closed in May","Other")
A5: 46106 | B5: 2026 | C5: First Energy | D5: Utility and C&I | F5: Closed | G5: Mr. Gaurav | H5: 9979185999 | I5: PE25032601 | J5: Module Defects | K5: Rajkot | L5: Gujarat | M5: hotspot found | N5: Hotspot | O5: 550 | P5: NSMP2409546021 | Q5: =MID(P5,5,2) | R5: =MID(P5,7,2) | S5: G2B | T5: P2 | U5: Multi Cell Hotspot | V5: Inspection | W5: Rejected | X5: =Z5 | Y5: =IF(X5="","",X5-A5) | Z5: 46143 | AF5: =IF(AND($F5="Closed",$X5>=DATE(2026,5,1),$X5<=DATE(2026,5,31)),"Closed in May","Other")
A6: 46106 | B6: 2026 | C6: First Energy | D6: Utility and C&I | F6: Closed | G6: Mr. Gaurav | H6: 9979185999 | I6: PE25032601 | J6: Module Defects | K6: Rajkot | L6: Gujarat | M6: hotspot found | N6: Hotspot | O6: 550 | P6: NSMP2212269256 | Q6: =MID(P6,5,2) | R6: =MID(P6,7,2) | S6: G2B | T6: P2 | U6: Multi Cell Hotspot | V6: Inspection | W6: Rejected | X6: =Z6 | Y6: =IF(X6="","",X6-A6) | Z6: 46143 | AF6: =IF(AND($F6="Closed",$X6>=DATE(2026,5,1),$X6<=DATE(2026,5,31)),"Closed in May","Other")
A7: 46106 | B7: 2026 | C7: First Energy | D7: Utility and C&I | F7: Closed | G7: Mr. Gaurav | H7: 9979185999 | I7: PE25032601 | J7: Module Defects | K7: Rajkot | L7: Gujarat | M7: hotspot found | N7: Hotspot | O7: 550 | P7: NSMP2212269311 | Q7: =MID(P7,5,2) | R7: =MID(P7,7,2) | S7: G2B | T7: P2 | U7: Multi Cell Hotspot | V7: Inspection | W7: Rejected | X7: =Z7 | Y7: =IF(X7="","",X7-A7) | Z7: 46143 | AF7: =IF(AND($F7="Closed",$X7>=DATE(2026,5,1),$X7<=DATE(2026,5,31)),"Closed in May","Other")
A8: 46106 | B8: 2026 | C8: First Energy | D8: Utility and C&I | F8: Closed | G8: Mr. Gaurav | H8: 9979185999 | I8: PE25032601 | J8: Module Defects | K8: Rajkot | L8: Gujarat | M8: hotspot found | N8: Hotspot | O8: 550 | P8: NSMP2212269144 | Q8: =MID(P8,5,2) | R8: =MID(P8,7,2) | S8: G2B | T8: P2 | U8: Single Cell Hotspot | V8: Inspection | W8: Rejected | X8: =Z8 | Y8: =IF(X8="","",X8-A8) | Z8: 46143 | AF8: =IF(AND($F8="Closed",$X8>=DATE(2026,5,1),$X8<=DATE(2026,5,31)),"Closed in May","Other")
A9: 46106 | B9: 2026 | C9: First Energy | D9: Utility and C&I | F9: Closed | G9: Mr. Gaurav | H9: 9979185999 | I9: PE25032601 | J9: Module Defects | K9: Rajkot | L9: Gujarat | M9: hotspot found | N9: Hotspot | O9: 550 | P9: NSMP2301302211 | Q9: =MID(P9,5,2) | R9: =MID(P9,7,2) | S9: G2B | T9: P2 | U9: Multi Cell Hotspot | V9: Inspection | W9: Rejected | X9: =Z9 | Y9: =IF(X9="","",X9-A9) | Z9: 46143 | AF9: =IF(AND($F9="Closed",$X9>=DATE(2026,5,1),$X9<=DATE(2026,5,31)),"Closed in May","Other")
A10: 46106 | B10: 2026 | C10: First Energy | D10: Utility and C&I | F10: Closed | G10: Mr. Gaurav | H10: 9979185999 | I10: PE25032601 | J10: Module Defects | K10: Rajkot | L10: Gujarat | M10: hotspot found | N10: Hotspot | O10: 550 | P10: NSMP2301328092 | Q10: =MID(P10,5,2) | R10: =MID(P10,7,2) | S10: G2B | T10: P2 | U10: Single Cell Hotspot | V10: Inspection | W10: Rejected | X10: =Z10 | Y10: =IF(X10="","",X10-A10) | Z10: 46143 | AF10: =IF(AND($F10="Closed",$X10>=DATE(2026,5,1),$X10<=DATE(2026,5,31)),"Closed in May","Other")
A11: 46106 | B11: 2026 | C11: First Energy | D11: Utility and C&I | F11: Closed | G11: Mr. Gaurav | H11: 9979185999 | I11: PE25032601 | J11: Module Defects | K11: Rajkot | L11: Gujarat | M11: hotspot found | N11: Hotspot | O11: 550 | P11: NSMP2212258292 | Q11: =MID(P11,5,2) | R11: =MID(P11,7,2) | S11: G2B | T11: P2 | U11: Multi Cell Hotspot | V11: Inspection | W11: Rejected | X11: =Z11 | Y11: =IF(X11="","",X11-A11) | Z11: 46143 | AF11: =IF(AND($F11="Closed",$X11>=DATE(2026,5,1),$X11<=DATE(2026,5,31)),"Closed in May","Other")
A12: 46106 | B12: 2026 | C12: First Energy | D12: Utility and C&I | F12: Closed | G12: Mr. Gaurav | H12: 9979185999 | I12: PE25032601 | J12: Module Defects | K12: Rajkot | L12: Gujarat | M12: hotspot found | N12: Hotspot | O12: 550 | P12: NSMP2212269072 | Q12: =MID(P12,5,2) | R12: =MID(P12,7,2) | S12: G2B | T12: P2 | U12: Multi Cell Hotspot | V12: Inspection | W12: Rejected | X12: =Z12 | Y12: =IF(X12="","",X12-A12) | Z12: 46143 | AF12: =IF(AND($F12="Closed",$X12>=DATE(2026,5,1),$X12<=DATE(2026,5,31)),"Closed in May","Other")
A13: 46106 | B13: 2026 | C13: First Energy | D13: Utility and C&I | F13: WIP | G13: Mr. Gaurav | H13: 9979185999 | I13: PE25032601 | J13: Module Defects | K13: Rajkot | L13: Gujarat | M13: Broken Module | N13: Hotspot | O13: 550 | P13: NSMP2212277874 | Q13: =MID(P13,5,2) | R13: =MID(P13,7,2) | S13: G2B | T13: P2 | U13: Multi Cell Hotspot | V13: Inspection | W13: WIP | Y13: =IF(X13="","",X13-A13) | Z13: 46143 | AF13: =IF(AND($F13="Closed",$X13>=DATE(2026,5,1),$X13<=DATE(2026,5,31)),"Closed in May","Other")
A14: 46106 | B14: 2026 | C14: First Energy | D14: Utility and C&I | F14: Closed | G14: PE02052602 | H14: 9979185999 | I14: PE25032601 | J14: Module Defects | K14: Rajkot | L14: Gujarat | M14: hotspot found | N14: Hotspot | O14: 550 | P14: NSMP2212277882 | Q14: =MID(P14,5,2) | R14: =MID(P14,7,2) | S14: G2B | T14: P2 | U14: Multi Cell Hotspot | V14: Inspection | W14: Rejected | X14: =Z14 | Y14: =IF(X14="","",X14-A14) | Z14: 46143 | AF14: =IF(AND($F14="Closed",$X14>=DATE(2026,5,1),$X14<=DATE(2026,5,31)),"Closed in May","Other")
A15: 46106 | B15: 2026 | C15: First Energy | D15: Utility and C&I | F15: Closed | G15: Mr. Gaurav | H15: 9979185999 | I15: PE25032601 | J15: Module Defects | K15: Rajkot | L15: Gujarat | M15: hotspot found | N15: Hotspot | O15: 550 | P15: NSMP2212270587 | Q15: =MID(P15,5,2) | R15: =MID(P15,7,2) | S15: G2B | T15: P2 | U15: Multi Cell Hotspot | V15: Inspection | W15: Rejected | X15: =Z15 | Y15: =IF(X15="","",X15-A15) | Z15: 46143 | AF15: =IF(AND($F15="Closed",$X15>=DATE(2026,5,1),$X15<=DATE(2026,5,31)),"Closed in May","Other")
A16: 46106 | B16: 2026 | C16: First Energy | D16: Utility and C&I | F16: Closed | G16: Mr. Gaurav | H16: 9979185999 | I16: PE25032601 | J16: Module Defects | K16: Rajkot | L16: Gujarat | M16: hotspot found | N16: Hotspot | O16: 550 | P16: NSMP2212277215 | Q16: =MID(P16,5,2) | R16: =MID(P16,7,2) | S16: G2B | T16: P2 | U16: Multi Cell Hotspot | V16: Inspection | W16: Rejected | X16: =Z16 | Y16: =IF(X16="","",X16-A16) | Z16: 46143 | AF16: =IF(AND($F16="Closed",$X16>=DATE(2026,5,1),$X16<=DATE(2026,5,31)),"Closed in May","Other")
A17: 46106 | B17: 2026 | C17: First Energy | D17: Utility and C&I | F17: Closed | G17: Mr. Gaurav | H17: 9979185999 | I17: PE25032601 | J17: Module Defects | K17: Rajkot | L17: Gujarat | M17: hotspot found | N17: Hotspot | O17: 550 | P17: NSMP2212268823 | Q17: =MID(P17,5,2) | R17: =MID(P17,7,2) | S17: G2B | T17: P2 | U17: Multi Cell Hotspot | V17: Inspection | W17: Rejected | X17: =Z17 | Y17: =IF(X17="","",X17-A17) | Z17: 46143 | AF17: =IF(AND($F17="Closed",$X17>=DATE(2026,5,1),$X17<=DATE(2026,5,31)),"Closed in May","Other")
A18: 46106 | B18: 2026 | C18: First Energy | D18: Utility and C&I | F18: Closed | G18: Mr. Gaurav | H18: 9979185999 | I18: PE25032601 | J18: Module Defects | K18: Rajkot | L18: Gujarat | M18: hotspot found | N18: Hotspot | O18: 550 | P18: NSMP2301334793 | Q18: =MID(P18,5,2) | R18: =MID(P18,7,2) | S18: G2B | T18: P2 | U18: Multi Cell Hotspot | V18: Inspection | W18: Rejected | X18: =Z18 | Y18: =IF(X18="","",X18-A18) | Z18: 46143 | AF18: =IF(AND($F18="Closed",$X18>=DATE(2026,5,1),$X18<=DATE(2026,5,31)),"Closed in May","Other")
A19: 46106 | B19: 2026 | C19: First Energy | D19: Utility and C&I | F19: Closed | G19: Mr. Gaurav | H19: 9979185999 | I19: PE25032601 | J19: Module Defects | K19: Rajkot | L19: Gujarat | M19: hotspot found | N19: Hotspot | O19: 550 | P19: NSMP2301304875 | Q19: =MID(P19,5,2) | R19: =MID(P19,7,2) | S19: G2B | T19: P2 | U19: Single Cell Hotspot | V19: Inspection | W19: Rejected | X19: =Z19 | Y19: =IF(X19="","",X19-A19) | Z19: 46143 | AF19: =IF(AND($F19="Closed",$X19>=DATE(2026,5,1),$X19<=DATE(2026,5,31)),"Closed in May","Other")
A20: 46106 | B20: 2026 | C20: First Energy | D20: Utility and C&I | F20: Closed | G20: Mr. Gaurav | H20: 9979185999 | I20: PE25032601 | J20: Module Defects | K20: Rajkot | L20: Gujarat | M20: hotspot found | N20: Hotspot | O20: 550 | P20: NSMP2212279131 | Q20: =MID(P20,5,2) | R20: =MID(P20,7,2) | S20: G2B | T20: P2 | U20: Multi Cell Hotspot | V20: Inspection | W20: Rejected | X20: =Z20 | Y20: =IF(X20="","",X20-A20) | Z20: 46143 | AF20: =IF(AND($F20="Closed",$X20>=DATE(2026,5,1),$X20<=DATE(2026,5,31)),"Closed in May","Other")
A21: 46106 | B21: 2026 | C21: First Energy | D21: Utility and C&I | F21: Closed | G21: Mr. Gaurav | H21: 9979185999 | I21: PE25032601 | J21: Module Defects | K21: Rajkot | L21: Gujarat | M21: hotspot found | N21: Hotspot | O21: 550 | P21: NSMP2212282140 | Q21: =MID(P21,5,2) | R21: =MID(P21,7,2) | S21: G2B | T21: P2 | U21: Multi Cell Hotspot | V21: Inspection | W21: Rejected | X21: =Z21 | Y21: =IF(X21="","",X21-A21) | Z21: 46143 | AF21: =IF(AND($F21="Closed",$X21>=DATE(2026,5,1),$X21<=DATE(2026,5,31)),"Closed in May","Other")
A22: 46106 | B22: 2026 | C22: First Energy | D22: Utility and C&I | F22: Closed | G22: Mr. Gaurav | H22: 9979185999 | I22: PE25032601 | J22: Module Defects | K22: Rajkot | L22: Gujarat | M22: hotspot found | N22: Hotspot | O22: 550 | P22: NSMP2212268033 | Q22: =MID(P22,5,2) | R22: =MID(P22,7,2) | S22: G2B | T22: P2 | U22: Single Cell Hotspot | V22: Inspection | W22: Rejected | X22: =Z22 | Y22: =IF(X22="","",X22-A22) | Z22: 46143 | AF22: =IF(AND($F22="Closed",$X22>=DATE(2026,5,1),$X22<=DATE(2026,5,31)),"Closed in May","Other")
A23: 46106 | B23: 2026 | C23: First Energy | D23: Utility and C&I | F23: Closed | G23: Mr. Gaurav | H23: 9979185999 | I23: PE25032601 | J23: Module Defects | K23: Rajkot | L23: Gujarat | M23: hotspot found | N23: Hotspot | O23: 550 | P23: NSMP2212268494 | Q23: =MID(P23,5,2) | R23: =MID(P23,7,2) | S23: G2B | T23: P2 | U23: Single Cell Hotspot | V23: Inspection | W23: Rejected | X23: =Z23 | Y23: =IF(X23="","",X23-A23) | Z23: 46143 | AF23: =IF(AND($F23="Closed",$X23>=DATE(2026,5,1),$X23<=DATE(2026,5,31)),"Closed in May","Other")
A24: 46106 | B24: 2026 | C24: First Energy | D24: Utility and C&I | F24: Closed | G24: Mr. Gaurav | H24: 9979185999 | I24: PE25032601 | J24: Module Defects | K24: Rajkot | L24: Gujarat | M24: hotspot found | N24: Hotspot | O24: 550 | P24: NSMP2212268542 | Q24: =MID(P24,5,2) | R24: =MID(P24,7,2) | S24: G2B | T24: P2 | U24: Single Cell Hotspot | V24: Inspection | W24: Rejected | X24: =Z24 | Y24: =IF(X24="","",X24-A24) | Z24: 46143 | AF24: =IF(AND($F24="Closed",$X24>=DATE(2026,5,1),$X24<=DATE(2026,5,31)),"Closed in May","Other")
A25: 46106 | B25: 2026 | C25: First Energy | D25: Utility and C&I | F25: Closed | G25: Mr. Gaurav | H25: 9979185999 | I25: PE25032601 | J25: Module Defects | K25: Rajkot | L25: Gujarat | M25: hotspot found | N25: Hotspot | O25: 550 | P25: NSMP2212268029 | Q25: =MID(P25,5,2) | R25: =MID(P25,7,2) | S25: G2B | T25: P2 | U25: Single Cell Hotspot | V25: Inspection | W25: Rejected | X25: =Z25 | Y25: =IF(X25="","",X25-A25) | Z25: 46143 | AF25: =IF(AND($F25="Closed",$X25>=DATE(2026,5,1),$X25<=DATE(2026,5,31)),"Closed in May","Other")
... A30: 46106 | B30: 2026 | C30: First Energy | D30: Utility and C&I | F30: Closed | G30: Mr. Gaurav | H30: 9979185999 | I30: PE25032601 | J30: Module Defects | K30: Rajkot | L30: Gujarat | M30: hotspot found | N30: Hotspot | O30: 550 | P30: NSMP2212268150 | Q30: =MID(P30,5,2) | R30: =MID(P30,7,2) | S30: G2B | T30: P2 | U30: Single Cell Hotspot | V30: Inspection | W30: Rejected | X30: =Z30 | Y30: =IF(X30="","",X30-A30) | Z30: 46144 | AF30: =IF(AND($F30="Closed",$X30>=DATE(2026,5,1),$X30<=DATE(2026,5,31)),"Closed in May","Other")
A31: 46106 | B31: 2026 | C31: First Energy | D31: Utility and C&I | F31: Closed | G31: Mr. Gaurav | H31: 9979185999 | I31: PE25032601 | J31: Module Defects | K31: Rajkot | L31: Gujarat | M31: hotspot found | N31: Hotspot | O31: 550 | P31: NSMP2212268242 | Q31: =MID(P31,5,2) | R31: =MID(P31,7,2) | S31: G2B | T31: P2 | U31: Single Cell Hotspot | V31: Inspection | W31: Rejected | X31: =Z31 | Y31: =IF(X31="","",X31-A31) | Z31: 46144 | AD31: =COUNTIF(W:W,"WIP") | AF31: =IF(AND($F31="Closed",$X31>=DATE(2026,5,1),$X31<=DATE(2026,5,31)),"Closed in May","Other")
A32: 46106 | B32: 2026 | C32: First Energy | D32: Utility and C&I | F32: Closed | G32: Mr. Gaurav | H32: 9979185999 | I32: PE25032601 | J32: Module Defects | K32: Rajkot | L32: Gujarat | M32: hotspot found | N32: Hotspot | O32: 550 | P32: NSMP2212268992 | Q32: =MID(P32,5,2) | R32: =MID(P32,7,2) | S32: G2B | T32: P2 | U32: Single Cell Hotspot | V32: Inspection | W32: Rejected | X32: =Z32 | Y32: =IF(X32="","",X32-A32) | Z32: 46144 | AF32: =IF(AND($F32="Closed",$X32>=DATE(2026,5,1),$X32<=DATE(2026,5,31)),"Closed in May","Other")
A33: 46106 | B33: 2026 | C33: First Energy | D33: Utility and C&I | F33: Closed | G33: Mr. Gaurav | H33: 9979185999 | I33: PE25032601 | J33: Module Defects | K33: Rajkot | L33: Gujarat | M33: hotspot found | N33: Hotspot | O33: 550 | P33: NSMP2212276699 | Q33: =MID(P33,5,2) | R33: =MID(P33,7,2) | S33: G2B | T33: P2 | U33: Single Cell Hotspot | V33: Inspection | W33: Rejected | X33: =Z33 | Y33: =IF(X33="","",X33-A33) | Z33: 46144 | AF33: =IF(AND($F33="Closed",$X33>=DATE(2026,5,1),$X33<=DATE(2026,5,31)),"Closed in May","Other")
A34: 46106 | B34: 2026 | C34: First Energy | D34: Utility and C&I | F34: Closed | G34: Mr. Gaurav | H34: 9979185999 | I34: PE25032601 | J34: Module Defects | K34: Rajkot | L34: Gujarat | M34: hotspot found | N34: Hotspot | O34: 550 | P34: NSMP2301333643 | Q34: =MID(P34,5,2) | R34: =MID(P34,7,2) | S34: G2B | T34: P2 | U34: Multi Cell Hotspot | V34: Inspection | W34: Rejected | X34: =Z34 | Y34: =IF(X34="","",X34-A34) | Z34: 46144 | AF34: =IF(AND($F34="Closed",$X34>=DATE(2026,5,1),$X34<=DATE(2026,5,31)),"Closed in May","Other")
A35: 46106 | B35: 2026 | C35: First Energy | D35: Utility and C&I | F35: Closed | G35: Mr. Gaurav | H35: 9979185999 | I35: PE25032601 | J35: Module Defects | K35: Rajkot | L35: Gujarat | M35: hotspot found | N35: Hotspot | O35: 550 | P35: NSMP2212284630 | Q35: =MID(P35,5,2) | R35: =MID(P35,7,2) | S35: G2B | T35: P2 | U35: Multi Cell Hotspot | V35: Inspection | W35: Rejected | X35: =Z35 | Y35: =IF(X35="","",X35-A35) | Z35: 46144 | AF35: =IF(AND($F35="Closed",$X35>=DATE(2026,5,1),$X35<=DATE(2026,5,31)),"Closed in May","Other")
A36: 46106 | B36: 2026 | C36: First Energy | D36: Utility and C&I | F36: WIP | G36: Mr. Gaurav | H36: 9979185999 | I36: PE25032601 | J36: Module Defects | K36: Rajkot | L36: Gujarat | M36: Broken Module | N36: Hotspot | O36: 550 | P36: NSMP2212278079 | Q36: =MID(P36,5,2) | R36: =MID(P36,7,2) | S36: G2B | T36: P2 | U36: Multi Cell Hotspot | V36: Inspection | W36: WIP | Y36: =IF(X36="","",X36-A36) | Z36: 46144 | AF36: =IF(AND($F36="Closed",$X36>=DATE(2026,5,1),$X36<=DATE(2026,5,31)),"Closed in May","Other")
A37: 46106 | B37: 2026 | C37: First Energy | D37: Utility and C&I | F37: Closed | G37: Mr. Gaurav | H37: 9979185999 | I37: PE25032601 | J37: Module Defects | K37: Rajkot | L37: Gujarat | M37: hotspot found | N37: Hotspot | O37: 550 | P37: NSMP2301348215 | Q37: =MID(P37,5,2) | R37: =MID(P37,7,2) | S37: G2B | T37: P2 | U37: Single Cell Hotspot | V37: Inspection | W37: Rejected | X37: =Z37 | Y37: =IF(X37="","",X37-A37) | Z37: 46144 | AF37: =IF(AND($F37="Closed",$X37>=DATE(2026,5,1),$X37<=DATE(2026,5,31)),"Closed in May","Other")
A38: 46106 | B38: 2026 | C38: First Energy | D38: Utility and C&I | F38: Closed | G38: Mr. Gaurav | H38: 9979185999 | I38: PE25032601 | J38: Module Defects | K38: Rajkot | L38: Gujarat | M38: hotspot found | N38: Hotspot | O38: 550 | P38: NSMP2212273080 | Q38: =MID(P38,5,2) | R38: =MID(P38,7,2) | S38: G2B | T38: P2 | U38: Single Cell Hotspot | V38: Inspection | W38: Rejected | X38: =Z38 | Y38: =IF(X38="","",X38-A38) | Z38: 46144 | AF38: =IF(AND($F38="Closed",$X38>=DATE(2026,5,1),$X38<=DATE(2026,5,31)),"Closed in May","Other")
A39: 46106 | B39: 2026 | C39: First Energy | D39: Utility and C&I | F39: Closed | G39: Mr. Gaurav | H39: 9979185999 | I39: PE25032601 | J39: Module Defects | K39: Rajkot | L39: Gujarat | M39: hotspot found | N39: Hotspot | O39: 550 | P39: NSMP2301313309 | Q39: =MID(P39,5,2) | R39: =MID(P39,7,2) | S39: G2B | T39: P2 | U39: Multi Cell Hotspot | V39: Inspection | W39: Rejected | X39: =Z39 | Y39: =IF(X39="","",X39-A39) | Z39: 46144 | AF39: =IF(AND($F39="Closed",$X39>=DATE(2026,5,1),$X39<=DATE(2026,5,31)),"Closed in May","Other")
A40: 46106 | B40: 2026 | C40: First Energy | D40: Utility and C&I | F40: Closed | G40: Mr. Gaurav | H40: 9979185999 | I40: PE25032601 | J40: Module Defects | K40: Rajkot | L40: Gujarat | M40: hotspot found | N40: Hotspot | O40: 550 | P40: NSMP2212281907 | Q40: =MID(P40,5,2) | R40: =MID(P40,7,2) | S40: G2B | T40: P2 | U40: Multi Cell Hotspot | V40: Inspection | W40: Rejected | X40: =Z40 | Y40: =IF(X40="","",X40-A40) | Z40: 46144 | AF40: =IF(AND($F40="Closed",$X40>=DATE(2026,5,1),$X40<=DATE(2026,5,31)),"Closed in May","Other")
A41: 46106 | B41: 2026 | C41: First Energy | D41: Utility and C&I | F41: Closed | G41: Mr. Gaurav | H41: 9979185999 | I41: PE25032601 | J41: Module Defects | K41: Rajkot | L41: Gujarat | M41: hotspot found | N41: Hotspot | O41: 550 | P41: NSMP2212280150 | Q41: =MID(P41,5,2) | R41: =MID(P41,7,2) | S41: G2B | T41: P2 | U41: Multi Cell Hotspot | V41: Inspection | W41: Rejected | X41: =Z41 | Y41: =IF(X41="","",X41-A41) | Z41: 46144 | AF41: =IF(AND($F41="Closed",$X41>=DATE(2026,5,1),$X41<=DATE(2026,5,31)),"Closed in May","Other")
A42: 46106 | B42: 2026 | C42: First Energy | D42: Utility and C&I | F42: Closed | G42: Mr. Gaurav | H42: 9979185999 | I42: PE25032601 | J42: Module Defects | K42: Rajkot | L42: Gujarat | M42: hotspot found | N42: Hotspot | O42: 550 | P42: NSMP2212275577 | Q42: =MID(P42,5,2) | R42: =MID(P42,7,2) | S42: G2B | T42: P2 | U42: Multi Cell Hotspot | V42: Inspection | W42: Rejected | X42: =Z42 | Y42: =IF(X42="","",X42-A42) | Z42: 46144 | AF42: =IF(AND($F42="Closed",$X42>=DATE(2026,5,1),$X42<=DATE(2026,5,31)),"Closed in May","Other")
A43: 46106 | B43: 2026 | C43: First Energy | D43: Utility and C&I | F43: Closed | G43: Mr. Gaurav | H43: 9979185999 | I43: PE25032601 | J43: Module Defects | K43: Rajkot | L43: Gujarat | M43: hotspot found | N43: Hotspot | O43: 550 | P43: NSMP2212297259 | Q43: =MID(P43,5,2) | R43: =MID(P43,7,2) | S43: G2B | T43: P2 | U43: Multi Cell Hotspot | V43: Inspection | W43: Rejected | X43: =Z43 | Y43: =IF(X43="","",X43-A43) | Z43: 46144 | AF43: =IF(AND($F43="Closed",$X43>=DATE(2026,5,1),$X43<=DATE(2026,5,31)),"Closed in May","Other")
A44: 46106 | B44: 2026 | C44: First Energy | D44: Utility and C&I | F44: Closed | G44: Mr. Gaurav | H44: 9979185999 | I44: PE25032601 | J44: Module Defects | K44: Rajkot | L44: Gujarat | M44: hotspot found | N44: Hotspot | O44: 550 | P44: NSMP2212283814 | Q44: =MID(P44,5,2) | R44: =MID(P44,7,2) | S44: G2B | T44: P2 | U44: Single Cell Hotspot | V44: Inspection | W44: Rejected | X44: =Z44 | Y44: =IF(X44="","",X44-A44) | Z44: 46144 | AF44: =IF(AND($F44="Closed",$X44>=DATE(2026,5,1),$X44<=DATE(2026,5,31)),"Closed in May","Other")
...

Sheet May-26 Analysis
A1: MAY 2026 - FIELD SERVICE ANALYSIS
B3: KEY PERFORMANCE INDICATORS
B4: Total Complaints | C4: Closed | D4: WIP / Open | E4: Repairable Defects | F4: Closure Rate | G4: May Expense | H4: Per Module cost | I4: Avg Resolution Day
B5: =C5+D5 | C5: =COUNTIFS('Monthly Report May-26 Cleaned'!$F$2:$F$2787,"Closed",'Monthly Report May-26 Cleaned'!$X$2:$X$2787,">="&DATE(2026,5,1),'Monthly Report May-26 Cleaned'!$X$2:$X$2787,"<="&DATE(2026,5,31)) | D5: =COUNTIFS('Monthly Report May-26 Cleaned'!$F$2:$F$2787,"WIP",'Monthly Report May-26 Cleaned'!$Z$2:$Z$2787,">="&DATE(2026,5,1),'Monthly Report May-26 Cleaned'!$Z$2:$Z$2787,"<="&DATE(2026,5,31)) | E5: =COUNTIFS('Monthly Report May-26 Cleaned'!$W$2:$W$2787,"Repair",'Monthly Report May-26 Cleaned'!$X$2:$X$2787,">="&DATE(2026,5,1),'Monthly Report May-26 Cleaned'!$X$2:$X$2787,"<="&DATE(2026,5,31)) | F5: =C5/B5 | G5: 331507.67 | H5: =G5/B5 | I5: =ROUND(AVERAGEIF('Monthly Report May-26 Cleaned'!$Y$2:$Y$2787,">=0"),1)
A10: Metric | B10: Value | C10: Metric | D10: Value
A11: Total Complaints (May) | B11: =B12+B13 | C11: Closure Rate | D11: =B12/B11
A12: Closed Modules | B12: =COUNTIFS('Monthly Report May-26 Cleaned'!$F$2:$F$2787,"Closed",'Monthly Report May-26 Cleaned'!$X$2:$X$2787,">="&DATE(2026,5,1),'Monthly Report May-26 Cleaned'!$X$2:$X$2787,"<="&DATE(2026,5,31)) | C12: WIP Rate | D12: =B13/B11
A13: WIP Modules | B13: =COUNTIFS('Monthly Report May-26 Cleaned'!$F$2:$F$2787,"WIP",'Monthly Report May-26 Cleaned'!$Z$2:$Z$2787,">="&DATE(2026,5,1),'Monthly Report May-26 Cleaned'!$Z$2:$Z$2787,"<="&DATE(2026,5,31))
A14: State covered | B14: =COUNTIF(H19:H27,">0")
A17: COMPLAINTS BY SITE | G17: COMPLAINTS BY STATE
A18: Site | B18: Modules | C18: Closed | D18: WIP | G18: State | H18: Modules | I18: % Share
A19: Blupine | B19: =C19+D19 | C19: =COUNTIFS('Monthly Report May-26 Cleaned'!$C$2:$C$2787,$A19,'Monthly Report May-26 Cleaned'!$F$2:$F$2787,"Closed",'Monthly Report May-26 Cleaned'!$X$2:$X$2787,">="&DATE(2026,5,1),'Monthly Report May-26 Cleaned'!$X$2:$X$2787,"<="&DATE(2026,5,31)) | D19: =COUNTIFS('Monthly Report May-26 Cleaned'!$C$2:$C$2787,$A19,'Monthly Report May-26 Cleaned'!$F$2:$F$2787,"WIP",'Monthly Report May-26 Cleaned'!$Z$2:$Z$2787,">="&DATE(2026,5,1),'Monthly Report May-26 Cleaned'!$Z$2:$Z$2787,"<="&DATE(2026,5,31)) | G19: Gujarat | H19: =COUNTIFS('Monthly Report May-26 Cleaned'!$L$2:$L$2787,$G19,'Monthly Report May-26 Cleaned'!$F$2:$F$2787,"Closed",'Monthly Report May-26 Cleaned'!$X$2:$X$2787,">="&DATE(2026,5,1),'Monthly Report May-26 Cleaned'!$X$2:$X$2787,"<="&DATE(2026,5,31)) | I19: =H19/$H$28
A20: Yanara Power | B20: =C20+D20 | C20: =COUNTIFS('Monthly Report May-26 Cleaned'!$C$2:$C$2787,$A20,'Monthly Report May-26 Cleaned'!$F$2:$F$2787,"Closed",'Monthly Report May-26 Cleaned'!$X$2:$X$2787,">="&DATE(2026,5,1),'Monthly Report May-26 Cleaned'!$X$2:$X$2787,"<="&DATE(2026,5,31)) | D20: =COUNTIFS('Monthly Report May-26 Cleaned'!$C$2:$C$2787,$A20,'Monthly Report May-26 Cleaned'!$F$2:$F$2787,"WIP",'Monthly Report May-26 Cleaned'!$Z$2:$Z$2787,">="&DATE(2026,5,1),'Monthly Report May-26 Cleaned'!$Z$2:$Z$2787,"<="&DATE(2026,5,31)) | G20: Maharashtra | H20: =COUNTIFS('Monthly Report May-26 Cleaned'!$L$2:$L$2787,$G20,'Monthly Report May-26 Cleaned'!$F$2:$F$2787,"Closed",'Monthly Report May-26 Cleaned'!$X$2:$X$2787,">="&DATE(2026,5,1),'Monthly Report May-26 Cleaned'!$X$2:$X$2787,"<="&DATE(2026,5,31)) | I20: =H20/$H$28
A21: Continuum | B21: =C21+D21 | C21: =COUNTIFS('Monthly Report May-26 Cleaned'!$C$2:$C$2787,$A21,'Monthly Report May-26 Cleaned'!$F$2:$F$2787,"Closed",'Monthly Report May-26 Cleaned'!$X$2:$X$2787,">="&DATE(2026,5,1),'Monthly Report May-26 Cleaned'!$X$2:$X$2787,"<="&DATE(2026,5,31)) | D21: =COUNTIFS('Monthly Report May-26 Cleaned'!$C$2:$C$2787,$A21,'Monthly Report May-26 Cleaned'!$F$2:$F$2787,"WIP",'Monthly Report May-26 Cleaned'!$Z$2:$Z$2787,">="&DATE(2026,5,1),'Monthly Report May-26 Cleaned'!$Z$2:$Z$2787,"<="&DATE(2026,5,31)) | G21: Kerala | H21: =COUNTIFS('Monthly Report May-26 Cleaned'!$L$2:$L$2787,$G21,'Monthly Report May-26 Cleaned'!$F$2:$F$2787,"Closed",'Monthly Report May-26 Cleaned'!$X$2:$X$2787,">="&DATE(2026,5,1),'Monthly Report May-26 Cleaned'!$X$2:$X$2787,"<="&DATE(2026,5,31)) | I21: =H21/$H$28
A22: First Energy | B22: =C22+D22 | C22: =COUNTIFS('Monthly Report May-26 Cleaned'!$C$2:$C$2787,$A22,'Monthly Report May-26 Cleaned'!$F$2:$F$2787,"Closed",'Monthly Report May-26 Cleaned'!$X$2:$X$2787,">="&DATE(2026,5,1),'Monthly Report May-26 Cleaned'!$X$2:$X$2787,"<="&DATE(2026,5,31)) | D22: =COUNTIFS('Monthly Report May-26 Cleaned'!$C$2:$C$2787,$A22,'Monthly Report May-26 Cleaned'!$F$2:$F$2787,"WIP",'Monthly Report May-26 Cleaned'!$Z$2:$Z$2787,">="&DATE(2026,5,1),'Monthly Report May-26 Cleaned'!$Z$2:$Z$2787,"<="&DATE(2026,5,31)) | G22: Telangana | H22: =COUNTIFS('Monthly Report May-26 Cleaned'!$L$2:$L$2787,$G22,'Monthly Report May-26 Cleaned'!$F$2:$F$2787,"Closed",'Monthly Report May-26 Cleaned'!$X$2:$X$2787,">="&DATE(2026,5,1),'Monthly Report May-26 Cleaned'!$X$2:$X$2787,"<="&DATE(2026,5,31)) | I22: =H22/$H$28
A23: Solar Square | B23: =C23+D23 | C23: =COUNTIFS('Monthly Report May-26 Cleaned'!$C$2:$C$2787,$A23,'Monthly Report May-26 Cleaned'!$F$2:$F$2787,"Closed",'Monthly Report May-26 Cleaned'!$X$2:$X$2787,">="&DATE(2026,5,1),'Monthly Report May-26 Cleaned'!$X$2:$X$2787,"<="&DATE(2026,5,31)) | D23: =COUNTIFS('Monthly Report May-26 Cleaned'!$C$2:$C$2787,$A23,'Monthly Report May-26 Cleaned'!$F$2:$F$2787,"WIP",'Monthly Report May-26 Cleaned'!$Z$2:$Z$2787,">="&DATE(2026,5,1),'Monthly Report May-26 Cleaned'!$Z$2:$Z$2787,"<="&DATE(2026,5,31)) | G23: UP | H23: =COUNTIFS('Monthly Report May-26 Cleaned'!$L$2:$L$2787,$G23,'Monthly Report May-26 Cleaned'!$F$2:$F$2787,"Closed",'Monthly Report May-26 Cleaned'!$X$2:$X$2787,">="&DATE(2026,5,1),'Monthly Report May-26 Cleaned'!$X$2:$X$2787,"<="&DATE(2026,5,31)) | I23: =H23/$H$28
A24: Oyster Technocon | B24: =C24+D24 | C24: =COUNTIFS('Monthly Report May-26 Cleaned'!$C$2:$C$2787,$A24,'Monthly Report May-26 Cleaned'!$F$2:$F$2787,"Closed",'Monthly Report May-26 Cleaned'!$X$2:$X$2787,">="&DATE(2026,5,1),'Monthly Report May-26 Cleaned'!$X$2:$X$2787,"<="&DATE(2026,5,31)) | D24: =COUNTIFS('Monthly Report May-26 Cleaned'!$C$2:$C$2787,$A24,'Monthly Report May-26 Cleaned'!$F$2:$F$2787,"WIP",'Monthly Report May-26 Cleaned'!$Z$2:$Z$2787,">="&DATE(2026,5,1),'Monthly Report May-26 Cleaned'!$Z$2:$Z$2787,"<="&DATE(2026,5,31)) | G24: MP | H24: =COUNTIFS('Monthly Report May-26 Cleaned'!$L$2:$L$2787,$G24,'Monthly Report May-26 Cleaned'!$F$2:$F$2787,"Closed",'Monthly Report May-26 Cleaned'!$X$2:$X$2787,">="&DATE(2026,5,1),'Monthly Report May-26 Cleaned'!$X$2:$X$2787,"<="&DATE(2026,5,31)) | I24: =H24/$H$28
A25: Panasonic | B25: =C25+D25 | C25: =COUNTIFS('Monthly Report May-26 Cleaned'!$C$2:$C$2787,$A25,'Monthly Report May-26 Cleaned'!$F$2:$F$2787,"Closed",'Monthly Report May-26 Cleaned'!$X$2:$X$2787,">="&DATE(2026,5,1),'Monthly Report May-26 Cleaned'!$X$2:$X$2787,"<="&DATE(2026,5,31)) | D25: =COUNTIFS('Monthly Report May-26 Cleaned'!$C$2:$C$2787,$A25,'Monthly Report May-26 Cleaned'!$F$2:$F$2787,"WIP",'Monthly Report May-26 Cleaned'!$Z$2:$Z$2787,">="&DATE(2026,5,1),'Monthly Report May-26 Cleaned'!$Z$2:$Z$2787,"<="&DATE(2026,5,31)) | G25: Andhra Pradesh | H25: =COUNTIFS('Monthly Report May-26 Cleaned'!$L$2:$L$2787,"*Andhra*",'Monthly Report May-26 Cleaned'!$F$2:$F$2787,"Closed",'Monthly Report May-26 Cleaned'!$X$2:$X$2787,">="&DATE(2026,5,1),'Monthly Report May-26 Cleaned'!$X$2:$X$2787,"<="&DATE(2026,5,31)) | I25: =H25/$H$28
A26: TRUE SUN TRADING COMPANY | B26: =C26+D26 | C26: =COUNTIFS('Monthly Report May-26 Cleaned'!$C$2:$C$2787,$A26,'Monthly Report May-26 Cleaned'!$F$2:$F$2787,"Closed",'Monthly Report May-26 Cleaned'!$X$2:$X$2787,">="&DATE(2026,5,1),'Monthly Report May-26 Cleaned'!$X$2:$X$2787,"<="&DATE(2026,5,31)) | D26: =COUNTIFS('Monthly Report May-26 Cleaned'!$C$2:$C$2787,$A26,'Monthly Report May-26 Cleaned'!$F$2:$F$2787,"WIP",'Monthly Report May-26 Cleaned'!$Z$2:$Z$2787,">="&DATE(2026,5,1),'Monthly Report May-26 Cleaned'!$Z$2:$Z$2787,"<="&DATE(2026,5,31)) | G26: Karnataka | H26: =COUNTIFS('Monthly Report May-26 Cleaned'!$L$2:$L$2787,$G26,'Monthly Report May-26 Cleaned'!$F$2:$F$2787,"Closed",'Monthly Report May-26 Cleaned'!$X$2:$X$2787,">="&DATE(2026,5,1),'Monthly Report May-26 Cleaned'!$X$2:$X$2787,"<="&DATE(2026,5,31)) | I26: =H26/$H$28
A27: Maya Power | B27: =C27+D27 | C27: =COUNTIFS('Monthly Report May-26 Cleaned'!$C$2:$C$2787,$A27,'Monthly Report May-26 Cleaned'!$F$2:$F$2787,"Closed",'Monthly Report May-26 Cleaned'!$X$2:$X$2787,">="&DATE(2026,5,1),'Monthly Report May-26 Cleaned'!$X$2:$X$2787,"<="&DATE(2026,5,31)) | D27: =COUNTIFS('Monthly Report May-26 Cleaned'!$C$2:$C$2787,$A27,'Monthly Report May-26 Cleaned'!$F$2:$F$2787,"WIP",'Monthly Report May-26 Cleaned'!$Z$2:$Z$2787,">="&DATE(2026,5,1),'Monthly Report May-26 Cleaned'!$Z$2:$Z$2787,"<="&DATE(2026,5,31)) | G27: Tamil Nadu | H27: =COUNTIFS('Monthly Report May-26 Cleaned'!$L$2:$L$2787,$G27,'Monthly Report May-26 Cleaned'!$F$2:$F$2787,"Closed",'Monthly Report May-26 Cleaned'!$X$2:$X$2787,">="&DATE(2026,5,1),'Monthly Report May-26 Cleaned'!$X$2:$X$2787,"<="&DATE(2026,5,31)) | I27: =H27/$H$28
A28: Axitec Energy | B28: =C28+D28 | C28: =COUNTIFS('Monthly Report May-26 Cleaned'!$C$2:$C$2787,$A28,'Monthly Report May-26 Cleaned'!$F$2:$F$2787,"Closed",'Monthly Report May-26 Cleaned'!$X$2:$X$2787,">="&DATE(2026,5,1),'Monthly Report May-26 Cleaned'!$X$2:$X$2787,"<="&DATE(2026,5,31)) | D28: =COUNTIFS('Monthly Report May-26 Cleaned'!$C$2:$C$2787,$A28,'Monthly Report May-26 Cleaned'!$F$2:$F$2787,"WIP",'Monthly Report May-26 Cleaned'!$Z$2:$Z$2787,">="&DATE(2026,5,1),'Monthly Report May-26 Cleaned'!$Z$2:$Z$2787,"<="&DATE(2026,5,31)) | G28: TOTAL | H28: =SUM(H19:H27) | I28: =SUM(I19:I27)
A29: Nabhas Constructions | B29: =C29+D29 | C29: =COUNTIFS('Monthly Report May-26 Cleaned'!$C$2:$C$2787,$A29,'Monthly Report May-26 Cleaned'!$F$2:$F$2787,"Closed",'Monthly Report May-26 Cleaned'!$X$2:$X$2787,">="&DATE(2026,5,1),'Monthly Report May-26 Cleaned'!$X$2:$X$2787,"<="&DATE(2026,5,31)) | D29: =COUNTIFS('Monthly Report May-26 Cleaned'!$C$2:$C$2787,$A29,'Monthly Report May-26 Cleaned'!$F$2:$F$2787,"WIP",'Monthly Report May-26 Cleaned'!$Z$2:$Z$2787,">="&DATE(2026,5,1),'Monthly Report May-26 Cleaned'!$Z$2:$Z$2787,"<="&DATE(2026,5,31))
A30: Cresta Solar | B30: =C30+D30 | C30: =COUNTIFS('Monthly Report May-26 Cleaned'!$C$2:$C$2787,$A30,'Monthly Report May-26 Cleaned'!$F$2:$F$2787,"Closed",'Monthly Report May-26 Cleaned'!$X$2:$X$2787,">="&DATE(2026,5,1),'Monthly Report May-26 Cleaned'!$X$2:$X$2787,"<="&DATE(2026,5,31)) | D30: =COUNTIFS('Monthly Report May-26 Cleaned'!$C$2:$C$2787,$A30,'Monthly Report May-26 Cleaned'!$F$2:$F$2787,"WIP",'Monthly Report May-26 Cleaned'!$Z$2:$Z$2787,">="&DATE(2026,5,1),'Monthly Report May-26 Cleaned'!$Z$2:$Z$2787,"<="&DATE(2026,5,31)) | G30: RESOLUTION TYPE
A31: SUNRISE TECHNOLOGIES | B31: =C31+D31 | C31: =COUNTIFS('Monthly Report May-26 Cleaned'!$C$2:$C$2787,$A31,'Monthly Report May-26 Cleaned'!$F$2:$F$2787,"Closed",'Monthly Report May-26 Cleaned'!$X$2:$X$2787,">="&DATE(2026,5,1),'Monthly Report May-26 Cleaned'!$X$2:$X$2787,"<="&DATE(2026,5,31)) | D31: =COUNTIFS('Monthly Report May-26 Cleaned'!$C$2:$C$2787,$A31,'Monthly Report May-26 Cleaned'!$F$2:$F$2787,"WIP",'Monthly Report May-26 Cleaned'!$Z$2:$Z$2787,">="&DATE(2026,5,1),'Monthly Report May-26 Cleaned'!$Z$2:$Z$2787,"<="&DATE(2026,5,31)) | G31: Resolution | H31: Modules | I31: % Share
A32: SILRES Energy Solutions Private Limited | B32: =C32+D32 | C32: =COUNTIFS('Monthly Report May-26 Cleaned'!$C$2:$C$2787,$A32,'Monthly Report May-26 Cleaned'!$F$2:$F$2787,"Closed",'Monthly Report May-26 Cleaned'!$X$2:$X$2787,">="&DATE(2026,5,1),'Monthly Report May-26 Cleaned'!$X$2:$X$2787,"<="&DATE(2026,5,31)) | D32: =COUNTIFS('Monthly Report May-26 Cleaned'!$C$2:$C$2787,$A32,'Monthly Report May-26 Cleaned'!$F$2:$F$2787,"WIP",'Monthly Report May-26 Cleaned'!$Z$2:$Z$2787,">="&DATE(2026,5,1),'Monthly Report May-26 Cleaned'!$Z$2:$Z$2787,"<="&DATE(2026,5,31)) | G32: Retrofit | H32: =COUNTIFS('Monthly Report May-26 Cleaned'!$W$2:$W$2787,"Retrofit",'Monthly Report May-26 Cleaned'!$X$2:$X$2787,">="&DATE(2026,5,1),'Monthly Report May-26 Cleaned'!$X$2:$X$2787,"<="&DATE(2026,5,31)) | I32: =H32/$H$39
