Workbook

Sheet Dashboard
U1: CHART DATA (linked)
B2: FIELD SERVICE DASHBOARD
B3: Dec 2025 • Solar Module Complaints & Defect Analysis | U3: Site | V3: Modules | W3: Plant | X3: Modules
U4: Blupine | V4: 1845 | W4: P1 | X4: 1
B5: Total Complaints | E5: Closed Modules | H5: WIP / Open | K5: Closure Rate | N5: Avg Resolution | U5: First Energy | V5: 834 | W5: P2 | X5: 1604
B6: ='MSI Report'!B6 -> 416 | E6: ='MSI Report'!C6 -> 416 | H6: ='MSI Report'!D6 -> 0 | K6: ='MSI Report'!F6 -> 1 | N6: ='MSI Report'!G6 -> 22.2 | U6: Continuum | V6: 596 | W6: P4 | X6: 1351
U7: Ayana | V7: 367
B8: Daily Complaints Trend - December 2025 | U8: NTPC Limited | V8: 197
U9: Asian Fab Tec Ltd | V9: 59
U10: Madhav Infra Projects Ltd. | V10: 37
U11: WBSEDCL | V11: 32
U12: State | V12: Modules | W12: Defect Type | X12: G2B | Y12: G2TB | Z12: G2G
U13: Gujarat | V13: 1688 | W13: Cold Soldering | X13: 2182 | Y13: 250 | Z13: 82
U14: Karnataka | V14: 688 | W14: JB Issue | X14: 215 | Y14: 67 | Z14: 31
U15: MP | V15: 502 | W15: No Issue | X15: 110 | Y15: 11 | Z15: 12
U16: J&K | V16: 192 | W16: Tab lead Burn | X16: 18 | Y16: 17 | Z16: 0
U17: West Bengal | V17: 32 | W17: Low Generation | X17: 4 | Y17: 1 | Z17: 3
U18: Kerala | V18: 21 | W18: Glass Breakage | X18: 1 | Y18: 0 | Z18: 0
U19: Maharashtra | V19: 6
U20: Bihar | V20: 1
U22: Defect Type | V22: Count
B23: Complaints by Site | H23: Complaints by State | N23: Defect Type Mix | U23: Cold Soldering | V23: 2514
U24: JB Issue | V24: 313
U25: Tab lead Burn | V25: 35
U26: Glass Breakage | V26: 1
U27: Others | V27: 145
U29: TAT Range | V29: Modules
U37: Week | V37: Modules
U38: W1 (01-07 Dec) | V38: =SUMIFS('MSI Report'!B40:B70,'MSI Report'!A40:A70,">="&DATE(2025,12,1),'MSI Report'!A40:A70,"<="&DATE(2025,12,7)) -> 97
U39: W2 (08-14 Dec) | V39: =SUMIFS('MSI Report'!B40:B70,'MSI Report'!A40:A70,">="&DATE(2025,12,8),'MSI Report'!A40:A70,"<="&DATE(2025,12,14)) -> 117
B40: Resolution Time (TAT) Distribution | H40: Weekly Complaint Volume | U40: W3 (15-21 Dec) | V40: =SUMIFS('MSI Report'!B40:B70,'MSI Report'!A40:A70,">="&DATE(2025,12,15),'MSI Report'!A40:A70,"<="&DATE(2025,12,21)) -> 149
U41: W4 (22-28 Dec) | V41: =SUMIFS('MSI Report'!B40:B70,'MSI Report'!A40:A70,">="&DATE(2025,12,22),'MSI Report'!A40:A70,"<="&DATE(2025,12,28)) -> 30
U42: W5 (29-31 Dec) | V42: =SUMIFS('MSI Report'!B40:B70,'MSI Report'!A40:A70,">="&DATE(2025,12,29),'MSI Report'!A40:A70,"<="&DATE(2025,12,31)) -> 23
B58: MANUFACTURING PLANT-WISE | K58: MODULE TYPE DEFECT ANALYSIS - JAN 2026

Sheet MSI Report
A1: Monthly MIS Report - Solar PV Warranty Claims
B4: KEY PERFORMANCE INDICATORS
B5: Total Complaints | C5: Closed | D5: WIP / Open | E5: Repairable Defects | F5: Closure Rate | G5: Avg Resolution Day
B6: =B10 -> 416 | C6: =B11 -> 416 | D6: =B12 -> 0 | E6: =COUNTIFS('Monthly Report Dec-25'!V:V,"Repair",'Monthly Report Dec-25'!W:W,">="&DATE(2025,12,1),'Monthly Report Dec-25'!W:W,"<="&DATE(2025,12,31)) -> 293 | F6: =D10 -> 1 | G6: =ROUND(AVERAGEIF('Monthly Report Dec-25'!X:X,">=0"),1) -> 22.2
A8: 1. COMPLAINT STATUS SUMMARY
A9: Metric | B9: Value | C9: Metric | D9: Value
A10: Total Complaints (Dec) | B10: =SUM(B11,B12) -> 416 | C10: Closure Rate | D10: =B11/B10 -> 1
A11: Closed Modules | B11: =COUNTIFS('Monthly Report Dec-25'!F:F,"Closed",'Monthly Report Dec-25'!W:W,">="&DATE(2025,12,1),'Monthly Report Dec-25'!W:W,"<="&DATE(2025,12,31)) -> 416 | C11: WIP Rate | D11: =B12/B10 -> 0
A12: WIP Modules | B12: =COUNTIFS('Monthly Report Dec-25'!F:F,"WIP",'Monthly Report Dec-25'!A:A,">="&DATE(2025,12,1),'Monthly Report Dec-25'!A:A,"<="&DATE(2025,12,31)) -> 0
A13: State covered | B13: =COUNTA(_xlfn.UNIQUE('Monthly Report Dec-25'!L2:L417)) -> 8
A16: By Customer | H16: By State
A17: COMPLAINTS BY SITE | H17: COMPLAINTS BY STATE
A18: Site | B18: Modules | C18: Closed | D18: WIP | H18: State | I18: Modules | J18: % Share | O18: =COUNTIFS(#REF!,H19,#REF!,"Closed",#REF!,">="&DATE(2026,4,1),#REF!,"<="&DATE(2026,4,30)) -> #REF!
A19: Madhav Infra Projects Ltd. | B19: =COUNTIF('Monthly Report Dec-25'!$C$2:$C$417,A19) -> 98 | C19: =COUNTIFS('Monthly Report Dec-25'!$C:$C,A19,'Monthly Report Dec-25'!$F:$F,"Closed",'Monthly Report Dec-25'!$W:$W,">="&DATE(2025,12,1),'Monthly Report Dec-25'!$W:$W,"<="&DATE(2025,12,31)) -> 98 | D19: =COUNTIFS('Monthly Report Dec-25'!$C:$C,B19,'Monthly Report Dec-25'!$F:$F,"WIP",'Monthly Report Dec-25'!$W:$W,">="&DATE(2025,12,1),'Monthly Report Dec-25'!$W:$W,"<="&DATE(2025,12,31)) -> 0 | H19: Gujarat | I19: =COUNTIFS('Monthly Report Dec-25'!$L:$L,H19,'Monthly Report Dec-25'!$F:$F,"Closed",'Monthly Report Dec-25'!$W:$W,">="&DATE(2025,12,1),'Monthly Report Dec-25'!$W:$W,"<="&DATE(2025,12,31)) -> 133 | J19: =I19/$I$27 -> 0.31971154
A20: TRUE SUN TRADING COMPANY | B20: =COUNTIF('Monthly Report Dec-25'!$C$2:$C$417,A20) -> 2 | C20: =COUNTIFS('Monthly Report Dec-25'!$C:$C,A20,'Monthly Report Dec-25'!$F:$F,"Closed",'Monthly Report Dec-25'!$W:$W,">="&DATE(2025,12,1),'Monthly Report Dec-25'!$W:$W,"<="&DATE(2025,12,31)) -> 2 | D20: =COUNTIFS('Monthly Report Dec-25'!$C:$C,B20,'Monthly Report Dec-25'!$F:$F,"WIP",'Monthly Report Dec-25'!$W:$W,">="&DATE(2025,12,1),'Monthly Report Dec-25'!$W:$W,"<="&DATE(2025,12,31)) -> 0 | H20: Maharashtra | I20: =COUNTIFS('Monthly Report Dec-25'!$L:$L,H20,'Monthly Report Dec-25'!$F:$F,"Closed",'Monthly Report Dec-25'!$W:$W,">="&DATE(2025,12,1),'Monthly Report Dec-25'!$W:$W,"<="&DATE(2025,12,31)) -> 4 | J20: =I20/$I$27 -> 0.0096153846
A21: Panasonic | B21: =COUNTIF('Monthly Report Dec-25'!$C$2:$C$417,A21) -> 5 | C21: =COUNTIFS('Monthly Report Dec-25'!$C:$C,A21,'Monthly Report Dec-25'!$F:$F,"Closed",'Monthly Report Dec-25'!$W:$W,">="&DATE(2025,12,1),'Monthly Report Dec-25'!$W:$W,"<="&DATE(2025,12,31)) -> 5 | D21: =COUNTIFS('Monthly Report Dec-25'!$C:$C,B21,'Monthly Report Dec-25'!$F:$F,"WIP",'Monthly Report Dec-25'!$W:$W,">="&DATE(2025,12,1),'Monthly Report Dec-25'!$W:$W,"<="&DATE(2025,12,31)) -> 0 | H21: Kerala | I21: =COUNTIFS('Monthly Report Dec-25'!$L:$L,H21,'Monthly Report Dec-25'!$F:$F,"Closed",'Monthly Report Dec-25'!$W:$W,">="&DATE(2025,12,1),'Monthly Report Dec-25'!$W:$W,"<="&DATE(2025,12,31)) -> 22 | J21: =I21/$I$27 -> 0.052884615
A22: Continuum | B22: =COUNTIF('Monthly Report Dec-25'!$C$2:$C$417,A22) -> 34 | C22: =COUNTIFS('Monthly Report Dec-25'!$C:$C,A22,'Monthly Report Dec-25'!$F:$F,"Closed",'Monthly Report Dec-25'!$W:$W,">="&DATE(2025,12,1),'Monthly Report Dec-25'!$W:$W,"<="&DATE(2025,12,31)) -> 34 | D22: =COUNTIFS('Monthly Report Dec-25'!$C:$C,B22,'Monthly Report Dec-25'!$F:$F,"WIP",'Monthly Report Dec-25'!$W:$W,">="&DATE(2025,12,1),'Monthly Report Dec-25'!$W:$W,"<="&DATE(2025,12,31)) -> 0 | H22: Telangana | I22: =COUNTIFS('Monthly Report Dec-25'!$L:$L,H22,'Monthly Report Dec-25'!$F:$F,"Closed",'Monthly Report Dec-25'!$W:$W,">="&DATE(2025,12,1),'Monthly Report Dec-25'!$W:$W,"<="&DATE(2025,12,31)) -> 1 | J22: =I22/$I$27 -> 0.0024038462
A23: KVK ENGINEERING | B23: =COUNTIF('Monthly Report Dec-25'!$C$2:$C$417,A23) -> 1 | C23: =COUNTIFS('Monthly Report Dec-25'!$C:$C,A23,'Monthly Report Dec-25'!$F:$F,"Closed",'Monthly Report Dec-25'!$W:$W,">="&DATE(2025,12,1),'Monthly Report Dec-25'!$W:$W,"<="&DATE(2025,12,31)) -> 1 | D23: =COUNTIFS('Monthly Report Dec-25'!$C:$C,B23,'Monthly Report Dec-25'!$F:$F,"WIP",'Monthly Report Dec-25'!$W:$W,">="&DATE(2025,12,1),'Monthly Report Dec-25'!$W:$W,"<="&DATE(2025,12,31)) -> 0 | H23: Chhattisgarh | I23: =COUNTIFS('Monthly Report Dec-25'!$L:$L,H23,'Monthly Report Dec-25'!$F:$F,"Closed",'Monthly Report Dec-25'!$W:$W,">="&DATE(2025,12,1),'Monthly Report Dec-25'!$W:$W,"<="&DATE(2025,12,31)) -> 58 | J23: =I23/$I$27 -> 0.13942308
A24: Blupine Jakson Green | B24: =COUNTIF('Monthly Report Dec-25'!$C$2:$C$417,A24) -> 58 | C24: =COUNTIFS('Monthly Report Dec-25'!$C:$C,A24,'Monthly Report Dec-25'!$F:$F,"Closed",'Monthly Report Dec-25'!$W:$W,">="&DATE(2025,12,1),'Monthly Report Dec-25'!$W:$W,"<="&DATE(2025,12,31)) -> 58 | D24: =COUNTIFS('Monthly Report Dec-25'!$C:$C,B24,'Monthly Report Dec-25'!$F:$F,"WIP",'Monthly Report Dec-25'!$W:$W,">="&DATE(2025,12,1),'Monthly Report Dec-25'!$W:$W,"<="&DATE(2025,12,31)) -> 0 | H24: Uttar Pradesh | I24: =COUNTIFS('Monthly Report Dec-25'!$L:$L,H24,'Monthly Report Dec-25'!$F:$F,"Closed",'Monthly Report Dec-25'!$W:$W,">="&DATE(2025,12,1),'Monthly Report Dec-25'!$W:$W,"<="&DATE(2025,12,31)) -> 15 | J24: =I24/$I$27 -> 0.036057692
A25: Arsiga Solar | B25: =COUNTIF('Monthly Report Dec-25'!$C$2:$C$417,A25) -> 9 | C25: =COUNTIFS('Monthly Report Dec-25'!$C:$C,A25,'Monthly Report Dec-25'!$F:$F,"Closed",'Monthly Report Dec-25'!$W:$W,">="&DATE(2025,12,1),'Monthly Report Dec-25'!$W:$W,"<="&DATE(2025,12,31)) -> 9 | D25: =COUNTIFS('Monthly Report Dec-25'!$C:$C,B25,'Monthly Report Dec-25'!$F:$F,"WIP",'Monthly Report Dec-25'!$W:$W,">="&DATE(2025,12,1),'Monthly Report Dec-25'!$W:$W,"<="&DATE(2025,12,31)) -> 0 | H25: Rajasthan | I25: =COUNTIFS('Monthly Report Dec-25'!$L:$L,H25,'Monthly Report Dec-25'!$F:$F,"Closed",'Monthly Report Dec-25'!$W:$W,">="&DATE(2025,12,1),'Monthly Report Dec-25'!$W:$W,"<="&DATE(2025,12,31)) -> 182 | J25: =I25/$I$27 -> 0.4375
A26: Solar Square | B26: =COUNTIF('Monthly Report Dec-25'!$C$2:$C$417,A26) -> 6 | C26: =COUNTIFS('Monthly Report Dec-25'!$C:$C,A26,'Monthly Report Dec-25'!$F:$F,"Closed",'Monthly Report Dec-25'!$W:$W,">="&DATE(2025,12,1),'Monthly Report Dec-25'!$W:$W,"<="&DATE(2025,12,31)) -> 6 | D26: =COUNTIFS('Monthly Report Dec-25'!$C:$C,B26,'Monthly Report Dec-25'!$F:$F,"WIP",'Monthly Report Dec-25'!$W:$W,">="&DATE(2025,12,1),'Monthly Report Dec-25'!$W:$W,"<="&DATE(2025,12,31)) -> 0 | H26: Karnataka | I26: =COUNTIFS('Monthly Report Dec-25'!$L:$L,H26,'Monthly Report Dec-25'!$F:$F,"Closed",'Monthly Report Dec-25'!$W:$W,">="&DATE(2025,12,1),'Monthly Report Dec-25'!$W:$W,"<="&DATE(2025,12,31)) -> 1 | J26: =I26/$I$27 -> 0.0024038462
A27: Shakti Pump | B27: =COUNTIF('Monthly Report Dec-25'!$C$2:$C$417,A27) -> 1 | C27: =COUNTIFS('Monthly Report Dec-25'!$C:$C,A27,'Monthly Report Dec-25'!$F:$F,"Closed",'Monthly Report Dec-25'!$W:$W,">="&DATE(2025,12,1),'Monthly Report Dec-25'!$W:$W,"<="&DATE(2025,12,31)) -> 1 | D27: =COUNTIFS('Monthly Report Dec-25'!$C:$C,B27,'Monthly Report Dec-25'!$F:$F,"WIP",'Monthly Report Dec-25'!$W:$W,">="&DATE(2025,12,1),'Monthly Report Dec-25'!$W:$W,"<="&DATE(2025,12,31)) -> 0 | H27: TOTAL | I27: =SUM(I19:I26) -> 416 | J27: =SUM(J19:J26) -> 1
A28: Blupine Energy | B28: =COUNTIF('Monthly Report Dec-25'!$C$2:$C$417,A28) -> 181 | C28: =COUNTIFS('Monthly Report Dec-25'!$C:$C,A28,'Monthly Report Dec-25'!$F:$F,"Closed",'Monthly Report Dec-25'!$W:$W,">="&DATE(2025,12,1),'Monthly Report Dec-25'!$W:$W,"<="&DATE(2025,12,31)) -> 181 | D28: =COUNTIFS('Monthly Report Dec-25'!$C:$C,B28,'Monthly Report Dec-25'!$F:$F,"WIP",'Monthly Report Dec-25'!$W:$W,">="&DATE(2025,12,1),'Monthly Report Dec-25'!$W:$W,"<="&DATE(2025,12,31)) -> 0
A29: Orb Energy | B29: =COUNTIF('Monthly Report Dec-25'!$C$2:$C$417,A29) -> 1 | C29: =COUNTIFS('Monthly Report Dec-25'!$C:$C,A29,'Monthly Report Dec-25'!$F:$F,"Closed",'Monthly Report Dec-25'!$W:$W,">="&DATE(2025,12,1),'Monthly Report Dec-25'!$W:$W,"<="&DATE(2025,12,31)) -> 1 | D29: =COUNTIFS('Monthly Report Dec-25'!$C:$C,B29,'Monthly Report Dec-25'!$F:$F,"WIP",'Monthly Report Dec-25'!$W:$W,">="&DATE(2025,12,1),'Monthly Report Dec-25'!$W:$W,"<="&DATE(2025,12,31)) -> 0
A30: Axitec Energy | B30: =COUNTIF('Monthly Report Dec-25'!$C$2:$C$417,A30) -> 20 | C30: =COUNTIFS('Monthly Report Dec-25'!$C:$C,A30,'Monthly Report Dec-25'!$F:$F,"Closed",'Monthly Report Dec-25'!$W:$W,">="&DATE(2025,12,1),'Monthly Report Dec-25'!$W:$W,"<="&DATE(2025,12,31)) -> 20 | D30: =COUNTIFS('Monthly Report Dec-25'!$C:$C,B30,'Monthly Report Dec-25'!$F:$F,"WIP",'Monthly Report Dec-25'!$W:$W,">="&DATE(2025,12,1),'Monthly Report Dec-25'!$W:$W,"<="&DATE(2025,12,31)) -> 0
A31: TOTAL | B31: =SUM(B19:B31) | C31: =SUM(C19:C31) | D31: =SUM(D19:D31)
H34: RESOLUTION TYPE
H35: Resolution | I35: Modules | J35: % Share
H36: Repair | I36: =COUNTIFS('Monthly Report Dec-25'!$V:$V,H36,'Monthly Report Dec-25'!$W:$W,">="&DATE(2025,12,1),'Monthly Report Dec-25'!$W:$W,"<="&DATE(2025,12,31)) -> 293 | J36: =I36/$I$41 -> 0.71463415
H37: Rejected | I37: =COUNTIFS('Monthly Report Dec-25'!$V:$V,H37,'Monthly Report Dec-25'!$W:$W,">="&DATE(2025,12,1),'Monthly Report Dec-25'!$W:$W,"<="&DATE(2025,12,31)) -> 116 | J37: =I37/$I$41 -> 0.28292683
A38: DAILY COMPLAINTS TREND - DEC 2025 | H38: Replacement | I38: =COUNTIFS('Monthly Report Dec-25'!$V:$V,H38,'Monthly Report Dec-25'!$W:$W,">="&DATE(2025,12,1),'Monthly Report Dec-25'!$W:$W,"<="&DATE(2025,12,31)) -> 1 | J38: =I38/$I$41 -> 0.0024390244
A39: Date | B39: Closed | C39: WIP | H39: Inspection | I39: =COUNTIFS('Monthly Report Dec-25'!$V:$V,H39,'Monthly Report Dec-25'!$W:$W,">="&DATE(2025,12,1),'Monthly Report Dec-25'!$W:$W,"<="&DATE(2025,12,31)) -> 0 | J39: =I39/$I$41 -> 0
A40: 45992 | B40: =COUNTIFS('Monthly Report Dec-25'!$W:W,A40,'Monthly Report Dec-25'!F:F,"Closed") -> 1 | C40: 0 | H40: CN | I40: =COUNTIFS('Monthly Report Dec-25'!$V:$V,H40,'Monthly Report Dec-25'!$W:$W,">="&DATE(2025,12,1),'Monthly Report Dec-25'!$W:$W,"<="&DATE(2025,12,31)) -> 0 | J40: =I40/$I$41 -> 0
A41: 45993 | B41: =COUNTIFS('Monthly Report Dec-25'!$W:W,A41,'Monthly Report Dec-25'!F:F,"Closed") -> 0 | C41: 0 | H41: TOTAL | I41: =SUM(I36:I40) -> 410 | J41: =SUM(J34:J40) -> 1
A42: 45994 | B42: =COUNTIFS('Monthly Report Dec-25'!$W:W,A42,'Monthly Report Dec-25'!F:F,"Closed") -> 0 | C42: 0
A43: 45995 | B43: =COUNTIFS('Monthly Report Dec-25'!$W:W,A43,'Monthly Report Dec-25'!F:F,"Closed") -> 0 | C43: 0
A44: 45996 | B44: =COUNTIFS('Monthly Report Dec-25'!$W:W,A44,'Monthly Report Dec-25'!F:F,"Closed") -> 0 | C44: 0 | H44: MANUFACTURING PLANT-WISE
A45: 45997 | B45: =COUNTIFS('Monthly Report Dec-25'!$W:W,A45,'Monthly Report Dec-25'!F:F,"Closed") -> 0 | C45: 0 | H45: Plant | I45: Modules | J45: % Share
A46: 45998 | B46: =COUNTIFS('Monthly Report Dec-25'!$W:W,A46,'Monthly Report Dec-25'!F:F,"Closed") -> 96 | C46: 0 | H46: P4 - PEIPL | I46: =COUNTIFS('Monthly Report Dec-25'!$S:$S,H46,'Monthly Report Dec-25'!$F:$F,"Closed",'Monthly Report Dec-25'!$W:$W,">="&DATE(2025,12,1),'Monthly Report Dec-25'!$W:$W,"<="&DATE(2025,12,31)) -> 92 | J46: =I46/$I$50 -> 0.22276029
A47: 45999 | B47: =COUNTIFS('Monthly Report Dec-25'!$W:W,A47,'Monthly Report Dec-25'!F:F,"Closed") -> 17 | C47: 0 | H47: P2 - PEPPL | I47: =COUNTIFS('Monthly Report Dec-25'!$S:$S,H47,'Monthly Report Dec-25'!$F:$F,"Closed",'Monthly Report Dec-25'!$W:$W,">="&DATE(2025,12,1),'Monthly Report Dec-25'!$W:$W,"<="&DATE(2025,12,31)) -> 137 | J47: =I47/$I$50 -> 0.33171913
...

Sheet Daily Report Dec-25
A1: Date | B1: Site | C1: Area | D1: State | E1: No Of Complaints | F1: Visited by | G1: Complaint ID | H1: Remarks
A2: 45995 | B2: Madhav Infra Projects Ltd. | C2: Lakadia,Bhachau,Kutchh | D2: Gujarat | E2: 26 | F2: Kunal & Aniruddha | G2: N/A | H2: Retrofit
A3: 45996 | B3: Madhav Infra Projects Ltd. | C3: Lakadia,Bhachau,Kutchh | D3: Gujarat | E3: 25 | F3: Kunal & Aniruddha | G3: N/A | H3: Retrofit
A4: 45997 | B4: Madhav Infra Projects Ltd. | C4: Lakadia,Bhachau,Kutchh | D4: Gujarat | E4: 29 | F4: Kunal & Aniruddha | G4: N/A | H4: Retrofit
A5: 45998 | B5: Madhav Infra Projects Ltd. | C5: Lakadia,Bhachau,Kutchh | D5: Gujarat | E5: 18 | F5: Kunal & Aniruddha | G5: N/A | H5: Retrofit
A6: 45999 | B6: Panasonic | C6: Aluva | D6: Kerala | E6: 1 | F6: Pavan | G6: N/A | H6: Retrofit
A7: 45999 | B7: Panasonic | C7: Mahavishnu Nagar, Nagpur | D7: Maharashtra | E7: 1 | F7: Chanchal | G7: N/A | H7: Retrofit
A8: 45999 | B8: Panasonic | C8: Nagpur | D8: Maharashtra | E8: 3 | F8: Chanchal | G8: N/A | H8: Retrofit
A9: 45999 | B9: TRUE SUN TRADING COMPANY | C9: VELIYANOOR | D9: Gujarat | E9: 1 | F9: Complaints closed by True Sun team | G9: N/A | H9: Retrofit
A10: 45999 | B10: Blupine | C10: Bhopalgarh | D10: Rajasthan | E10: 9 | F10: Kamal | G10: N/A | H10: Retrofit
A11: 46001 | B11: Blupine | C11: Bhopalgarh | D11: Rajasthan | E11: 19 | F11: Kamal | G11: N/A | H11: Retrofit
A12: 46001 | B12: TRUE SUN TRADING COMPANY | C12: Kizhakenmuthoor | D12: Kerala | E12: 1 | F12: Pavan | G12: w-122 | H12: Retrofit
A13: 45992 | B13: Axitec Energy | C13: Ernakulam | D13: Kerala | E13: 1 | F13: By mail | G13: N/A | H13: By mail
... A39: 46022 | B39: Continuum | C39: Bhuj | D39: Gujarat | E39: 7 | F39: Bhimsen + 4 | G39: N/A | H39: Retrofit

Sheet Monthly Report Dec-25
A1: Request Received Date | B1: Year | C1: Complaint Raised By | D1: Customer Type | E1: Project Name | F1: Current Status | G1: Claim Reported By | H1: Contact No. | I1: Contract / Complaint / Invoice No. | J1: Customer Reported Problem | K1: Venue / Location | L1: State | M1: Our Evaluation | N1: PV Panels Wp | O1: Module Serial Number | P1: Module Make Year | Q1: Module Make Month | R1: Module Type | S1: Manufacturing Plant | T1: Remark | U1: Action Taken | V1: Resolution Type | W1: Date of Claim Settled | X1: Claim Settlement Duration | Y1: Costing/Module | Z1: Review Meeting Remarks - | AA1: Todays review Minutes
A2: 45941 | B2: 2025 | C2: Madhav Infra Projects Ltd. | D2: Channel Sales | E2: GIPCL,Vastan ,Surat | F2: Closed | G2: Ritesh Jariwala | H2: 9033920684 | J2: Low VOC | K2: Vastan | L2: Gujarat | M2: JB Issue | N2: 545 | O2: NSMI24120992977 | P2: =MID(O2,5,2) -> 24 | Q2: =MID(O2,7,2) -> 12 | R2: G2G | S2: P5 - PEGPL | T2: JB Issue | U2: P JB Changed | V2: Repair | W2: 45999 | X2: =W2-A2 -> 58 | AB2: =IF(AND(F2="Closed",W2>=DATE(2025,12,1),W2<=DATE(2025,12,31)),"Closed in Dec","Other") -> Closed in Dec
A3: 45941 | B3: 2025 | C3: Madhav Infra Projects Ltd. | D3: Channel Sales | E3: GIPCL,Vastan ,Surat | F3: Closed | G3: Ritesh Jariwala | H3: 9033920684 | J3: Low VOC | K3: Vastan | L3: Gujarat | M3: JB Issue | N3: 545 | O3: NSMI24120993021 | P3: =MID(O3,5,2) -> 24 | Q3: =MID(O3,7,2) -> 12 | R3: G2G | S3: P5 - PEGPL | T3: JB Issue | U3: P JB Changed | V3: Repair | W3: 45999 | X3: =W3-A3 -> 58 | AB3: =IF(AND(F3="Closed",W3>=DATE(2025,12,1),W3<=DATE(2025,12,31)),"Closed in Dec","Other") -> Closed in Dec
A4: 45973 | B4: 2025 | C4: Madhav Infra Projects Ltd. | D4: Channel Sales | E4: Lakadia,Bhachau,Kutchh | F4: Closed | G4: Ritesh Jariwala | H4: 9033920684 | J4: Sustained damage | K4: Lakadia | L4: Gujarat | M4: JB Issue | N4: 540 | O4: NSMP2307404623 | P4: =MID(O4,5,2) -> 23 | Q4: =MID(O4,7,2) -> 07 | R4: G2B | S4: P2 - PEPPL | T4: JB Issue | U4: All Jb Changed | V4: Repair | W4: 45998 | X4: =W4-A4 -> 25 | AB4: =IF(AND(F4="Closed",W4>=DATE(2025,12,1),W4<=DATE(2025,12,31)),"Closed in Dec","Other") -> Closed in Dec
A5: 45973 | B5: 2025 | C5: Madhav Infra Projects Ltd. | D5: Channel Sales | E5: Lakadia,Bhachau,Kutchh | F5: Closed | G5: Ritesh Jariwala | H5: 9033920684 | J5: Sustained damage | K5: Lakadia | L5: Gujarat | M5: JB Issue | N5: 540 | O5: NSMP2307404631 | P5: =MID(O5,5,2) -> 23 | Q5: =MID(O5,7,2) -> 07 | R5: G2B | S5: P2 - PEPPL | T5: JB Issue | U5: All Jb Changed | V5: Repair | W5: 45998 | X5: =W5-A5 -> 25 | AB5: =IF(AND(F5="Closed",W5>=DATE(2025,12,1),W5<=DATE(2025,12,31)),"Closed in Dec","Other") -> Closed in Dec
A6: 45973 | B6: 2025 | C6: Madhav Infra Projects Ltd. | D6: Channel Sales | E6: Lakadia,Bhachau,Kutchh | F6: Closed | G6: Ritesh Jariwala | H6: 9033920684 | J6: Sustained damage | K6: Lakadia | L6: Gujarat | M6: JB Issue | N6: 540 | O6: NSMP2307404571 | P6: =MID(O6,5,2) -> 23 | Q6: =MID(O6,7,2) -> 07 | R6: G2B | S6: P2 - PEPPL | T6: JB Issue | U6: All Jb Changed | V6: Repair | W6: 45998 | X6: =W6-A6 -> 25 | AB6: =IF(AND(F6="Closed",W6>=DATE(2025,12,1),W6<=DATE(2025,12,31)),"Closed in Dec","Other") -> Closed in Dec
A7: 45973 | B7: 2025 | C7: Madhav Infra Projects Ltd. | D7: Channel Sales | E7: Lakadia,Bhachau,Kutchh | F7: Closed | G7: Ritesh Jariwala | H7: 9033920684 | J7: Sustained damage | K7: Lakadia | L7: Gujarat | M7: JB Issue | N7: 540 | O7: NSMP2307406784 | P7: =MID(O7,5,2) -> 23 | Q7: =MID(O7,7,2) -> 07 | R7: G2B | S7: P2 - PEPPL | T7: JB Issue | U7: All Jb Changed | V7: Repair | W7: 45998 | X7: =W7-A7 -> 25 | AB7: =IF(AND(F7="Closed",W7>=DATE(2025,12,1),W7<=DATE(2025,12,31)),"Closed in Dec","Other") -> Closed in Dec
A8: 45973 | B8: 2025 | C8: Madhav Infra Projects Ltd. | D8: Channel Sales | E8: Lakadia,Bhachau,Kutchh | F8: Closed | G8: Ritesh Jariwala | H8: 9033920684 | J8: Sustained damage | K8: Lakadia | L8: Gujarat | M8: JB Issue | N8: 540 | O8: NSMP2307406768 | P8: =MID(O8,5,2) -> 23 | Q8: =MID(O8,7,2) -> 07 | R8: G2B | S8: P2 - PEPPL | T8: JB Issue | U8: All Jb Changed | V8: Repair | W8: 45998 | X8: =W8-A8 -> 25 | AB8: =IF(AND(F8="Closed",W8>=DATE(2025,12,1),W8<=DATE(2025,12,31)),"Closed in Dec","Other") -> Closed in Dec
A9: 45973 | B9: 2025 | C9: Madhav Infra Projects Ltd. | D9: Channel Sales | E9: Lakadia,Bhachau,Kutchh | F9: Closed | G9: Ritesh Jariwala | H9: 9033920684 | J9: Sustained damage | K9: Lakadia | L9: Gujarat | M9: JB Issue | N9: 540 | O9: NSMP2307406744 | P9: =MID(O9,5,2) -> 23 | Q9: =MID(O9,7,2) -> 07 | R9: G2B | S9: P2 - PEPPL | T9: JB Issue | U9: All Jb Changed | V9: Repair | W9: 45998 | X9: =W9-A9 -> 25 | AB9: =IF(AND(F9="Closed",W9>=DATE(2025,12,1),W9<=DATE(2025,12,31)),"Closed in Dec","Other") -> Closed in Dec
A10: 45973 | B10: 2025 | C10: Madhav Infra Projects Ltd. | D10: Channel Sales | E10: Lakadia,Bhachau,Kutchh | F10: Closed | G10: Ritesh Jariwala | H10: 9033920684 | J10: Sustained damage | K10: Lakadia | L10: Gujarat | M10: JB Issue | N10: 540 | O10: NSMP2307406753 | P10: =MID(O10,5,2) -> 23 | Q10: =MID(O10,7,2) -> 07 | R10: G2B | S10: P2 - PEPPL | T10: JB Issue | U10: All Jb Changed | V10: Repair | W10: 45998 | X10: =W10-A10 -> 25 | AB10: =IF(AND(F10="Closed",W10>=DATE(2025,12,1),W10<=DATE(2025,12,31)),"Closed in Dec","Other") -> Closed in Dec
A11: 45973 | B11: 2025 | C11: Madhav Infra Projects Ltd. | D11: Channel Sales | E11: Lakadia,Bhachau,Kutchh | F11: Closed | G11: Ritesh Jariwala | H11: 9033920684 | J11: Sustained damage | K11: Lakadia | L11: Gujarat | M11: JB Issue | N11: 540 | O11: NSMP2307406719 | P11: =MID(O11,5,2) -> 23 | Q11: =MID(O11,7,2) -> 07 | R11: G2B | S11: P2 - PEPPL | T11: JB Issue | U11: All Jb Changed | V11: Repair | W11: 45998 | X11: =W11-A11 -> 25 | AB11: =IF(AND(F11="Closed",W11>=DATE(2025,12,1),W11<=DATE(2025,12,31)),"Closed in Dec","Other") -> Closed in Dec
A12: 45973 | B12: 2025 | C12: Madhav Infra Projects Ltd. | D12: Channel Sales | E12: Lakadia,Bhachau,Kutchh | F12: Closed | G12: Ritesh Jariwala | H12: 9033920684 | J12: Sustained damage | K12: Lakadia | L12: Gujarat | M12: JB Issue | N12: 540 | O12: NSMP2307406752 | P12: =MID(O12,5,2) -> 23 | Q12: =MID(O12,7,2) -> 07 | R12: G2B | S12: P2 - PEPPL | T12: JB Issue | U12: All Jb Changed | V12: Repair | W12: 45998 | X12: =W12-A12 -> 25 | AB12: =IF(AND(F12="Closed",W12>=DATE(2025,12,1),W12<=DATE(2025,12,31)),"Closed in Dec","Other") -> Closed in Dec
A13: 45973 | B13: 2025 | C13: Madhav Infra Projects Ltd. | D13: Channel Sales | E13: Lakadia,Bhachau,Kutchh | F13: Closed | G13: Ritesh Jariwala | H13: 9033920684 | J13: Sustained damage | K13: Lakadia | L13: Gujarat | M13: JB Issue | N13: 540 | O13: NSMP2307406504 | P13: =MID(O13,5,2) -> 23 | Q13: =MID(O13,7,2) -> 07 | R13: G2B | S13: P2 - PEPPL | T13: JB Issue | U13: All Jb Changed | V13: Repair | W13: 45998 | X13: =W13-A13 -> 25 | AB13: =IF(AND(F13="Closed",W13>=DATE(2025,12,1),W13<=DATE(2025,12,31)),"Closed in Dec","Other") -> Closed in Dec
... A99: 45973 | B99: 2025 | C99: Madhav Infra Projects Ltd. | D99: Channel Sales | E99: Lakadia,Bhachau,Kutchh | F99: Closed | G99: Ritesh Jariwala | H99: 9033920684 | J99: Sustained damage | K99: Lakadia | L99: Gujarat | M99: JB Issue | N99: 540 | O99: NSMP2307402779 | P99: =MID(O99,5,2) -> 23 | Q99: =MID(O99,7,2) -> 07 | R99: G2B | S99: P2 - PEPPL | T99: JB Issue | U99: All Jb Changed | V99: Repair | W99: 45998 | X99: =W99-A99 -> 25 | AB99: =IF(AND(F99="Closed",W99>=DATE(2025,12,1),W99<=DATE(2025,12,31)),"Closed in Dec","Other") -> Closed in Dec
A100: 45923 | B100: 2025 | C100: True Sun Trading Company | D100: Channel Sales | F100: Closed | G100: Joel Jacob | H100: 7902222180 | J100: Low Voc | K100: VELIYANOOR | L100: Gujarat | M100: Cold Soldering | N100: 545 | O100: Wrong Srl. no.(w-94) updated in w-99 | P100: N/A | Q100: N/A | T100: Complaints closed by True Sun team | U100: Complaints closed by True Sun team | V100: Repair | W100: 45999 | X100: =W100-A100 -> 76 | AB100: =IF(AND(F100="Closed",W100>=DATE(2025,12,1),W100<=DATE(2025,12,31)),"Closed in Dec","Other") -> Closed in Dec
A101: 45996 | B101: 2025 | C101: Panasonic | D101: Channel Sales | F101: Closed | G101: Chirag Tare | H101: 7719846027 | J101: Low VOC | K101: Nagpur | L101: Maharashtra | M101: No Issue | N101: 445 | O101: NSMP2203012985 | P101: =MID(O101,5,2) -> 22 | Q101: =MID(O101,7,2) -> 03 | R101: G2B | S101: P2 - PEPPL | T101: No Issue | U101: Found OK | V101: Repair | W101: 45999 | X101: =W101-A101 -> 3 | AB101: =IF(AND(F101="Closed",W101>=DATE(2025,12,1),W101<=DATE(2025,12,31)),"Closed in Dec","Other") -> Closed in Dec
A102: 45994 | B102: 2025 | C102: Panasonic | D102: Channel Sales | F102: Closed | G102: Chirag Tare | H102: 7719846027 | J102: Low VOC | K102: Nagpur | L102: Maharashtra | M102: Cold Soldering | N102: 545 | O102: NSMP2211232416 | P102: =MID(O102,5,2) -> 22 | Q102: =MID(O102,7,2) -> 11 | R102: G2B | S102: P2 - PEPPL | T102: JB Issue | U102: All JB Soldering | V102: Repair | W102: 45999 | X102: =W102-A102 -> 5 | AB102: =IF(AND(F102="Closed",W102>=DATE(2025,12,1),W102<=DATE(2025,12,31)),"Closed in Dec","Other") -> Closed in Dec
A103: 45994 | B103: 2025 | C103: Panasonic | D103: Channel Sales | F103: Closed | G103: Chirag Tare | H103: 7719846027 | J103: Low VOC | K103: Nagpur | L103: Maharashtra | M103: Cold Soldering | N103: 545 | O103: NSMP2211232485 | P103: =MID(O103,5,2) -> 22 | Q103: =MID(O103,7,2) -> 11 | R103: G2B | S103: P2 - PEPPL | T103: JB Issue | U103: All JB Soldering | V103: Repair | W103: 45999 | X103: =W103-A103 -> 5 | AB103: =IF(AND(F103="Closed",W103>=DATE(2025,12,1),W103<=DATE(2025,12,31)),"Closed in Dec","Other") -> Closed in Dec
A104: 45994 | B104: 2025 | C104: Panasonic | D104: Channel Sales | F104: Closed | G104: Chirag Tare | H104: 7719846027 | J104: Low VOC | K104: Nagpur | L104: Maharashtra | M104: Cold Soldering | N104: 545 | O104: NSMP2211232374 | P104: =MID(O104,5,2) -> 22 | Q104: =MID(O104,7,2) -> 11 | R104: G2B | S104: P2 - PEPPL | T104: JB Issue | U104: All JB Soldering | V104: Repair | W104: 45999 | X104: =W104-A104 -> 5 | AB104: =IF(AND(F104="Closed",W104>=DATE(2025,12,1),W104<=DATE(2025,12,31)),"Closed in Dec","Other") -> Closed in Dec
A105: 45996 | B105: 2025 | C105: Panasonic | D105: Channel Sales | F105: Closed | G105: Chirag Tare | H105: 7719846027 | J105: Low VOC | K105: Aluva | L105: Kerala | M105: Cold Soldering | N105: 535 | O105: ANCHOR2305114695 | P105: 23 | Q105: =MID(O105,9,2) -> 05 | R105: G2B | S105: P2 - PEPPL | T105: JB Issue | U105: N JB Soldering | V105: Repair | W105: 45999 | X105: =W105-A105 -> 3 | AB105: =IF(AND(F105="Closed",W105>=DATE(2025,12,1),W105<=DATE(2025,12,31)),"Closed in Dec","Other") -> Closed in Dec
A106: 45999 | B106: 2025 | C106: Continuum | D106: Utility and C&I | F106: Closed | G106: Sudarshan Bhosale | H106: 9972197300 | J106: Low Voc / Burn spot | K106: Jamnagar | L106: Gujarat | M106: JB Burn | N106: 580 | O106: NSMI25040181104 | P106: =MID(O106,5,2) -> 25 | Q106: =MID(O106,7,2) -> 04 | R106: G2G | S106: P4 - PEIPL | T106: JB Issue | U106: P & N JB Changed | V106: Repair | W106: 46003 | X106: =W106-A106 -> 4 | AB106: =IF(AND(F106="Closed",W106>=DATE(2025,12,1),W106<=DATE(2025,12,31)),"Closed in Dec","Other") -> Closed in Dec
A107: 45999 | B107: 2025 | C107: Continuum | D107: Utility and C&I | F107: Closed | G107: Sudarshan Bhosale | H107: 9972197300 | J107: Low Voc / Burn spot | K107: Jamnagar | L107: Gujarat | M107: JB Burn | N107: 580 | O107: NSMI25040181026 | P107: =MID(O107,5,2) -> 25 | Q107: =MID(O107,7,2) -> 04 | R107: G2G | S107: P4 - PEIPL | T107: JB Issue | U107: P & N JB Changed | V107: Repair | W107: 46003 | X107: =W107-A107 -> 4 | AB107: =IF(AND(F107="Closed",W107>=DATE(2025,12,1),W107<=DATE(2025,12,31)),"Closed in Dec","Other") -> Closed in Dec
A108: 45999 | B108: 2025 | C108: Continuum | D108: Utility and C&I | F108: Closed | G108: Sudarshan Bhosale | H108: 9972197300 | J108: Low Voc / Burn spot | K108: Jamnagar | L108: Gujarat | M108: JB Burn | N108: 580 | O108: NSMI25040181099 | P108: =MID(O108,5,2) -> 25 | Q108: =MID(O108,7,2) -> 04 | R108: G2G | S108: P4 - PEIPL | T108: JB Issue | U108: P & N JB Changed | V108: Repair | W108: 46003 | X108: =W108-A108 -> 4 | AB108: =IF(AND(F108="Closed",W108>=DATE(2025,12,1),W108<=DATE(2025,12,31)),"Closed in Dec","Other") -> Closed in Dec
A109: 45999 | B109: 2025 | C109: Continuum | D109: Utility and C&I | F109: Closed | G109: Sudarshan Bhosale | H109: 9972197300 | J109: Low Voc / Burn spot | K109: Jamnagar | L109: Gujarat | M109: JB Burn | N109: 580 | O109: NSMI25040181106 | P109: =MID(O109,5,2) -> 25 | Q109: =MID(O109,7,2) -> 04 | R109: G2G | S109: P4 - PEIPL | T109: JB Issue | U109: P & N JB Changed | V109: Repair | W109: 46003 | X109: =W109-A109 -> 4 | AB109: =IF(AND(F109="Closed",W109>=DATE(2025,12,1),W109<=DATE(2025,12,31)),"Closed in Dec","Other") -> Closed in Dec
A110: 45999 | B110: 2025 | C110: Continuum | D110: Utility and C&I | F110: Closed | G110: Sudarshan Bhosale | H110: 9972197300 | J110: Low Voc / Burn spot | K110: Jamnagar | L110: Gujarat | M110: JB Burn | N110: 580 | O110: NSMI25040181095 | P110: =MID(O110,5,2) -> 25 | Q110: =MID(O110,7,2) -> 04 | R110: G2G | S110: P4 - PEIPL | T110: JB Issue | U110: P & N JB Changed | V110: Repair | W110: 46003 | X110: =W110-A110 -> 4 | AB110: =IF(AND(F110="Closed",W110>=DATE(2025,12,1),W110<=DATE(2025,12,31)),"Closed in Dec","Other") -> Closed in Dec
A111: 45999 | B111: 2025 | C111: Continuum | D111: Utility and C&I | F111: Closed | G111: Sudarshan Bhosale | H111: 9972197300 | J111: Low Voc / Burn spot | K111: Jamnagar | L111: Gujarat | M111: JB Burn | N111: 580 | O111: NSMI25040181107 | P111: =MID(O111,5,2) -> 25 | Q111: =MID(O111,7,2) -> 04 | R111: G2G | S111: P4 - PEIPL | T111: JB Burnt | U111: All Jb Changed | V111: Repair | W111: 46003 | X111: =W111-A111 -> 4 | AB111: =IF(AND(F111="Closed",W111>=DATE(2025,12,1),W111<=DATE(2025,12,31)),"Closed in Dec","Other") -> Closed in Dec
A112: 45999 | B112: 2025 | C112: Continuum | D112: Utility and C&I | F112: Closed | G112: Sudarshan Bhosale | H112: 9972197300 | J112: Low Voc / Burn spot | K112: Jamnagar | L112: Gujarat | M112: JB Burn | N112: 580 | O112: NSMI25040181109 | P112: =MID(O112,5,2) -> 25 | Q112: =MID(O112,7,2) -> 04 | R112: G2G | S112: P4 - PEIPL | T112: JB Issue | U112: P & N JB Changed | V112: Repair | W112: 46004 | X112: =W112-A112 -> 5 | AB112: =IF(AND(F112="Closed",W112>=DATE(2025,12,1),W112<=DATE(2025,12,31)),"Closed in Dec","Other") -> Closed in Dec
A113: 45999 | B113: 2025 | C113: Continuum | D113: Utility and C&I | F113: Closed | G113: Sudarshan Bhosale | H113: 9972197300 | J113: Low Voc / Burn spot | K113: Jamnagar | L113: Gujarat | M113: JB Burn | N113: 580 | O113: NSMI25040181112 | P113: =MID(O113,5,2) -> 25 | Q113: =MID(O113,7,2) -> 04 | R113: G2G | S113: P4 - PEIPL | T113: JB Burnt | U113: N JB Changed | V113: Repair | W113: 46004 | X113: =W113-A113 -> 5 | AB113: =IF(AND(F113="Closed",W113>=DATE(2025,12,1),W113<=DATE(2025,12,31)),"Closed in Dec","Other") -> Closed in Dec
A114: 45999 | B114: 2025 | C114: Continuum | D114: Utility and C&I | F114: Closed | G114: Sudarshan Bhosale | H114: 9972197300 | J114: Low Voc / Burn spot | K114: Jamnagar | L114: Gujarat | M114: JB Burn | N114: 580 | O114: NSMI25040181131 | P114: =MID(O114,5,2) -> 25 | Q114: =MID(O114,7,2) -> 04 | R114: G2G | S114: P4 - PEIPL | T114: JB Issue | U114: P & N JB Changed | V114: Repair | W114: 46004 | X114: =W114-A114 -> 5 | AB114: =IF(AND(F114="Closed",W114>=DATE(2025,12,1),W114<=DATE(2025,12,31)),"Closed in Dec","Other") -> Closed in Dec
A115: 45999 | B115: 2025 | C115: Continuum | D115: Utility and C&I | F115: Closed | G115: Sudarshan Bhosale | H115: 9972197300 | J115: Low Voc / Burn spot | K115: Jamnagar | L115: Gujarat | M115: JB Burn | N115: 580 | O115: NSMI25040181097 | P115: =MID(O115,5,2) -> 25 | Q115: =MID(O115,7,2) -> 04 | R115: G2G | S115: P4 - PEIPL | T115: JB Issue | U115: P & N JB Changed | V115: Repair | W115: 46004 | X115: =W115-A115 -> 5 | AB115: =IF(AND(F115="Closed",W115>=DATE(2025,12,1),W115<=DATE(2025,12,31)),"Closed in Dec","Other") -> Closed in Dec
A116: 45999 | B116: 2025 | C116: Continuum | D116: Utility and C&I | F116: Closed | G116: Sudarshan Bhosale | H116: 9972197300 | J116: Low Voc / Burn spot | K116: Jamnagar | L116: Gujarat | M116: JB Burn | N116: 580 | O116: NSMI25040181078 | P116: =MID(O116,5,2) -> 25 | Q116: =MID(O116,7,2) -> 04 | R116: G2G | S116: P4 - PEIPL | T116: JB Issue | U116: P JB Changed | V116: Repair | W116: 46004 | X116: =W116-A116 -> 5 | AB116: =IF(AND(F116="Closed",W116>=DATE(2025,12,1),W116<=DATE(2025,12,31)),"Closed in Dec","Other") -> Closed in Dec
A117: 46001 | B117: 2025 | C117: KVK Engineering | D117: Channel Sales | F117: Closed | G117: RAVIRAJ GOUD | H117: 9440789940 | J117: Low VOC | K117: Kukatpally Y-Junction ,Blanagar ,Hyderabad | L117: Telangana | M117: Cold Soldering | N117: 590 | O117: NSMI25060004260 | P117: =MID(O117,5,2) -> 25 | Q117: =MID(O117,7,2) -> 06 | R117: G2G | S117: P5 - PEGPL | T117: JB Issue | U117: N JB Soldering | V117: Repair | W117: 46011 | X117: =W117-A117 -> 10 | AB117: =IF(AND(F117="Closed",W117>=DATE(2025,12,1),W117<=DATE(2025,12,31)),"Closed in Dec","Other") -> Closed in Dec
A118: 45974 | B118: 2025 | C118: Blupine Jakson Green | D118: Utility and C&I | E118: Blupine Energy | F118: Closed | G118: Deepak Kumar Behera | H118: 7854906505 | J118: Low voc/Zero Amp/JB Damage module | K118: Mungeli | L118: Chhattisgarh | M118: Cold Soldering | N118: 585 | O118: NSMI24090424381 | P118: =MID(O118,5,2) -> 24 | Q118: =MID(O118,7,2) -> 09 | R118: G2G | S118: P4 - PEIPL | T118: JB Issue | U118: P JB Soldering | V118: Repair | W118: 46004 | X118: =W118-A118 -> 30 | AB118: =IF(AND(F118="Closed",W118>=DATE(2025,12,1),W118<=DATE(2025,12,31)),"Closed in Dec","Other") -> Closed in Dec
A119: 45974 | B119: 2025 | C119: Blupine Jakson Green | D119: Utility and C&I | E119: Blupine Energy | F119: Closed | G119: Deepak Kumar Behera | H119: 7854906506 | J119: Low voc/Zero Amp/JB Damage module | K119: Mungeli | L119: Chhattisgarh | M119: Cold Soldering | N119: 585 | O119: NSMI24090424355 | P119: =MID(O119,5,2) -> 24 | Q119: =MID(O119,7,2) -> 09 | R119: G2G | S119: P4 - PEIPL | T119: JB Issue | U119: P JB Soldering | V119: Repair | W119: 46004 | X119: =W119-A119 -> 30 | AB119: =IF(AND(F119="Closed",W119>=DATE(2025,12,1),W119<=DATE(2025,12,31)),"Closed in Dec","Other") -> Closed in Dec
A120: 45974 | B120: 2025 | C120: Blupine Jakson Green | D120: Utility and C&I | E120: Blupine Energy | F120: Closed | G120: Deepak Kumar Behera | H120: 7854906507 | J120: Low voc/Zero Amp/JB Damage module | K120: Mungeli | L120: Chhattisgarh | M120: Cold Soldering | N120: 585 | O120: NSMI24090424374 | P120: =MID(O120,5,2) -> 24 | Q120: =MID(O120,7,2) -> 09 | R120: G2G | S120: P4 - PEIPL | T120: JB Issue | U120: P JB Soldering | V120: Repair | W120: 46004 | X120: =W120-A120 -> 30 | AB120: =IF(AND(F120="Closed",W120>=DATE(2025,12,1),W120<=DATE(2025,12,31)),"Closed in Dec","Other") -> Closed in Dec
A121: 45974 | B121: 2025 | C121: Blupine Jakson Green | D121: Utility and C&I | E121: Blupine Energy | F121: Closed | G121: Deepak Kumar Behera | H121: 7854906508 | J121: Low voc/Zero Amp/JB Damage module | K121: Mungeli | L121: Chhattisgarh | M121: Cold Soldering | N121: 585 | O121: NSMI24090424378 | P121: =MID(O121,5,2) -> 24 | Q121: =MID(O121,7,2) -> 09 | R121: G2G | S121: P4 - PEIPL | T121: JB Issue | U121: P JB Soldering | V121: Repair | W121: 46004 | X121: =W121-A121 -> 30 | AB121: =IF(AND(F121="Closed",W121>=DATE(2025,12,1),W121<=DATE(2025,12,31)),"Closed in Dec","Other") -> Closed in Dec
A122: 45974 | B122: 2025 | C122: Blupine Jakson Green | D122: Utility and C&I | E122: Blupine Energy | F122: Closed | G122: Deepak Kumar Behera | H122: 7854906509 | J122: Low voc/Zero Amp/JB Damage module | K122: Mungeli | L122: Chhattisgarh | M122: Cold Soldering | N122: 585 | O122: NSMI24090424385 | P122: =MID(O122,5,2) -> 24 | Q122: =MID(O122,7,2) -> 09 | R122: G2G | S122: P4 - PEIPL | T122: JB Issue | U122: P JB Soldering | V122: Repair | W122: 46004 | X122: =W122-A122 -> 30 | AB122: =IF(AND(F122="Closed",W122>=DATE(2025,12,1),W122<=DATE(2025,12,31)),"Closed in Dec","Other") -> Closed in Dec
A123: 45974 | B123: 2025 | C123: Blupine Jakson Green | D123: Utility and C&I | E123: Blupine Energy | F123: Closed | G123: Deepak Kumar Behera | H123: 7854906510 | J123: Low voc/Zero Amp/JB Damage module | K123: Mungeli | L123: Chhattisgarh | M123: JB Issue | N123: 585 | O123: NSMI24090424386 | P123: =MID(O123,5,2) -> 24 | Q123: =MID(O123,7,2) -> 09 | R123: G2G | S123: P4 - PEIPL | T123: JB Issue | U123: P JB Changed | V123: Repair | W123: 46004 | X123: =W123-A123 -> 30 | AB123: =IF(AND(F123="Closed",W123>=DATE(2025,12,1),W123<=DATE(2025,12,31)),"Closed in Dec","Other") -> Closed in Dec
A124: 45974 | B124: 2025 | C124: Blupine Jakson Green | D124: Utility and C&I | E124: Blupine Energy | F124: Closed | G124: Deepak Kumar Behera | H124: 7854906511 | J124: Low voc/Zero Amp/JB Damage module | K124: Mungeli | L124: Chhattisgarh | M124: Cold Soldering | N124: 585 | O124: NSMI24090395950 | P124: =MID(O124,5,2) -> 24 | Q124: =MID(O124,7,2) -> 09 | R124: G2G | S124: P4 - PEIPL | T124: JB Issue | U124: P JB Soldering | V124: Repair | W124: 46006 | X124: =W124-A124 -> 32 | AB124: =IF(AND(F124="Closed",W124>=DATE(2025,12,1),W124<=DATE(2025,12,31)),"Closed in Dec","Other") -> Closed in Dec
A125: 45974 | B125: 2025 | C125: Blupine Jakson Green | D125: Utility and C&I | E125: Blupine Energy | F125: Closed | G125: Deepak Kumar Behera | H125: 7854906512 | J125: Low voc/Zero Amp/JB Damage module | K125: Mungeli | L125: Chhattisgarh | M125: Cold Soldering | N125: 585 | O125: NSMI24090424387 | P125: =MID(O125,5,2) -> 24 | Q125: =MID(O125,7,2) -> 09 | R125: G2G | S125: P4 - PEIPL | T125: JB Issue | U125: P JB Soldering | V125: Repair | W125: 46006 | X125: =W125-A125 -> 32 | AB125: =IF(AND(F125="Closed",W125>=DATE(2025,12,1),W125<=DATE(2025,12,31)),"Closed in Dec","Other") -> Closed in Dec
...

Sheet Sheet1
D1: aaa
C2: NSMI24110755622 | D2: =VLOOKUP(C2,'Monthly Report Dec-25'!O:O,1,0) -> #N/A | F2: NSMI24110755622 | G2: =VLOOKUP(F2,'Monthly Report Dec-25'!#REF!,1,0) -> #REF!
C3: NSMI24100693901 | D3: =VLOOKUP(C3,'Monthly Report Dec-25'!O:O,1,0) -> #N/A | F3: NSMI24100693901 | G3: =VLOOKUP(F3,'Monthly Report Dec-25'!O118:O118,1,0) -> #N/A
C4: NSMI24100719165 | D4: =VLOOKUP(C4,'Monthly Report Dec-25'!O:O,1,0) -> #N/A | F4: NSMI24100719165 | G4: =VLOOKUP(F4,'Monthly Report Dec-25'!O118:O119,1,0) -> #N/A
C5: NSMI24110758207 | D5: =VLOOKUP(C5,'Monthly Report Dec-25'!O:O,1,0) -> #N/A | F5: NSMI24110758207 | G5: =VLOOKUP(F5,'Monthly Report Dec-25'!O118:O120,1,0) -> #N/A
C6: NSMI24110758250 | D6: =VLOOKUP(C6,'Monthly Report Dec-25'!O:O,1,0) -> #N/A | F6: NSMI24110758250 | G6: =VLOOKUP(F6,'Monthly Report Dec-25'!O118:O121,1,0) -> #N/A
C7: NSMI24110763670 | D7: =VLOOKUP(C7,'Monthly Report Dec-25'!O:O,1,0) -> #N/A | F7: NSMI24110763670 | G7: =VLOOKUP(F7,'Monthly Report Dec-25'!O118:O122,1,0) -> #N/A
C8: NSMI24110762009 | D8: =VLOOKUP(C8,'Monthly Report Dec-25'!O:O,1,0) -> #N/A | F8: NSMI24110762009 | G8: =VLOOKUP(F8,'Monthly Report Dec-25'!O118:O123,1,0) -> #N/A
C9: NSMI24110761366 | D9: =VLOOKUP(C9,'Monthly Report Dec-25'!O:O,1,FALSE) -> #N/A | F9: NSMI24110761366 | G9: =VLOOKUP(F9,'Monthly Report Dec-25'!O118:O124,1,0) -> #N/A
C10: NSMI24100733638 | D10: =VLOOKUP(C10,'Monthly Report Dec-25'!O:O,2,0) -> #N/A | F10: NSMI24100733638 | G10: =VLOOKUP(F10,'Monthly Report Dec-25'!O118:O125,1,0) -> #N/A
C11: NSMI24100695077 | D11: =VLOOKUP(C11,'Monthly Report Dec-25'!O:O,1,0) -> #N/A | F11: NSMI24100695077 | G11: =VLOOKUP(F11,'Monthly Report Dec-25'!O118:O126,1,0) -> #N/A
C12: NSMI24100725741 | D12: =VLOOKUP(C12,'Monthly Report Dec-25'!O:O,1,0) -> #N/A | F12: NSMI24100725741 | G12: =VLOOKUP(F12,'Monthly Report Dec-25'!O118:O127,1,0) -> #N/A
C13: NSMI24110789579 | D13: =VLOOKUP(C13,'Monthly Report Dec-25'!O:O,1,0) -> #N/A | F13: NSMI24110789579 | G13: =VLOOKUP(F13,'Monthly Report Dec-25'!O118:O128,1,0) -> #N/A
C14: NSMI24110789569 | D14: =VLOOKUP(C14,'Monthly Report Dec-25'!O:O,1,0) -> #N/A | F14: NSMI24110789569 | G14: =VLOOKUP(F14,'Monthly Report Dec-25'!O118:O129,1,0) -> #N/A
C15: NSMI24110789553 | D15: =VLOOKUP(C15,'Monthly Report Dec-25'!O:O,1,0) -> #N/A | F15: NSMI24110789553 | G15: =VLOOKUP(F15,'Monthly Report Dec-25'!O118:O130,1,0) -> #N/A
C16: NSMI24110789578 | D16: =VLOOKUP(C16,'Monthly Report Dec-25'!O:O,1,0) -> #N/A | F16: NSMI24110789578 | G16: =VLOOKUP(F16,'Monthly Report Dec-25'!O118:O131,1,0) -> #N/A
C17: NSMI24110789577 | D17: =VLOOKUP(C17,'Monthly Report Dec-25'!O:O,1,0) -> #N/A | F17: NSMI24110789577 | G17: =VLOOKUP(F17,'Monthly Report Dec-25'!O118:O132,1,0) -> #N/A
C18: NSMI24110789633 | D18: =VLOOKUP(C18,'Monthly Report Dec-25'!O:O,1,0) -> #N/A | F18: NSMI24110789633 | G18: =VLOOKUP(F18,'Monthly Report Dec-25'!O118:O133,1,0) -> #N/A
C19: NSMI24110789584 | D19: =VLOOKUP(C19,'Monthly Report Dec-25'!O:O,1,0) -> #N/A | F19: NSMI24110789584 | G19: =VLOOKUP(F19,'Monthly Report Dec-25'!O118:O134,1,0) -> #N/A
C20: NSMI24110789609 | D20: =VLOOKUP(C20,'Monthly Report Dec-25'!O:O,1,0) -> #N/A | F20: NSMI24110789609 | G20: =VLOOKUP(F20,'Monthly Report Dec-25'!O118:O135,1,0) -> #N/A
C21: NSMI24110789631 | D21: =VLOOKUP(C21,'Monthly Report Dec-25'!O:O,1,0) -> #N/A | F21: NSMI24110789631 | G21: =VLOOKUP(F21,'Monthly Report Dec-25'!O118:O136,1,0) -> #N/A
C22: NSMI24110759924 | D22: =VLOOKUP(C22,'Monthly Report Dec-25'!O:O,1,0) -> #N/A | F22: NSMI24110759924 | G22: =VLOOKUP(F22,'Monthly Report Dec-25'!O118:O137,1,0) -> #N/A
C23: NSMI24100725027 | D23: =VLOOKUP(C23,'Monthly Report Dec-25'!O:O,1,0) -> #N/A | F23: NSMI24100725027 | G23: =VLOOKUP(F23,'Monthly Report Dec-25'!O118:O138,1,0) -> #N/A
C24: NSMI24110759989 | D24: =VLOOKUP(C24,'Monthly Report Dec-25'!O:O,1,0) -> #N/A | F24: NSMI24110759989 | G24: =VLOOKUP(F24,'Monthly Report Dec-25'!O118:O139,1,0) -> #N/A
C25: NSMI24100698708 | D25: =VLOOKUP(C25,'Monthly Report Dec-25'!O:O,1,0) -> #N/A | F25: NSMI24100698708 | G25: =VLOOKUP(F25,'Monthly Report Dec-25'!O118:O140,1,0) -> #N/A
C26: NSMI24110788200 | D26: =VLOOKUP(C26,'Monthly Report Dec-25'!O:O,1,0) -> #N/A | F26: NSMI24110788200 | G26: =VLOOKUP(F26,'Monthly Report Dec-25'!O118:O141,1,0) -> #N/A
C27: NSMI24110740240 | D27: =VLOOKUP(C27,'Monthly Report Dec-25'!O:O,1,0) -> #N/A | F27: NSMI24110740240 | G27: =VLOOKUP(F27,'Monthly Report Dec-25'!O118:O142,1,0) -> #N/A
C28: NSMI24110740246 | D28: =VLOOKUP(C28,'Monthly Report Dec-25'!O:O,1,0) -> #N/A | F28: NSMI24110740246 | G28: =VLOOKUP(F28,'Monthly Report Dec-25'!O118:O143,1,0) -> #N/A
C29: NSMI24110740321 | D29: =VLOOKUP(C29,'Monthly Report Dec-25'!O:O,1,0) -> #N/A | F29: NSMI24110740321 | G29: =VLOOKUP(F29,'Monthly Report Dec-25'!O118:O144,1,0) -> #N/A
C30: NSMI24100717544 | D30: =VLOOKUP(C30,'Monthly Report Dec-25'!O:O,1,0) -> #N/A | F30: NSMI24100717544 | G30: =VLOOKUP(F30,'Monthly Report Dec-25'!O118:O145,1,0) -> #N/A
C31: NSMI24110739230 | D31: =VLOOKUP(C31,'Monthly Report Dec-25'!O:O,1,0) -> #N/A | F31: NSMI24110739230 | G31: =VLOOKUP(F31,'Monthly Report Dec-25'!O118:O146,1,0) -> #N/A
C32: NSMI24110739374 | D32: =VLOOKUP(C32,'Monthly Report Dec-25'!O:O,1,0) -> #N/A | F32: NSMI24110739374 | G32: =VLOOKUP(F32,'Monthly Report Dec-25'!O118:O147,1,0) -> #N/A
C33: NSMI24100735430 | D33: =VLOOKUP(C33,'Monthly Report Dec-25'!O:O,1,0) -> #N/A | F33: NSMI24100735430 | G33: =VLOOKUP(F33,'Monthly Report Dec-25'!O118:O148,1,0) -> #N/A
C34: NSMI24100729540 | D34: =VLOOKUP(C34,'Monthly Report Dec-25'!O:O,1,0) -> #N/A | F34: NSMI24100729540 | G34: =VLOOKUP(F34,'Monthly Report Dec-25'!O118:O149,1,0) -> #N/A
C35: NSMI24110790910 | D35: =VLOOKUP(C35,'Monthly Report Dec-25'!O:O,1,0) -> #N/A | F35: NSMI24110790910 | G35: =VLOOKUP(F35,'Monthly Report Dec-25'!O118:O150,1,0) -> #N/A
C36: NSMI24110791179 | D36: =VLOOKUP(C36,'Monthly Report Dec-25'!O:O,1,0) -> #N/A | F36: NSMI24110791179 | G36: =VLOOKUP(F36,'Monthly Report Dec-25'!O118:O151,1,0) -> #N/A
C37: NSMI24110791107 | D37: =VLOOKUP(C37,'Monthly Report Dec-25'!O:O,1,0) -> #N/A | F37: NSMI24110791107 | G37: =VLOOKUP(F37,'Monthly Report Dec-25'!O118:O152,1,0) -> #N/A
C38: NSMI24100732031 | D38: =VLOOKUP(C38,'Monthly Report Dec-25'!O:O,1,0) -> #N/A | F38: NSMI24100732031 | G38: =VLOOKUP(F38,'Monthly Report Dec-25'!O118:O153,1,0) -> #N/A
C39: NSMI24100729559 | D39: =VLOOKUP(C39,'Monthly Report Dec-25'!O:O,1,0) -> #N/A | F39: NSMI24100729559 | G39: =VLOOKUP(F39,'Monthly Report Dec-25'!O118:O154,1,0) -> #N/A
C40: NSMI24110740809 | D40: =VLOOKUP(C40,'Monthly Report Dec-25'!O:O,1,0) -> #N/A | F40: NSMI24110740809 | G40: =VLOOKUP(F40,'Monthly Report Dec-25'!O118:O155,1,0) -> #N/A
...

Sheet Sheet6
F1: State | L1: Complaint Raised By | N1: Resolution Type | P1: JB Issue
F2: Gujarat | H2: {=_xlfn.UNIQUE('Monthly Report Dec-25'!C2:C417)} -> Madhav Infra Projects Ltd. | L2: Madhav Infra Projects Ltd. | N2: Repair | P2: Module Damaged
A3: Row Labels | B3: Count of Complaint Raised By | F3: Maharashtra | H3: True Sun Trading Company | L3: TRUE SUN TRADING COMPANY | N3: Rejected | P3: Cold Soldering
A4: Axitec Energy | B4: 20 | F4: Kerala | H4: Panasonic | L4: Panasonic | N4: Replacement | P4: No Issue
A5: Panasonic | B5: 5 | F5: Telengana | H5: Continuum | L5: Continuum - JROPL | P5: JB Burn
A6: Solar Square | B6: 6 | F6: Chhattisgarh | H6: KVK Engineering | L6: KVK ENGINEERING | P6: Burn Module
A7: TRUE SUN TRADING COMPANY | B7: 2 | F7: UP | H7: Blupine Jakson Green | L7: Blupine Jakson Green | P7: Improper ribbon/tab lead soldering
A8: Madhav Infra Projects Ltd. | B8: 98 | F8: Rajasthan | H8: Arsiga Solar | L8: Arsiga Solar | P8: Oil Marks on the module
A9: Continuum - JROPL | B9: 11 | F9: Karnataka | H9: Solar Square | L9: Solar Square | P9: Not related to Premier Complaints
A10: KVK ENGINEERING | B10: 1 | H10: Shakti Pump | L10: Shakti Pump
A11: (blank) | H11: Blupine Energy | L11: Blupine Energy
A12: Blupine Jakson Green | B12: 58 | H12: ORB Energy | L12: Orb Energy
A13: Arsiga Solar | B13: 9 | H13: Axitec Energy | L13: Axitec Energy
A14: Shakti Pump | B14: 1 | L14: Continuum
A15: Blupine Energy | B15: 181
A16: Orb Energy | B16: 1
A17: Continuum | B17: 23
A18: Grand Total | B18: 416
